Workbook

Sheet Master Sheet
A3: Main Line | K3: Average for models
A4: OPERADOR | B4: Tiempo disponible de operación. | C4: Producción diaria | D4: Over Speed | E4: Min. a Seg. | F4: Takt Time (Seg) | G4: Takt Time (Min) | H4: Takt Time (Hr) | I4: Fecha | K4: Models | L4: NORTHFACE
A5: Operador 1 | B5: 660 | C5: 13 | D5: 1.08 | E5: 60 | F5: =(($B$5/($C$5*$D$5)*$E$5)) -> 2820.5128 | G5: =F5/60 -> 47.008547 | H5: =G5/60 -> 0.78347578 | I5: 45776 | K5: Main Line | L5: =+'Pillar Chart NORTHFACE'!C48+'Pillar Chart NORTHFACE'!G48 -> 50.9
K6: Subassembly | L6: =+'Pillar Chart NORTHFACE'!D48+'Pillar Chart NORTHFACE'!E48+'Pillar Chart NORTHFACE'!F48+'Pillar Chart NORTHFACE'!H48+'Pillar Chart NORTHFACE'!I48+'Pillar Chart NORTHFACE'!J48 -> 309.85
L7: =+SUM(L5:L6) -> 360.75

Sheet NORTH FACE
A1: HOJA DE TRABAJO ESTÁNDAR
A2: Área | C2: Linea | E2: Tiempo de Operación Disponible | G2: Fecha de Revisión: | K2: 1 | L2: 2 | M2: 3 | N2: 4 | O2: 5 | P2: 6 | Q2: 7 | R2: 8 | S2: 9 | T2: 10 | U2: 11 | V2: 12
A3: Ensamble | C3: NORTH FACE | E3: =+'Master Sheet'!B5 -> 660 | G3: =+'Master Sheet'!I5 -> 45776 | J3: Apretar | K3: =+SUMIFS(tbl_WI[BEC Time (seg..)],tbl_WI[ELEMENTO],"*"&$J3&"*",tbl_WI['# Operador],K$2) -> 0 | L3: =+SUMIFS(tbl_WI[BEC Time (seg..)],tbl_WI[ELEMENTO],"*"&$J3&"*",tbl_WI['# Operador],L$2) -> 0 | M3: =+SUMIFS(tbl_WI[BEC Time (seg..)],tbl_WI[ELEMENTO],"*"&$J3&"*",tbl_WI['# Operador],M$2) -> 0 | N3: =+SUMIFS(tbl_WI[BEC Time (seg..)],tbl_WI[ELEMENTO],"*"&$J3&"*",tbl_WI['# Operador],N$2) -> 257 | O3: =+SUMIFS(tbl_WI[BEC Time (seg..)],tbl_WI[ELEMENTO],"*"&$J3&"*",tbl_WI['# Operador],O$2) -> 0 | P3: =+SUMIFS(tbl_WI[BEC Time (seg..)],tbl_WI[ELEMENTO],"*"&$J3&"*",tbl_WI['# Operador],P$2) -> 0 | Q3: =+SUMIFS(tbl_WI[BEC Time (seg..)],tbl_WI[ELEMENTO],"*"&$J3&"*",tbl_WI['# Operador],Q$2) -> 759 | R3: =+SUMIFS(tbl_WI[BEC Time (seg..)],tbl_WI[ELEMENTO],"*"&$J3&"*",tbl_WI['# Operador],R$2) -> 0 | ... V3: =+SUMIFS(tbl_WI[BEC Time (seg..)],tbl_WI[ELEMENTO],"*"&$J3&"*",tbl_WI['# Operador],V$2) -> 0
A4: Proceso | C4: Modelo | E4: Eficiencia% | F4: Produccion Diaria | G4: No. De Revisión: | J4: Conectar | K4: =+SUMIFS(tbl_WI[BEC Time (seg..)],tbl_WI[ELEMENTO],"*"&$J4&"*",tbl_WI['# Operador],K$2) -> 0 | L4: =+SUMIFS(tbl_WI[BEC Time (seg..)],tbl_WI[ELEMENTO],"*"&$J4&"*",tbl_WI['# Operador],L$2) -> 0 | M4: =+SUMIFS(tbl_WI[BEC Time (seg..)],tbl_WI[ELEMENTO],"*"&$J4&"*",tbl_WI['# Operador],M$2) -> 0 | N4: =+SUMIFS(tbl_WI[BEC Time (seg..)],tbl_WI[ELEMENTO],"*"&$J4&"*",tbl_WI['# Operador],N$2) -> 0 | O4: =+SUMIFS(tbl_WI[BEC Time (seg..)],tbl_WI[ELEMENTO],"*"&$J4&"*",tbl_WI['# Operador],O$2) -> 0 | P4: =+SUMIFS(tbl_WI[BEC Time (seg..)],tbl_WI[ELEMENTO],"*"&$J4&"*",tbl_WI['# Operador],P$2) -> 0 | Q4: =+SUMIFS(tbl_WI[BEC Time (seg..)],tbl_WI[ELEMENTO],"*"&$J4&"*",tbl_WI['# Operador],Q$2) -> 126 | R4: =+SUMIFS(tbl_WI[BEC Time (seg..)],tbl_WI[ELEMENTO],"*"&$J4&"*",tbl_WI['# Operador],R$2) -> 0 | ... V4: =+SUMIFS(tbl_WI[BEC Time (seg..)],tbl_WI[ELEMENTO],"*"&$J4&"*",tbl_WI['# Operador],V$2) -> 0
A5: Linea produccion | C5: =+C3 -> NORTH FACE | E5: =(((D226/G226)*F5)/521)*100 -> 109.23493 | F5: =+'Master Sheet'!C5 -> 13 | G5: 1 | J5: Elaborar | K5: =+SUMIFS(tbl_WI[BEC Time (seg..)],tbl_WI[ELEMENTO],"*"&$J5&"*",tbl_WI['# Operador],K$2) -> 2065 | L5: =+SUMIFS(tbl_WI[BEC Time (seg..)],tbl_WI[ELEMENTO],"*"&$J5&"*",tbl_WI['# Operador],L$2) -> 200 | M5: =+SUMIFS(tbl_WI[BEC Time (seg..)],tbl_WI[ELEMENTO],"*"&$J5&"*",tbl_WI['# Operador],M$2) -> 0 | N5: =+SUMIFS(tbl_WI[BEC Time (seg..)],tbl_WI[ELEMENTO],"*"&$J5&"*",tbl_WI['# Operador],N$2) -> 203 | O5: =+SUMIFS(tbl_WI[BEC Time (seg..)],tbl_WI[ELEMENTO],"*"&$J5&"*",tbl_WI['# Operador],O$2) -> 769 | P5: =+SUMIFS(tbl_WI[BEC Time (seg..)],tbl_WI[ELEMENTO],"*"&$J5&"*",tbl_WI['# Operador],P$2) -> 81 | Q5: =+SUMIFS(tbl_WI[BEC Time (seg..)],tbl_WI[ELEMENTO],"*"&$J5&"*",tbl_WI['# Operador],Q$2) -> 0 | R5: =+SUMIFS(tbl_WI[BEC Time (seg..)],tbl_WI[ELEMENTO],"*"&$J5&"*",tbl_WI['# Operador],R$2) -> 0 | ... V5: =+SUMIFS(tbl_WI[BEC Time (seg..)],tbl_WI[ELEMENTO],"*"&$J5&"*",tbl_WI['# Operador],V$2) -> 0
A6: Mapa del Lugar de Trabajo | J6: Instalar | K6: =+SUMIFS(tbl_WI[BEC Time (seg..)],tbl_WI[ELEMENTO],"*"&$J6&"*",tbl_WI['# Operador],K$2) -> 0 | L6: =+SUMIFS(tbl_WI[BEC Time (seg..)],tbl_WI[ELEMENTO],"*"&$J6&"*",tbl_WI['# Operador],L$2) -> 1382 | M6: =+SUMIFS(tbl_WI[BEC Time (seg..)],tbl_WI[ELEMENTO],"*"&$J6&"*",tbl_WI['# Operador],M$2) -> 3276 | N6: =+SUMIFS(tbl_WI[BEC Time (seg..)],tbl_WI[ELEMENTO],"*"&$J6&"*",tbl_WI['# Operador],N$2) -> 728 | O6: =+SUMIFS(tbl_WI[BEC Time (seg..)],tbl_WI[ELEMENTO],"*"&$J6&"*",tbl_WI['# Operador],O$2) -> 49 | P6: =+SUMIFS(tbl_WI[BEC Time (seg..)],tbl_WI[ELEMENTO],"*"&$J6&"*",tbl_WI['# Operador],P$2) -> 4290 | Q6: =+SUMIFS(tbl_WI[BEC Time (seg..)],tbl_WI[ELEMENTO],"*"&$J6&"*",tbl_WI['# Operador],Q$2) -> 746 | R6: =+SUMIFS(tbl_WI[BEC Time (seg..)],tbl_WI[ELEMENTO],"*"&$J6&"*",tbl_WI['# Operador],R$2) -> 0 | ... V6: =+SUMIFS(tbl_WI[BEC Time (seg..)],tbl_WI[ELEMENTO],"*"&$J6&"*",tbl_WI['# Operador],V$2) -> 0
J7: Perforar | K7: =+SUMIFS(tbl_WI[BEC Time (seg..)],tbl_WI[ELEMENTO],"*"&$J7&"*",tbl_WI['# Operador],K$2) -> 0 | L7: =+SUMIFS(tbl_WI[BEC Time (seg..)],tbl_WI[ELEMENTO],"*"&$J7&"*",tbl_WI['# Operador],L$2) -> 0 | M7: =+SUMIFS(tbl_WI[BEC Time (seg..)],tbl_WI[ELEMENTO],"*"&$J7&"*",tbl_WI['# Operador],M$2) -> 0 | N7: =+SUMIFS(tbl_WI[BEC Time (seg..)],tbl_WI[ELEMENTO],"*"&$J7&"*",tbl_WI['# Operador],N$2) -> 0 | O7: =+SUMIFS(tbl_WI[BEC Time (seg..)],tbl_WI[ELEMENTO],"*"&$J7&"*",tbl_WI['# Operador],O$2) -> 0 | P7: =+SUMIFS(tbl_WI[BEC Time (seg..)],tbl_WI[ELEMENTO],"*"&$J7&"*",tbl_WI['# Operador],P$2) -> 0 | Q7: =+SUMIFS(tbl_WI[BEC Time (seg..)],tbl_WI[ELEMENTO],"*"&$J7&"*",tbl_WI['# Operador],Q$2) -> 0 | R7: =+SUMIFS(tbl_WI[BEC Time (seg..)],tbl_WI[ELEMENTO],"*"&$J7&"*",tbl_WI['# Operador],R$2) -> 0 | ... V7: =+SUMIFS(tbl_WI[BEC Time (seg..)],tbl_WI[ELEMENTO],"*"&$J7&"*",tbl_WI['# Operador],V$2) -> 0
J8: Atornillar | K8: =+SUMIFS(tbl_WI[BEC Time (seg..)],tbl_WI[ELEMENTO],"*"&$J8&"*",tbl_WI['# Operador],K$2) -> 0 | L8: =+SUMIFS(tbl_WI[BEC Time (seg..)],tbl_WI[ELEMENTO],"*"&$J8&"*",tbl_WI['# Operador],L$2) -> 0 | M8: =+SUMIFS(tbl_WI[BEC Time (seg..)],tbl_WI[ELEMENTO],"*"&$J8&"*",tbl_WI['# Operador],M$2) -> 0 | N8: =+SUMIFS(tbl_WI[BEC Time (seg..)],tbl_WI[ELEMENTO],"*"&$J8&"*",tbl_WI['# Operador],N$2) -> 0 | O8: =+SUMIFS(tbl_WI[BEC Time (seg..)],tbl_WI[ELEMENTO],"*"&$J8&"*",tbl_WI['# Operador],O$2) -> 0 | P8: =+SUMIFS(tbl_WI[BEC Time (seg..)],tbl_WI[ELEMENTO],"*"&$J8&"*",tbl_WI['# Operador],P$2) -> 0 | Q8: =+SUMIFS(tbl_WI[BEC Time (seg..)],tbl_WI[ELEMENTO],"*"&$J8&"*",tbl_WI['# Operador],Q$2) -> 0 | R8: =+SUMIFS(tbl_WI[BEC Time (seg..)],tbl_WI[ELEMENTO],"*"&$J8&"*",tbl_WI['# Operador],R$2) -> 0 | ... V8: =+SUMIFS(tbl_WI[BEC Time (seg..)],tbl_WI[ELEMENTO],"*"&$J8&"*",tbl_WI['# Operador],V$2) -> 0
J9: Programar | K9: =+SUMIFS(tbl_WI[BEC Time (seg..)],tbl_WI[ELEMENTO],"*"&$J9&"*",tbl_WI['# Operador],K$2) -> 0 | L9: =+SUMIFS(tbl_WI[BEC Time (seg..)],tbl_WI[ELEMENTO],"*"&$J9&"*",tbl_WI['# Operador],L$2) -> 0 | M9: =+SUMIFS(tbl_WI[BEC Time (seg..)],tbl_WI[ELEMENTO],"*"&$J9&"*",tbl_WI['# Operador],M$2) -> 0 | N9: =+SUMIFS(tbl_WI[BEC Time (seg..)],tbl_WI[ELEMENTO],"*"&$J9&"*",tbl_WI['# Operador],N$2) -> 0 | O9: =+SUMIFS(tbl_WI[BEC Time (seg..)],tbl_WI[ELEMENTO],"*"&$J9&"*",tbl_WI['# Operador],O$2) -> 0 | P9: =+SUMIFS(tbl_WI[BEC Time (seg..)],tbl_WI[ELEMENTO],"*"&$J9&"*",tbl_WI['# Operador],P$2) -> 0 | Q9: =+SUMIFS(tbl_WI[BEC Time (seg..)],tbl_WI[ELEMENTO],"*"&$J9&"*",tbl_WI['# Operador],Q$2) -> 0 | R9: =+SUMIFS(tbl_WI[BEC Time (seg..)],tbl_WI[ELEMENTO],"*"&$J9&"*",tbl_WI['# Operador],R$2) -> 0 | ... V9: =+SUMIFS(tbl_WI[BEC Time (seg..)],tbl_WI[ELEMENTO],"*"&$J9&"*",tbl_WI['# Operador],V$2) -> 0
J10: Puntear | K10: =+SUMIFS(tbl_WI[BEC Time (seg..)],tbl_WI[ELEMENTO],"*"&$J10&"*",tbl_WI['# Operador],K$2) -> 0 | L10: =+SUMIFS(tbl_WI[BEC Time (seg..)],tbl_WI[ELEMENTO],"*"&$J10&"*",tbl_WI['# Operador],L$2) -> 0 | M10: =+SUMIFS(tbl_WI[BEC Time (seg..)],tbl_WI[ELEMENTO],"*"&$J10&"*",tbl_WI['# Operador],M$2) -> 0 | N10: =+SUMIFS(tbl_WI[BEC Time (seg..)],tbl_WI[ELEMENTO],"*"&$J10&"*",tbl_WI['# Operador],N$2) -> 0 | O10: =+SUMIFS(tbl_WI[BEC Time (seg..)],tbl_WI[ELEMENTO],"*"&$J10&"*",tbl_WI['# Operador],O$2) -> 0 | P10: =+SUMIFS(tbl_WI[BEC Time (seg..)],tbl_WI[ELEMENTO],"*"&$J10&"*",tbl_WI['# Operador],P$2) -> 0 | Q10: =+SUMIFS(tbl_WI[BEC Time (seg..)],tbl_WI[ELEMENTO],"*"&$J10&"*",tbl_WI['# Operador],Q$2) -> 0 | R10: =+SUMIFS(tbl_WI[BEC Time (seg..)],tbl_WI[ELEMENTO],"*"&$J10&"*",tbl_WI['# Operador],R$2) -> 0 | ... V10: =+SUMIFS(tbl_WI[BEC Time (seg..)],tbl_WI[ELEMENTO],"*"&$J10&"*",tbl_WI['# Operador],V$2) -> 0
J11: Remachar | K11: =+SUMIFS(tbl_WI[BEC Time (seg..)],tbl_WI[ELEMENTO],"*"&$J11&"*",tbl_WI['# Operador],K$2) -> 0 | L11: =+SUMIFS(tbl_WI[BEC Time (seg..)],tbl_WI[ELEMENTO],"*"&$J11&"*",tbl_WI['# Operador],L$2) -> 0 | M11: =+SUMIFS(tbl_WI[BEC Time (seg..)],tbl_WI[ELEMENTO],"*"&$J11&"*",tbl_WI['# Operador],M$2) -> 0 | N11: =+SUMIFS(tbl_WI[BEC Time (seg..)],tbl_WI[ELEMENTO],"*"&$J11&"*",tbl_WI['# Operador],N$2) -> 0 | O11: =+SUMIFS(tbl_WI[BEC Time (seg..)],tbl_WI[ELEMENTO],"*"&$J11&"*",tbl_WI['# Operador],O$2) -> 0 | P11: =+SUMIFS(tbl_WI[BEC Time (seg..)],tbl_WI[ELEMENTO],"*"&$J11&"*",tbl_WI['# Operador],P$2) -> 0 | Q11: =+SUMIFS(tbl_WI[BEC Time (seg..)],tbl_WI[ELEMENTO],"*"&$J11&"*",tbl_WI['# Operador],Q$2) -> 0 | R11: =+SUMIFS(tbl_WI[BEC Time (seg..)],tbl_WI[ELEMENTO],"*"&$J11&"*",tbl_WI['# Operador],R$2) -> 0 | ... V11: =+SUMIFS(tbl_WI[BEC Time (seg..)],tbl_WI[ELEMENTO],"*"&$J11&"*",tbl_WI['# Operador],V$2) -> 0
J12: Rutear | K12: =+SUMIFS(tbl_WI[BEC Time (seg..)],tbl_WI[ELEMENTO],"*"&$J12&"*",tbl_WI['# Operador],K$2) -> 0 | L12: =+SUMIFS(tbl_WI[BEC Time (seg..)],tbl_WI[ELEMENTO],"*"&$J12&"*",tbl_WI['# Operador],L$2) -> 0 | M12: =+SUMIFS(tbl_WI[BEC Time (seg..)],tbl_WI[ELEMENTO],"*"&$J12&"*",tbl_WI['# Operador],M$2) -> 0 | N12: =+SUMIFS(tbl_WI[BEC Time (seg..)],tbl_WI[ELEMENTO],"*"&$J12&"*",tbl_WI['# Operador],N$2) -> 0 | O12: =+SUMIFS(tbl_WI[BEC Time (seg..)],tbl_WI[ELEMENTO],"*"&$J12&"*",tbl_WI['# Operador],O$2) -> 0 | P12: =+SUMIFS(tbl_WI[BEC Time (seg..)],tbl_WI[ELEMENTO],"*"&$J12&"*",tbl_WI['# Operador],P$2) -> 0 | Q12: =+SUMIFS(tbl_WI[BEC Time (seg..)],tbl_WI[ELEMENTO],"*"&$J12&"*",tbl_WI['# Operador],Q$2) -> 0 | R12: =+SUMIFS(tbl_WI[BEC Time (seg..)],tbl_WI[ELEMENTO],"*"&$J12&"*",tbl_WI['# Operador],R$2) -> 0 | ... V12: =+SUMIFS(tbl_WI[BEC Time (seg..)],tbl_WI[ELEMENTO],"*"&$J12&"*",tbl_WI['# Operador],V$2) -> 0
J13: % | K13: =(SUM(K3:K12)/('Master Sheet'!$F$5)) -> 0.73213636 | L13: =(SUM(L3:L12)/('Master Sheet'!$F$5)) -> 0.56089091 | M13: =(SUM(M3:M12)/('Master Sheet'!$F$5)) -> 1.1614909 | N13: =(SUM(N3:N12)/('Master Sheet'!$F$5)) -> 0.4212 | O13: =(SUM(O3:O12)/('Master Sheet'!$F$5)) -> 0.29001818 | P13: =(SUM(P3:P12)/('Master Sheet'!$F$5)) -> 1.5497182 | Q13: =(SUM(Q3:Q12)/('Master Sheet'!$F$5)) -> 0.57826364 | R13: =(SUM(R3:R12)/('Master Sheet'!$F$5)) -> 0 | ... V13: =(SUM(V3:V12)/('Master Sheet'!$F$5)) -> 0
J14: Abrir | K14: =+SUMIFS(tbl_WI[Work Time (seg…)],tbl_WI[ELEMENTO],"*"&$J14&"*",tbl_WI['# Operador],K$2) -> 0 | L14: =+SUMIFS(tbl_WI[Work Time (seg…)],tbl_WI[ELEMENTO],"*"&$J14&"*",tbl_WI['# Operador],L$2) -> 0 | M14: =+SUMIFS(tbl_WI[Work Time (seg…)],tbl_WI[ELEMENTO],"*"&$J14&"*",tbl_WI['# Operador],M$2) -> 0 | N14: =+SUMIFS(tbl_WI[Work Time (seg…)],tbl_WI[ELEMENTO],"*"&$J14&"*",tbl_WI['# Operador],N$2) -> 0 | O14: =+SUMIFS(tbl_WI[Work Time (seg…)],tbl_WI[ELEMENTO],"*"&$J14&"*",tbl_WI['# Operador],O$2) -> 0 | P14: =+SUMIFS(tbl_WI[Work Time (seg…)],tbl_WI[ELEMENTO],"*"&$J14&"*",tbl_WI['# Operador],P$2) -> 0 | Q14: =+SUMIFS(tbl_WI[Work Time (seg…)],tbl_WI[ELEMENTO],"*"&$J14&"*",tbl_WI['# Operador],Q$2) -> 0 | R14: =+SUMIFS(tbl_WI[Work Time (seg…)],tbl_WI[ELEMENTO],"*"&$J14&"*",tbl_WI['# Operador],R$2) -> 0 | ... V14: =+SUMIFS(tbl_WI[Work Time (seg…)],tbl_WI[ELEMENTO],"*"&$J14&"*",tbl_WI['# Operador],V$2) -> 0
J15: Activar | K15: =+SUMIFS(tbl_WI[Work Time (seg…)],tbl_WI[ELEMENTO],"*"&$J15&"*",tbl_WI['# Operador],K$2) -> 0 | L15: =+SUMIFS(tbl_WI[Work Time (seg…)],tbl_WI[ELEMENTO],"*"&$J15&"*",tbl_WI['# Operador],L$2) -> 0 | M15: =+SUMIFS(tbl_WI[Work Time (seg…)],tbl_WI[ELEMENTO],"*"&$J15&"*",tbl_WI['# Operador],M$2) -> 0 | N15: =+SUMIFS(tbl_WI[Work Time (seg…)],tbl_WI[ELEMENTO],"*"&$J15&"*",tbl_WI['# Operador],N$2) -> 0 | O15: =+SUMIFS(tbl_WI[Work Time (seg…)],tbl_WI[ELEMENTO],"*"&$J15&"*",tbl_WI['# Operador],O$2) -> 0 | P15: =+SUMIFS(tbl_WI[Work Time (seg…)],tbl_WI[ELEMENTO],"*"&$J15&"*",tbl_WI['# Operador],P$2) -> 0 | Q15: =+SUMIFS(tbl_WI[Work Time (seg…)],tbl_WI[ELEMENTO],"*"&$J15&"*",tbl_WI['# Operador],Q$2) -> 0 | R15: =+SUMIFS(tbl_WI[Work Time (seg…)],tbl_WI[ELEMENTO],"*"&$J15&"*",tbl_WI['# Operador],R$2) -> 0 | ... V15: =+SUMIFS(tbl_WI[Work Time (seg…)],tbl_WI[ELEMENTO],"*"&$J15&"*",tbl_WI['# Operador],V$2) -> 0
J16: Aflojar | K16: =+SUMIFS(tbl_WI[Work Time (seg…)],tbl_WI[ELEMENTO],"*"&$J16&"*",tbl_WI['# Operador],K$2) -> 0 | L16: =+SUMIFS(tbl_WI[Work Time (seg…)],tbl_WI[ELEMENTO],"*"&$J16&"*",tbl_WI['# Operador],L$2) -> 0 | M16: =+SUMIFS(tbl_WI[Work Time (seg…)],tbl_WI[ELEMENTO],"*"&$J16&"*",tbl_WI['# Operador],M$2) -> 0 | N16: =+SUMIFS(tbl_WI[Work Time (seg…)],tbl_WI[ELEMENTO],"*"&$J16&"*",tbl_WI['# Operador],N$2) -> 0 | O16: =+SUMIFS(tbl_WI[Work Time (seg…)],tbl_WI[ELEMENTO],"*"&$J16&"*",tbl_WI['# Operador],O$2) -> 0 | P16: =+SUMIFS(tbl_WI[Work Time (seg…)],tbl_WI[ELEMENTO],"*"&$J16&"*",tbl_WI['# Operador],P$2) -> 0 | Q16: =+SUMIFS(tbl_WI[Work Time (seg…)],tbl_WI[ELEMENTO],"*"&$J16&"*",tbl_WI['# Operador],Q$2) -> 0 | R16: =+SUMIFS(tbl_WI[Work Time (seg…)],tbl_WI[ELEMENTO],"*"&$J16&"*",tbl_WI['# Operador],R$2) -> 0 | ... V16: =+SUMIFS(tbl_WI[Work Time (seg…)],tbl_WI[ELEMENTO],"*"&$J16&"*",tbl_WI['# Operador],V$2) -> 0
J17: Ajustar | K17: =+SUMIFS(tbl_WI[Work Time (seg…)],tbl_WI[ELEMENTO],"*"&$J17&"*",tbl_WI['# Operador],K$2) -> 0 | L17: =+SUMIFS(tbl_WI[Work Time (seg…)],tbl_WI[ELEMENTO],"*"&$J17&"*",tbl_WI['# Operador],L$2) -> 0 | M17: =+SUMIFS(tbl_WI[Work Time (seg…)],tbl_WI[ELEMENTO],"*"&$J17&"*",tbl_WI['# Operador],M$2) -> 0 | N17: =+SUMIFS(tbl_WI[Work Time (seg…)],tbl_WI[ELEMENTO],"*"&$J17&"*",tbl_WI['# Operador],N$2) -> 0 | O17: =+SUMIFS(tbl_WI[Work Time (seg…)],tbl_WI[ELEMENTO],"*"&$J17&"*",tbl_WI['# Operador],O$2) -> 0 | P17: =+SUMIFS(tbl_WI[Work Time (seg…)],tbl_WI[ELEMENTO],"*"&$J17&"*",tbl_WI['# Operador],P$2) -> 0 | Q17: =+SUMIFS(tbl_WI[Work Time (seg…)],tbl_WI[ELEMENTO],"*"&$J17&"*",tbl_WI['# Operador],Q$2) -> 0 | R17: =+SUMIFS(tbl_WI[Work Time (seg…)],tbl_WI[ELEMENTO],"*"&$J17&"*",tbl_WI['# Operador],R$2) -> 0 | ... V17: =+SUMIFS(tbl_WI[Work Time (seg…)],tbl_WI[ELEMENTO],"*"&$J17&"*",tbl_WI['# Operador],V$2) -> 0
J18: Cerrar | K18: =+SUMIFS(tbl_WI[Work Time (seg…)],tbl_WI[ELEMENTO],"*"&$J18&"*",tbl_WI['# Operador],K$2) -> 0 | L18: =+SUMIFS(tbl_WI[Work Time (seg…)],tbl_WI[ELEMENTO],"*"&$J18&"*",tbl_WI['# Operador],L$2) -> 0 | M18: =+SUMIFS(tbl_WI[Work Time (seg…)],tbl_WI[ELEMENTO],"*"&$J18&"*",tbl_WI['# Operador],M$2) -> 0 | N18: =+SUMIFS(tbl_WI[Work Time (seg…)],tbl_WI[ELEMENTO],"*"&$J18&"*",tbl_WI['# Operador],N$2) -> 0 | O18: =+SUMIFS(tbl_WI[Work Time (seg…)],tbl_WI[ELEMENTO],"*"&$J18&"*",tbl_WI['# Operador],O$2) -> 0 | P18: =+SUMIFS(tbl_WI[Work Time (seg…)],tbl_WI[ELEMENTO],"*"&$J18&"*",tbl_WI['# Operador],P$2) -> 0 | Q18: =+SUMIFS(tbl_WI[Work Time (seg…)],tbl_WI[ELEMENTO],"*"&$J18&"*",tbl_WI['# Operador],Q$2) -> 0 | R18: =+SUMIFS(tbl_WI[Work Time (seg…)],tbl_WI[ELEMENTO],"*"&$J18&"*",tbl_WI['# Operador],R$2) -> 0 | ... V18: =+SUMIFS(tbl_WI[Work Time (seg…)],tbl_WI[ELEMENTO],"*"&$J18&"*",tbl_WI['# Operador],V$2) -> 0
J19: Colocar | K19: =+SUMIFS(tbl_WI[Work Time (seg…)],tbl_WI[ELEMENTO],"*"&$J19&"*",tbl_WI['# Operador],K$2) -> 0 | L19: =+SUMIFS(tbl_WI[Work Time (seg…)],tbl_WI[ELEMENTO],"*"&$J19&"*",tbl_WI['# Operador],L$2) -> 84 | M19: =+SUMIFS(tbl_WI[Work Time (seg…)],tbl_WI[ELEMENTO],"*"&$J19&"*",tbl_WI['# Operador],M$2) -> 328 | N19: =+SUMIFS(tbl_WI[Work Time (seg…)],tbl_WI[ELEMENTO],"*"&$J19&"*",tbl_WI['# Operador],N$2) -> 0 | O19: =+SUMIFS(tbl_WI[Work Time (seg…)],tbl_WI[ELEMENTO],"*"&$J19&"*",tbl_WI['# Operador],O$2) -> 0 | P19: =+SUMIFS(tbl_WI[Work Time (seg…)],tbl_WI[ELEMENTO],"*"&$J19&"*",tbl_WI['# Operador],P$2) -> 53 | Q19: =+SUMIFS(tbl_WI[Work Time (seg…)],tbl_WI[ELEMENTO],"*"&$J19&"*",tbl_WI['# Operador],Q$2) -> 71 | R19: =+SUMIFS(tbl_WI[Work Time (seg…)],tbl_WI[ELEMENTO],"*"&$J19&"*",tbl_WI['# Operador],R$2) -> 0 | ... V19: =+SUMIFS(tbl_WI[Work Time (seg…)],tbl_WI[ELEMENTO],"*"&$J19&"*",tbl_WI['# Operador],V$2) -> 0
J20: Cortar | K20: =+SUMIFS(tbl_WI[Work Time (seg…)],tbl_WI[ELEMENTO],"*"&$J20&"*",tbl_WI['# Operador],K$2) -> 0 | L20: =+SUMIFS(tbl_WI[Work Time (seg…)],tbl_WI[ELEMENTO],"*"&$J20&"*",tbl_WI['# Operador],L$2) -> 0 | M20: =+SUMIFS(tbl_WI[Work Time (seg…)],tbl_WI[ELEMENTO],"*"&$J20&"*",tbl_WI['# Operador],M$2) -> 0 | N20: =+SUMIFS(tbl_WI[Work Time (seg…)],tbl_WI[ELEMENTO],"*"&$J20&"*",tbl_WI['# Operador],N$2) -> 0 | O20: =+SUMIFS(tbl_WI[Work Time (seg…)],tbl_WI[ELEMENTO],"*"&$J20&"*",tbl_WI['# Operador],O$2) -> 0 | P20: =+SUMIFS(tbl_WI[Work Time (seg…)],tbl_WI[ELEMENTO],"*"&$J20&"*",tbl_WI['# Operador],P$2) -> 0 | Q20: =+SUMIFS(tbl_WI[Work Time (seg…)],tbl_WI[ELEMENTO],"*"&$J20&"*",tbl_WI['# Operador],Q$2) -> 0 | R20: =+SUMIFS(tbl_WI[Work Time (seg…)],tbl_WI[ELEMENTO],"*"&$J20&"*",tbl_WI['# Operador],R$2) -> 0 | ... V20: =+SUMIFS(tbl_WI[Work Time (seg…)],tbl_WI[ELEMENTO],"*"&$J20&"*",tbl_WI['# Operador],V$2) -> 0
J21: Dejar | K21: =+SUMIFS(tbl_WI[Work Time (seg…)],tbl_WI[ELEMENTO],"*"&$J21&"*",tbl_WI['# Operador],K$2) -> 0 | L21: =+SUMIFS(tbl_WI[Work Time (seg…)],tbl_WI[ELEMENTO],"*"&$J21&"*",tbl_WI['# Operador],L$2) -> 0 | M21: =+SUMIFS(tbl_WI[Work Time (seg…)],tbl_WI[ELEMENTO],"*"&$J21&"*",tbl_WI['# Operador],M$2) -> 0 | N21: =+SUMIFS(tbl_WI[Work Time (seg…)],tbl_WI[ELEMENTO],"*"&$J21&"*",tbl_WI['# Operador],N$2) -> 0 | O21: =+SUMIFS(tbl_WI[Work Time (seg…)],tbl_WI[ELEMENTO],"*"&$J21&"*",tbl_WI['# Operador],O$2) -> 0 | P21: =+SUMIFS(tbl_WI[Work Time (seg…)],tbl_WI[ELEMENTO],"*"&$J21&"*",tbl_WI['# Operador],P$2) -> 0 | Q21: =+SUMIFS(tbl_WI[Work Time (seg…)],tbl_WI[ELEMENTO],"*"&$J21&"*",tbl_WI['# Operador],Q$2) -> 0 | R21: =+SUMIFS(tbl_WI[Work Time (seg…)],tbl_WI[ELEMENTO],"*"&$J21&"*",tbl_WI['# Operador],R$2) -> 0 | ... V21: =+SUMIFS(tbl_WI[Work Time (seg…)],tbl_WI[ELEMENTO],"*"&$J21&"*",tbl_WI['# Operador],V$2) -> 0
J22: Encender | K22: =+SUMIFS(tbl_WI[Work Time (seg…)],tbl_WI[ELEMENTO],"*"&$J22&"*",tbl_WI['# Operador],K$2) -> 0 | L22: =+SUMIFS(tbl_WI[Work Time (seg…)],tbl_WI[ELEMENTO],"*"&$J22&"*",tbl_WI['# Operador],L$2) -> 0 | M22: =+SUMIFS(tbl_WI[Work Time (seg…)],tbl_WI[ELEMENTO],"*"&$J22&"*",tbl_WI['# Operador],M$2) -> 0 | N22: =+SUMIFS(tbl_WI[Work Time (seg…)],tbl_WI[ELEMENTO],"*"&$J22&"*",tbl_WI['# Operador],N$2) -> 0 | O22: =+SUMIFS(tbl_WI[Work Time (seg…)],tbl_WI[ELEMENTO],"*"&$J22&"*",tbl_WI['# Operador],O$2) -> 0 | P22: =+SUMIFS(tbl_WI[Work Time (seg…)],tbl_WI[ELEMENTO],"*"&$J22&"*",tbl_WI['# Operador],P$2) -> 0 | Q22: =+SUMIFS(tbl_WI[Work Time (seg…)],tbl_WI[ELEMENTO],"*"&$J22&"*",tbl_WI['# Operador],Q$2) -> 0 | R22: =+SUMIFS(tbl_WI[Work Time (seg…)],tbl_WI[ELEMENTO],"*"&$J22&"*",tbl_WI['# Operador],R$2) -> 0 | ... V22: =+SUMIFS(tbl_WI[Work Time (seg…)],tbl_WI[ELEMENTO],"*"&$J22&"*",tbl_WI['# Operador],V$2) -> 0
J23: Firmar | K23: =+SUMIFS(tbl_WI[Work Time (seg…)],tbl_WI[ELEMENTO],"*"&$J23&"*",tbl_WI['# Operador],K$2) -> 0 | L23: =+SUMIFS(tbl_WI[Work Time (seg…)],tbl_WI[ELEMENTO],"*"&$J23&"*",tbl_WI['# Operador],L$2) -> 0 | M23: =+SUMIFS(tbl_WI[Work Time (seg…)],tbl_WI[ELEMENTO],"*"&$J23&"*",tbl_WI['# Operador],M$2) -> 0 | N23: =+SUMIFS(tbl_WI[Work Time (seg…)],tbl_WI[ELEMENTO],"*"&$J23&"*",tbl_WI['# Operador],N$2) -> 0 | O23: =+SUMIFS(tbl_WI[Work Time (seg…)],tbl_WI[ELEMENTO],"*"&$J23&"*",tbl_WI['# Operador],O$2) -> 0 | P23: =+SUMIFS(tbl_WI[Work Time (seg…)],tbl_WI[ELEMENTO],"*"&$J23&"*",tbl_WI['# Operador],P$2) -> 0 | Q23: =+SUMIFS(tbl_WI[Work Time (seg…)],tbl_WI[ELEMENTO],"*"&$J23&"*",tbl_WI['# Operador],Q$2) -> 166 | R23: =+SUMIFS(tbl_WI[Work Time (seg…)],tbl_WI[ELEMENTO],"*"&$J23&"*",tbl_WI['# Operador],R$2) -> 0 | ... V23: =+SUMIFS(tbl_WI[Work Time (seg…)],tbl_WI[ELEMENTO],"*"&$J23&"*",tbl_WI['# Operador],V$2) -> 0
J24: Marcar | K24: =+SUMIFS(tbl_WI[Work Time (seg…)],tbl_WI[ELEMENTO],"*"&$J24&"*",tbl_WI['# Operador],K$2) -> 0 | L24: =+SUMIFS(tbl_WI[Work Time (seg…)],tbl_WI[ELEMENTO],"*"&$J24&"*",tbl_WI['# Operador],L$2) -> 0 | M24: =+SUMIFS(tbl_WI[Work Time (seg…)],tbl_WI[ELEMENTO],"*"&$J24&"*",tbl_WI['# Operador],M$2) -> 0 | N24: =+SUMIFS(tbl_WI[Work Time (seg…)],tbl_WI[ELEMENTO],"*"&$J24&"*",tbl_WI['# Operador],N$2) -> 0 | O24: =+SUMIFS(tbl_WI[Work Time (seg…)],tbl_WI[ELEMENTO],"*"&$J24&"*",tbl_WI['# Operador],O$2) -> 0 | P24: =+SUMIFS(tbl_WI[Work Time (seg…)],tbl_WI[ELEMENTO],"*"&$J24&"*",tbl_WI['# Operador],P$2) -> 0 | Q24: =+SUMIFS(tbl_WI[Work Time (seg…)],tbl_WI[ELEMENTO],"*"&$J24&"*",tbl_WI['# Operador],Q$2) -> 0 | R24: =+SUMIFS(tbl_WI[Work Time (seg…)],tbl_WI[ELEMENTO],"*"&$J24&"*",tbl_WI['# Operador],R$2) -> 0 | ... V24: =+SUMIFS(tbl_WI[Work Time (seg…)],tbl_WI[ELEMENTO],"*"&$J24&"*",tbl_WI['# Operador],V$2) -> 0
J25: Guiar | K25: =+SUMIFS(tbl_WI[Work Time (seg…)],tbl_WI[ELEMENTO],"*"&$J25&"*",tbl_WI['# Operador],K$2) -> 0 | L25: =+SUMIFS(tbl_WI[Work Time (seg…)],tbl_WI[ELEMENTO],"*"&$J25&"*",tbl_WI['# Operador],L$2) -> 0 | M25: =+SUMIFS(tbl_WI[Work Time (seg…)],tbl_WI[ELEMENTO],"*"&$J25&"*",tbl_WI['# Operador],M$2) -> 0 | N25: =+SUMIFS(tbl_WI[Work Time (seg…)],tbl_WI[ELEMENTO],"*"&$J25&"*",tbl_WI['# Operador],N$2) -> 0 | O25: =+SUMIFS(tbl_WI[Work Time (seg…)],tbl_WI[ELEMENTO],"*"&$J25&"*",tbl_WI['# Operador],O$2) -> 0 | P25: =+SUMIFS(tbl_WI[Work Time (seg…)],tbl_WI[ELEMENTO],"*"&$J25&"*",tbl_WI['# Operador],P$2) -> 0 | Q25: =+SUMIFS(tbl_WI[Work Time (seg…)],tbl_WI[ELEMENTO],"*"&$J25&"*",tbl_WI['# Operador],Q$2) -> 0 | R25: =+SUMIFS(tbl_WI[Work Time (seg…)],tbl_WI[ELEMENTO],"*"&$J25&"*",tbl_WI['# Operador],R$2) -> 0 | ... V25: =+SUMIFS(tbl_WI[Work Time (seg…)],tbl_WI[ELEMENTO],"*"&$J25&"*",tbl_WI['# Operador],V$2) -> 0
... J34: Verificar | K34: =+SUMIFS(tbl_WI[Work Time (seg…)],tbl_WI[ELEMENTO],"*"&$J34&"*",tbl_WI['# Operador],K$2) -> 0 | L34: =+SUMIFS(tbl_WI[Work Time (seg…)],tbl_WI[ELEMENTO],"*"&$J34&"*",tbl_WI['# Operador],L$2) -> 0 | M34: =+SUMIFS(tbl_WI[Work Time (seg…)],tbl_WI[ELEMENTO],"*"&$J34&"*",tbl_WI['# Operador],M$2) -> 52 | N34: =+SUMIFS(tbl_WI[Work Time (seg…)],tbl_WI[ELEMENTO],"*"&$J34&"*",tbl_WI['# Operador],N$2) -> 0 | O34: =+SUMIFS(tbl_WI[Work Time (seg…)],tbl_WI[ELEMENTO],"*"&$J34&"*",tbl_WI['# Operador],O$2) -> 8 | P34: =+SUMIFS(tbl_WI[Work Time (seg…)],tbl_WI[ELEMENTO],"*"&$J34&"*",tbl_WI['# Operador],P$2) -> 702 | Q34: =+SUMIFS(tbl_WI[Work Time (seg…)],tbl_WI[ELEMENTO],"*"&$J34&"*",tbl_WI['# Operador],Q$2) -> 1278 | R34: =+SUMIFS(tbl_WI[Work Time (seg…)],tbl_WI[ELEMENTO],"*"&$J34&"*",tbl_WI['# Operador],R$2) -> 0 | ... V34: =+SUMIFS(tbl_WI[Work Time (seg…)],tbl_WI[ELEMENTO],"*"&$J34&"*",tbl_WI['# Operador],V$2) -> 0
A35: # | B35: ELEMENTO | C35: # Operador | D35: BEC Time (seg..) | E35: Work Time (seg…) | F35: Tiempo de Espera (seg..) | G35: Tiempo de Caminatas (seg..) | J35: % | K35: =(SUM(K14:K34)/('Master Sheet'!$F$5)) -> 0.040063636 | L35: =(SUM(L14:L34)/('Master Sheet'!$F$5)) -> 0.036518182 | M35: =(SUM(M14:M34)/('Master Sheet'!$F$5)) -> 0.13472727 | N35: =(SUM(N14:N34)/('Master Sheet'!$F$5)) -> 0 | O35: =(SUM(O14:O34)/('Master Sheet'!$F$5)) -> 0.020563636 | P35: =(SUM(P14:P34)/('Master Sheet'!$F$5)) -> 0.35596364 | Q35: =(SUM(Q14:Q34)/('Master Sheet'!$F$5)) -> 0.60769091 | R35: =(SUM(R14:R34)/('Master Sheet'!$F$5)) -> 0 | ... V35: =(SUM(V14:V34)/('Master Sheet'!$F$5)) -> 0
B36: Fabricacion | C36: 1 | J36: Caminar | K36: =+SUMIFS(tbl_WI[Tiempo de Caminatas (seg..)],tbl_WI[ELEMENTO],"*"&$J36&"*",tbl_WI['# Operador],K$2) -> 0 | L36: =+SUMIFS(tbl_WI[Tiempo de Caminatas (seg..)],tbl_WI[ELEMENTO],"*"&$J36&"*",tbl_WI['# Operador],L$2) -> 0 | M36: =+SUMIFS(tbl_WI[Tiempo de Caminatas (seg..)],tbl_WI[ELEMENTO],"*"&$J36&"*",tbl_WI['# Operador],M$2) -> 0 | N36: =+SUMIFS(tbl_WI[Tiempo de Caminatas (seg..)],tbl_WI[ELEMENTO],"*"&$J36&"*",tbl_WI['# Operador],N$2) -> 188 | O36: =+SUMIFS(tbl_WI[Tiempo de Caminatas (seg..)],tbl_WI[ELEMENTO],"*"&$J36&"*",tbl_WI['# Operador],O$2) -> 0 | P36: =+SUMIFS(tbl_WI[Tiempo de Caminatas (seg..)],tbl_WI[ELEMENTO],"*"&$J36&"*",tbl_WI['# Operador],P$2) -> 0 | Q36: =+SUMIFS(tbl_WI[Tiempo de Caminatas (seg..)],tbl_WI[ELEMENTO],"*"&$J36&"*",tbl_WI['# Operador],Q$2) -> 482 | R36: =+SUMIFS(tbl_WI[Tiempo de Caminatas (seg..)],tbl_WI[ELEMENTO],"*"&$J36&"*",tbl_WI['# Operador],R$2) -> 0 | ... V36: =+SUMIFS(tbl_WI[Tiempo de Caminatas (seg..)],tbl_WI[ELEMENTO],"*"&$J36&"*",tbl_WI['# Operador],V$2) -> 0
B37: Estacion #1-Fabricacion subensamble | C37: 1 | J37: Trasladar | K37: =+SUMIFS(tbl_WI[Tiempo de Caminatas (seg..)],tbl_WI[ELEMENTO],"*"&$J37&"*",tbl_WI['# Operador],K$2) -> 0 | L37: =+SUMIFS(tbl_WI[Tiempo de Caminatas (seg..)],tbl_WI[ELEMENTO],"*"&$J37&"*",tbl_WI['# Operador],L$2) -> 0 | M37: =+SUMIFS(tbl_WI[Tiempo de Caminatas (seg..)],tbl_WI[ELEMENTO],"*"&$J37&"*",tbl_WI['# Operador],M$2) -> 148 | N37: =+SUMIFS(tbl_WI[Tiempo de Caminatas (seg..)],tbl_WI[ELEMENTO],"*"&$J37&"*",tbl_WI['# Operador],N$2) -> 859 | O37: =+SUMIFS(tbl_WI[Tiempo de Caminatas (seg..)],tbl_WI[ELEMENTO],"*"&$J37&"*",tbl_WI['# Operador],O$2) -> 0 | P37: =+SUMIFS(tbl_WI[Tiempo de Caminatas (seg..)],tbl_WI[ELEMENTO],"*"&$J37&"*",tbl_WI['# Operador],P$2) -> 408 | Q37: =+SUMIFS(tbl_WI[Tiempo de Caminatas (seg..)],tbl_WI[ELEMENTO],"*"&$J37&"*",tbl_WI['# Operador],Q$2) -> 390 | R37: =+SUMIFS(tbl_WI[Tiempo de Caminatas (seg..)],tbl_WI[ELEMENTO],"*"&$J37&"*",tbl_WI['# Operador],R$2) -> 0 | ... V37: =+SUMIFS(tbl_WI[Tiempo de Caminatas (seg..)],tbl_WI[ELEMENTO],"*"&$J37&"*",tbl_WI['# Operador],V$2) -> 0
A38: 1 | B38: Preparar material | C38: 1 | E38: 113 | J38: % | K38: =(SUM(K36:K37)/('Master Sheet'!$F$5)) -> 0 | L38: =(SUM(L36:L37)/('Master Sheet'!$F$5)) -> 0 | M38: =(SUM(M36:M37)/('Master Sheet'!$F$5)) -> 0.052472727 | N38: =(SUM(N36:N37)/('Master Sheet'!$F$5)) -> 0.37120909 | O38: =(SUM(O36:O37)/('Master Sheet'!$F$5)) -> 0 | P38: =(SUM(P36:P37)/('Master Sheet'!$F$5)) -> 0.14465455 | Q38: =(SUM(Q36:Q37)/('Master Sheet'!$F$5)) -> 0.30916364 | R38: =(SUM(R36:R37)/('Master Sheet'!$F$5)) -> 0 | ... V38: =(SUM(V36:V37)/('Master Sheet'!$F$5)) -> 0
A39: =+A38+1 -> 2 | B39: Elaborar subensamble MTL-02356-04;80 1/4 | C39: 1 | D39: =300+46 -> 346 | J39: Esperar | K39: =+SUMIFS(tbl_WI[Tiempo de Espera (seg..)],tbl_WI[ELEMENTO],"*"&$J39&"*",tbl_WI['# Operador],K$2) -> 0 | L39: =+SUMIFS(tbl_WI[Tiempo de Espera (seg..)],tbl_WI[ELEMENTO],"*"&$J39&"*",tbl_WI['# Operador],L$2) -> 0 | M39: =+SUMIFS(tbl_WI[Tiempo de Espera (seg..)],tbl_WI[ELEMENTO],"*"&$J39&"*",tbl_WI['# Operador],M$2) -> 0 | N39: =+SUMIFS(tbl_WI[Tiempo de Espera (seg..)],tbl_WI[ELEMENTO],"*"&$J39&"*",tbl_WI['# Operador],N$2) -> 0 | O39: =+SUMIFS(tbl_WI[Tiempo de Espera (seg..)],tbl_WI[ELEMENTO],"*"&$J39&"*",tbl_WI['# Operador],O$2) -> 0 | P39: =+SUMIFS(tbl_WI[Tiempo de Espera (seg..)],tbl_WI[ELEMENTO],"*"&$J39&"*",tbl_WI['# Operador],P$2) -> 633 | Q39: =+SUMIFS(tbl_WI[Tiempo de Espera (seg..)],tbl_WI[ELEMENTO],"*"&$J39&"*",tbl_WI['# Operador],Q$2) -> 234 | R39: =+SUMIFS(tbl_WI[Tiempo de Espera (seg..)],tbl_WI[ELEMENTO],"*"&$J39&"*",tbl_WI['# Operador],R$2) -> 0 | ... V39: =+SUMIFS(tbl_WI[Tiempo de Espera (seg..)],tbl_WI[ELEMENTO],"*"&$J39&"*",tbl_WI['# Operador],V$2) -> 0
A40: =+A39+1 -> 3 | B40: Elaborar subensamble MTL-02356-04;80 2/4 | C40: 1 | D40: =300+38 -> 338 | J40: % | K40: =(SUM(K39)/('Master Sheet'!$F$5)) -> 0 | L40: =(SUM(L39)/('Master Sheet'!$F$5)) -> 0 | M40: =(SUM(M39)/('Master Sheet'!$F$5)) -> 0 | N40: =(SUM(N39)/('Master Sheet'!$F$5)) -> 0 | O40: =(SUM(O39)/('Master Sheet'!$F$5)) -> 0 | P40: =(SUM(P39)/('Master Sheet'!$F$5)) -> 0.22442727 | Q40: =(SUM(Q39)/('Master Sheet'!$F$5)) -> 0.082963636 | R40: =(SUM(R39)/('Master Sheet'!$F$5)) -> 0 | ... V40: =(SUM(V39)/('Master Sheet'!$F$5)) -> 0
A41: =+A40+1 -> 4 | B41: Elaborar subensamble MTL-02356-04;80 3/4 | C41: 1 | D41: 350
A42: =+A41+1 -> 5 | B42: Elaborar subensamble MTL-02356-04;80 4/4 | C42: 1 | D42: 375
A43: =+A42+1 -> 6 | B43: Elaborar subensamble ASY/05275-01;A0 1/6 | C43: 1 | D43: =60+36 -> 96
A44: =+A43+1 -> 7 | B44: Elaborar subensamble ASY/05275-01;A0 2/6 | C44: 1 | D44: =60+55 -> 115
A45: =+A44+1 -> 8 | B45: Elaborar subensamble ASY/05275-01;A0 3/6 | C45: 1 | D45: =60+58 -> 118
A46: =+A45+1 -> 9 | B46: Elaborar subensamble ASY/05275-01;A0 4/6 | C46: 1 | D46: =60+49 -> 109
A47: =+A46+1 -> 10 | B47: Elaborar subensamble ASY/05275-01;A0 5/6 | C47: 1 | D47: =60+37 -> 97
A48: =+A47+1 -> 11 | B48: Elaborar subensamble ASY/05275-01;A0 6/6 | C48: 1 | D48: 121
...

Sheet Pillar Chart  NORTHFACE
B2: =+'NORTH FACE'!C3 -> NORTH FACE
C45: =+'NORTH FACE'!B37 -> Estacion #1-Fabricacion subensamble | D45: =+'NORTH FACE'!B49 -> Estacion #2-Fabricacion | E45: =+'NORTH FACE'!B56 -> Estacion #3-Fabricacion | F45: =+'NORTH FACE'!B75 -> Estacion #4-H | G45: =+'NORTH FACE'!B89 -> Estacion #5-H Subensamble | H45: =+'NORTH FACE'!B101 -> Estacion #6-Ensamble completo | I45: =+'NORTH FACE'!B134 -> Estacion #7-Integracion | J45: =+'NORTH FACE'!B198 -> Estacion #9-Empaque | K45: PROMEDIO
C46: 1 | D46: 2 | E46: 3 | F46: 4 | G46: 5 | H46: 6 | I46: 7 | J46: 8
B47: MPH | C47: =(C48*60)/C49 -> 46.332 | D47: =(D48*60)/D49 -> 35.844545 | E47: =(E48*60)/E49 -> 80.921455 | F47: =(F48*60)/F49 -> 47.544545 | G47: =(G48*60)/G49 -> 18.634909 | H47: =(H48*60)/H49 -> 136.48582 | I47: =(I48*60)/I49 -> 94.684909 | J47: =(J48*60)/J49 -> 0 | K47: =SUM(C47:J47) -> 460.44818
B48: Cycle Time | C48: =SUM(C50:C53) -> 36.3 | D48: =SUM(D50:D53) -> 28.083333 | E48: =SUM(E50:E53) -> 63.4 | F48: =SUM(F50:F53) -> 37.25 | G48: =SUM(G50:G53) -> 14.6 | H48: =SUM(H50:H53) -> 106.93333 | I48: =SUM(I50:I53) -> 74.183333 | J48: =SUM(J50:J53) -> 0 | K48: =SUM(C48:J48) -> 360.75
B49: Takt Time | C49: =+'Master Sheet'!$G$5 -> 47.008547 | D49: =+'Master Sheet'!$G$5 -> 47.008547 | E49: =+'Master Sheet'!$G$5 -> 47.008547 | F49: =+'Master Sheet'!$G$5 -> 47.008547 | G49: =+'Master Sheet'!$G$5 -> 47.008547 | H49: =+'Master Sheet'!$G$5 -> 47.008547 | I49: =+'Master Sheet'!$G$5 -> 47.008547 | J49: =+'Master Sheet'!$G$5 -> 47.008547 | K49: ='Master Sheet'!$F$5 -> 2820.5128
B50: Assy | C50: =IF(C46="","",SUM('NORTH FACE'!K3:K12))/60 -> 34.416667 | D50: =IF(D46="","",SUM('NORTH FACE'!L3:L12))/60 -> 26.366667 | E50: =IF(E46="","",SUM('NORTH FACE'!M3:M12))/60 -> 54.6 | F50: =IF(F46="","",SUM('NORTH FACE'!N3:N12))/60 -> 19.8 | G50: =IF(G46="","",SUM('NORTH FACE'!O3:O12))/60 -> 13.633333 | H50: =IF(H46="","",SUM('NORTH FACE'!P3:P12))/60 -> 72.85 | I50: =IF(I46="","",SUM('NORTH FACE'!Q3:Q12))/60 -> 27.183333 | J50: =IF(J46="","",SUM('NORTH FACE'!R3:R12))/60 -> 0 | K50: =SUM(C50:J50) -> 248.85
B51: Work Time | C51: =IF(C46="","",SUM('NORTH FACE'!K14:K34))/60 -> 1.8833333 | D51: =IF(D46="","",SUM('NORTH FACE'!L14:L34))/60 -> 1.7166667 | E51: =IF(E46="","",SUM('NORTH FACE'!M14:M34))/60 -> 6.3333333 | F51: =IF(F46="","",SUM('NORTH FACE'!N14:N34))/60 -> 0 | G51: =IF(G46="","",SUM('NORTH FACE'!O14:O34))/60 -> 0.96666667 | H51: =IF(H46="","",SUM('NORTH FACE'!P14:P34))/60 -> 16.733333 | I51: =IF(I46="","",SUM('NORTH FACE'!Q14:Q34))/60 -> 28.566667 | J51: =IF(J46="","",SUM('NORTH FACE'!R14:R34))/60 -> 0 | K51: =SUM(C51:J51) -> 56.2
B52: Walk Time | C52: =IF(C46="","",SUM('NORTH FACE'!K36:K37))/60 -> 0 | D52: =IF(D46="","",SUM('NORTH FACE'!L36:L37))/60 -> 0 | E52: =IF(E46="","",SUM('NORTH FACE'!M36:M37))/60 -> 2.4666667 | F52: =IF(F46="","",SUM('NORTH FACE'!N36:N37))/60 -> 17.45 | G52: =IF(G46="","",SUM('NORTH FACE'!O36:O37))/60 -> 0 | H52: =IF(H46="","",SUM('NORTH FACE'!P36:P37))/60 -> 6.8 | I52: =IF(I46="","",SUM('NORTH FACE'!Q36:Q37))/60 -> 14.533333 | J52: =IF(J46="","",SUM('NORTH FACE'!R36:R37))/60 -> 0 | K52: =SUM(C52:J52) -> 41.25
B53: Wait Time | C53: =IF(C46="","",'NORTH FACE'!K39)/60 -> 0 | D53: =IF(D46="","",'NORTH FACE'!L39)/60 -> 0 | E53: =IF(E46="","",'NORTH FACE'!M39)/60 -> 0 | F53: =IF(F46="","",'NORTH FACE'!N39)/60 -> 0 | G53: =IF(G46="","",'NORTH FACE'!O39)/60 -> 0 | H53: =IF(H46="","",'NORTH FACE'!P39)/60 -> 10.55 | I53: =IF(I46="","",'NORTH FACE'!Q39)/60 -> 3.9 | J53: =IF(J46="","",'NORTH FACE'!R39)/60 -> 0 | K53: =SUM(C53:J53) -> 14.45
B54: WAR % | C54: =IFERROR(C48/C49,"") -> 0.7722 | D54: =IFERROR(D48/D49,"") -> 0.59740909 | E54: =IFERROR(E48/E49,"") -> 1.3486909 | F54: =IFERROR(F48/F49,"") -> 0.79240909 | G54: =IFERROR(G48/G49,"") -> 0.31058182 | H54: =IFERROR(H48/H49,"") -> 2.2747636 | I54: =IFERROR(I48/I49,"") -> 1.5780818 | J54: =IFERROR(J48/J49,"") -> 0 | K54: =SUM(C54:J54) -> 7.6741364

Sheet Configuración 
C3: =+'NORTH FACE'!C3 -> NORTH FACE
C4: ENSAMBLE
B5: Fabricacion | C5: Estacion 1
C6: Estacion 2
C7: Estacion 3
B8: H | C8: Estacion 4
C9: Estacion 5
B10: Empaque | C10: Estacion 6
C11: Estacion 7
B12: Integracion | C12: Estacion 8
C13: Estacion 9
B14: Testing | C14: Estacion 10
B15: Empaque | C15: Estacion 12
