Workbook

Sheet Plan for every part
C1: 50 A WEEK | H1: Weekly Demand: | I1: 125 | K1: Batch size in days: | L1: 3
B2: Model: | C2: Operator: | D2: Station: | E2: Cart: | F2: Bin: | G2: Step: | H2: Component: | I2: Quantity: | J2: Process route: | K2: Image: | L2: Widht: | M2: Depth: | N2: Height: | O2: in3: | P2: Storage: | Q2: Bin model: | R2: Bin capacity: | S2: Batch size: | T2: Days of stock: | U2: Required bins | V2: Bin location: | W2: Assembled using: | X2: Tool used to assemble:
B3: ASY-03128-24;A0 | C3: 1 | D3: 1 | E3: C1-B1-PB1-WS#1 | G3: 1 | H3: MTL-02321-01;A0 | I3: 1 | J3: LSR - BRK | L3: 17 | M3: 0.6 | N3: 0.8 | O3: =IFERROR(L3*M3*N3,"") -> 8.16 | P3: Bin | Q3: 1 | R3: =ROUNDUP(IFERROR(VLOOKUP(Q3,$AA$9:$AD$10,4,)/O3,""),0) -> 205 | S3: 100 | T3: =S3/(I3*25) -> 4 | U3: =S3/R3 -> 0.48780488 | W3: Place in fixture | X3: Manually | Z3: Type: | AA3: Part numbers assignment | AB3: Carts needed: | AC3: Cart dimensions: | AD3: Space used:
B4: ASY-03128-24;A0 | C4: 1 | D4: 1 | E4: C5-B2-PB5-WS#1 | G4: 2 | H4: ASY-05258-01;A0 | I4: 1 | J4: TURR - BRK - PEM | L4: 21 | M4: 18.6 | N4: 0.7 | O4: =IFERROR(L4*M4*N4,"") -> 273.42 | P4: Bin | Q4: 2 | R4: =ROUNDUP(IFERROR(VLOOKUP(Q4,$AA$9:$AD$10,4,)/O4,""),0) -> 40 | S4: 80 | T4: =S4/(I4*25) -> 3.2 | U4: =S4/R4 -> 2 | W4: SK41H x6 | X4: Rivet gun | Z4: Cart | AA4: =COUNTIF($P$3:$P$133,"Cart") -> 4
B5: ASY-03128-24;A0 | C5: 1 | D5: 1 | E5: C1-B1-PB1-WS#1 | G5: 3 | H5: GSKT-00352 | I5: 1 | J5: BUY | L5: 10 | M5: 0.5 | N5: 0.5 | O5: =IFERROR(L5*M5*N5,"") -> 2.5 | P5: Bin | Q5: 1 | R5: =ROUNDUP(IFERROR(VLOOKUP(Q5,$AA$9:$AD$10,4,)/O5,""),0) -> 668 | S5: 100 | T5: =S5/(I5*25) -> 4 | U5: =S5/R5 -> 0.1497006 | W5: Stick onto ASY-05258-01;A0 | X5: Manually | Z5: Bin 1 | AA5: =COUNTIF($Q$3:$Q$133,"1") -> 82 | AB5: =81/6 -> 13.5 | AC5: 2.1' x 4.6'
B6: ASY-03128-24;A0 | C6: 1 | D6: 1 | E6: C1-B1-PB1-WS#1 | G6: 3 | H6: GSKT-00353 | I6: 1 | J6: BUY | L6: 10.5 | M6: 0.5 | N6: 0.5 | O6: =IFERROR(L6*M6*N6,"") -> 2.625 | P6: Bin | Q6: 1 | R6: =ROUNDUP(IFERROR(VLOOKUP(Q6,$AA$9:$AD$10,4,)/O6,""),0) -> 637 | S6: 100 | T6: =S6/(I6*25) -> 4 | U6: =S6/R6 -> 0.15698587 | W6: Stick onto ASY-05258-01;A0 | X6: Manually | Z6: Bin 2 | AA6: =COUNTIF($Q$3:$Q$133,"2") -> 36 | AB6: =53/2 -> 26.5 | AC6: 2.1' x 4.6' | AD6: 9 x 3 Array 18.9' x 13.8'
B7: ASY-03128-24;A0 | C7: 1 | D7: 1 | E7: C1-B1-PB1-WS#1 | G7: 4 | H7: MTL-02217-01;A0 | I7: 1 | J7: TURR - BRK | L7: 15.7 | M7: 1.5 | N7: 1.2 | O7: =IFERROR(L7*M7*N7,"") -> 28.26 | P7: Bin | Q7: 1 | R7: =ROUNDUP(IFERROR(VLOOKUP(Q7,$AA$9:$AD$10,4,)/O7,""),0) -> 60 | S7: 120 | T7: =S7/(I7*25) -> 4.8 | U7: =S7/R7 -> 2 | W7: SK41H x14 | X7: Rivet gun
B8: ASY-03128-24;A0 | C8: 1 | D8: 1 | E8: C6-B2-PB6-WS#1 | G8: 4 | H8: ASY-05257-01;A0 | I8: 1 | J8: TURR - BRK - PEM | L8: 21 | M8: 17.5 | N8: 1.2 | O8: =IFERROR(L8*M8*N8,"") -> 441 | P8: Bin | Q8: 2 | R8: =ROUNDUP(IFERROR(VLOOKUP(Q8,$AA$9:$AD$10,4,)/O8,""),0) -> 25 | S8: 50 | T8: =S8/(I8*25) -> 2 | U8: =S8/R8 -> 2 | W8: Assembled to MTL-02217-01;A0 | X8: Rivet gun | Z8: Bin | AA8: Bin ID | AB8: Outter dim | AC8: Inner dim | AD8: Inner vol
B9: ASY-03128-24;A0 | C9: 1 | D9: 2 | E9: C7-B2-PB7-WS#2 | G9: 5 | H9: ASY-05277-02;A0 | I9: 1 | J9: TURR - BRK - PEM | L9: 22.8 | M9: 17.2 | N9: 0.8 | O9: =IFERROR(L9*M9*N9,"") -> 313.728 | P9: Bin | Q9: 2 | R9: =ROUNDUP(IFERROR(VLOOKUP(Q9,$AA$9:$AD$10,4,)/O9,""),0) -> 35 | S9: 70 | T9: =S9/(I9*25) -> 2.8 | U9: =S9/R9 -> 2 | W9: SK41H x14 | X9: Rivet gun | Z9: 42185T92 | AA9: 1 | AB9: 11 x 23.87 x 10 | AC9: 9.4 x 18.7 x 9.5 | AD9: =9.4*18.7*9.5 -> 1669.91
B10: ASY-03128-24;A0 | C10: 1 | D10: 2 | E10: C2-B1-PB2-WS#2 | G10: 6 | H10: MTL-02324-02;A0 | I10: 1 | J10: TURR - BRK | L10: 16.1 | M10: 1.2 | N10: 0.4 | O10: =IFERROR(L10*M10*N10,"") -> 7.728 | P10: Bin | Q10: 1 | R10: =ROUNDUP(IFERROR(VLOOKUP(Q10,$AA$9:$AD$10,4,)/O10,""),0) -> 217 | S10: 100 | T10: =S10/(I10*25) -> 4 | U10: =S10/R10 -> 0.46082949 | W10: SK41H x9 | X10: Rivet gun | Z10: 28765T78 | AA10: 2 | AB10: 23.87 x 35.87 x 17.5 | AC10: 22.4 x 28.3 x 17.2 | AD10: =22.25*28.5*17 -> 10780.125
B11: ASY-03128-24;A0 | C11: 1 | D11: 2 | E11: C2-B1-PB2-WS#2 | G11: 6 | H11: MTL-02214-01;A1 | I11: 1 | J11: LSR - BRK - OSP | L11: 17 | M11: 1.4 | N11: 0.4 | O11: =IFERROR(L11*M11*N11,"") -> 9.52 | P11: Bin | Q11: 1 | R11: =ROUNDUP(IFERROR(VLOOKUP(Q11,$AA$9:$AD$10,4,)/O11,""),0) -> 176 | S11: 100 | T11: =S11/(I11*25) -> 4 | U11: =S11/R11 -> 0.56818182 | W11: Assembled to MTL-02324-02;A0 | X11: Rivet gun
B12: ASY-03128-24;A0 | C12: 1 | D12: 1 | E12: C1-B1-PB1-WS#1 | G12: 9 | H12: MTL-02216-03;A0 | I12: 1 | J12: LSR - BRK | L12: 16.9 | M12: 1.3 | N12: 0.4 | O12: =IFERROR(L12*M12*N12,"") -> 8.788 | P12: Bin | Q12: 1 | R12: =ROUNDUP(IFERROR(VLOOKUP(Q12,$AA$9:$AD$10,4,)/O12,""),0) -> 191 | S12: 100 | T12: =S12/(I12*25) -> 4 | U12: =S12/R12 -> 0.52356021 | W12: SK41H x11 | X12: Rivet gun
B13: ASY-03128-24;A0 | C13: 1 | D13: 1 | E13: C4-B2-PB4-WS#1 | G13: 9 | H13: ASY-05299-02;A0 | I13: 1 | J13: TURR - BRK - PEM | L13: 17.9 | M13: 17.2 | N13: 0.4 | O13: =IFERROR(L13*M13*N13,"") -> 123.152 | P13: Bin | Q13: 2 | R13: =ROUNDUP(IFERROR(VLOOKUP(Q13,$AA$9:$AD$10,4,)/O13,""),0) -> 88 | S13: 89 | T13: =S13/(I13*25) -> 3.56 | U13: =S13/R13 -> 1.0113636 | W13: Assembled to MTL-02216-03;A0 | X13: Rivet gun
B14: ASY-03128-24;A0 | C14: 1 | D14: 2 | E14: C2-B1-PB2-WS#2 | G14: 11 | H14: H FAS-00525 | I14: 6 | J14: BUY | L14: 3 | M14: 0.5 | N14: 0.5 | O14: =IFERROR(L14*M14*N14,"") -> 0.75 | P14: Bin | Q14: 1 | R14: =ROUNDUP(IFERROR(VLOOKUP(Q14,$AA$9:$AD$10,4,)/O14,""),0) -> 2227 | S14: 600 | T14: =S14/(I14*25) -> 4 | U14: =S14/R14 -> 0.26942075 | W14: Assembled into ASY-05275-01;A0 | X14: Manually
B15: ASY-03128-24;A0 | C15: 2 | D15: 3 | E15: C8-B1-PB8 | G15: 12 | H15: MTL-02215-02;A1 | I15: 1 | J15: LSR - BRK - OSP | L15: 17 | M15: 1.5 | N15: 0.4 | O15: =IFERROR(L15*M15*N15,"") -> 10.2 | P15: Bin | Q15: 1 | R15: =ROUNDUP(IFERROR(VLOOKUP(Q15,$AA$9:$AD$10,4,)/O15,""),0) -> 164 | S15: 100 | T15: =S15/(I15*25) -> 4 | U15: =S15/R15 -> 0.6097561 | W15: Assembled to ASY-05299-02;A0 SK41H x25 | X15: Rivet gun
B16: ASY-03128-24;A0 | C16: 2 | D16: 3 | E16: C8-B1-PB8 | G16: 13 | H16: MECH-02707-01;B0 | I16: 1 | J16: BUY | L16: 10.5 | M16: 0.5 | N16: 0.5 | O16: =IFERROR(L16*M16*N16,"") -> 2.625 | P16: Bin | Q16: 1 | R16: =ROUNDUP(IFERROR(VLOOKUP(Q16,$AA$9:$AD$10,4,)/O16,""),0) -> 637 | S16: 100 | T16: =S16/(I16*25) -> 4 | U16: =S16/R16 -> 0.15698587 | W16: Stick onto part | X16: Manually
B17: ASY-03128-24;A0 | C17: 2 | D17: 3 | E17: C8-B1-PB8 | G17: 14 | H17: A MECH-02688-02 | I17: 1 | J17: BUY | L17: 6 | M17: 1.5 | N17: 0.75 | O17: =IFERROR(L17*M17*N17,"") -> 6.75 | P17: Bin | Q17: 1 | R17: =ROUNDUP(IFERROR(VLOOKUP(Q17,$AA$9:$AD$10,4,)/O17,""),0) -> 248 | S17: 100 | T17: =S17/(I17*25) -> 4 | U17: =S17/R17 -> 0.40322581 | W17: Assembled into part | X17: Manually
B18: ASY-03128-24;A0 | C18: 2 | D18: 3 | E18: C8-B1-PB8 | G18: 15 | H18: A MECH-02687-02 | I18: 5 | J18: BUY | L18: 6.75 | M18: 1.25 | N18: 0.375 | O18: =IFERROR(L18*M18*N18,"") -> 3.1640625 | P18: Bin | Q18: 1 | R18: =ROUNDUP(IFERROR(VLOOKUP(Q18,$AA$9:$AD$10,4,)/O18,""),0) -> 528 | S18: 345 | T18: =S18/(I18*25) -> 2.76 | U18: =S18/R18 -> 0.65340909 | W18: Assembled into part | X18: Manually
B19: ASY-03128-24;A0 | C19: 2 | D19: 3 | E19: C8-B1-PB8 | G19: 16 | H19: ASY-03668-01;A0 | I19: 1 | J19: TURR - BRK - PEM | L19: 12.3 | M19: 0.5 | N19: 0.5 | O19: =IFERROR(L19*M19*N19,"") -> 3.075 | P19: Bin | Q19: 1 | R19: =ROUNDUP(IFERROR(VLOOKUP(Q19,$AA$9:$AD$10,4,)/O19,""),0) -> 544 | S19: 100 | T19: =S19/(I19*25) -> 4 | U19: =S19/R19 -> 0.18382353 | W19: Place in fixture | X19: Manually
B20: ASY-03128-24;A0 | C20: 2 | D20: 3 | E20: C9-B2-PB9 | G20: 17 | H20: MTL-02352-04;A0 | I20: 1 | J20: TURR - BRK | L20: 16.7 | M20: 14.2 | N20: 0.5 | O20: =IFERROR(L20*M20*N20,"") -> 118.57 | P20: Bin | Q20: 2 | R20: =ROUNDUP(IFERROR(VLOOKUP(Q20,$AA$9:$AD$10,4,)/O20,""),0) -> 91 | S20: 92 | T20: =S20/(I20*25) -> 3.68 | U20: =S20/R20 -> 1.010989 | W20: Aassembled to ASY-03668-01;A0 SK41H 5x | X20: Rivet gun
B21: ASY-03128-24;A0 | C21: 2 | D21: 3 | E21: C9-B2-PB9 | G21: 19 | H21: ASY-04181-02;A0 | I21: 1 | J21: TURR - BRK - PEM | L21: 17.1 | M21: 3.4 | N21: 3.1 | O21: =IFERROR(L21*M21*N21,"") -> 180.234 | P21: Bin | Q21: 2 | R21: =ROUNDUP(IFERROR(VLOOKUP(Q21,$AA$9:$AD$10,4,)/O21,""),0) -> 60 | S21: 61 | T21: =S21/(I21*25) -> 2.44 | U21: =S21/R21 -> 1.0166667 | W21: SK41H x16 | X21: Rivet gun
B22: ASY-03128-24;A0 | C22: 2 | D22: 3 | E22: C10-B2-PB10 | G22: 21 | H22: ASY-03157-02;A0 | I22: 1 | J22: TURR - BRK - PEM | L22: 17.2 | M22: 6.1 | N22: 4.8 | O22: =IFERROR(L22*M22*N22,"") -> 503.616 | P22: Bin | Q22: 2 | R22: =ROUNDUP(IFERROR(VLOOKUP(Q22,$AA$9:$AD$10,4,)/O22,""),0) -> 22 | S22: 44 | T22: =S22/(I22*25) -> 1.76 | U22: =S22/R22 -> 2 | W22: SK41H x21 | X22: Rivet gun
... B32: ASY-03128-24;A0 | C32: 3 | D32: 5 | E32: C19-B2-PB19 | G32: 31 | H32: MTL-02220-03;A0 | I32: 1 | J32: TURR - BRK | L32: 17.1 | M32: 13.2 | N32: 1.9 | O32: =IFERROR(L32*M32*N32,"") -> 428.868 | P32: Bin | Q32: 2 | R32: =ROUNDUP(IFERROR(VLOOKUP(Q32,$AA$9:$AD$10,4,)/O32,""),0) -> 26 | S32: 52 | T32: =S32/(I32*25) -> 2.08 | U32: =S32/R32 -> 2 | W32: SK41H 12x | X32: Rivet gun
B33: ASY-03128-24;A0 | C33: 3 | D33: 6 | E33: C15-B1-PB15 | G33: 32 | H33: MTL-03697-01;A0 | I33: 1 | J33: LSR - BRK | L33: 16.2 | M33: 3.7 | N33: 0.8 | O33: =IFERROR(L33*M33*N33,"") -> 47.952 | P33: Bin | Q33: 1 | R33: 100 | S33: 100 | T33: =S33/(I33*25) -> 4 | U33: =S33/R33 -> 1 | W33: SK41H 6x | X33: Rivet gun
B34: ASY-03128-24;A0 | C34: 3 | D34: 5 | E34: C20-B2-PB20 | G34: 33 | H34: ASY-03139-03;A0 | I34: 1 | J34: TURR - BRK - PEM | L34: 17.1 | M34: 14.4 | N34: 0.8 | O34: =IFERROR(L34*M34*N34,"") -> 196.992 | P34: Bin | Q34: 2 | R34: =ROUNDUP(IFERROR(VLOOKUP(Q34,$AA$9:$AD$10,4,)/O34,""),0) -> 55 | S34: 100 | T34: =S34/(I34*25) -> 4 | U34: =S34/R34 -> 1.8181818 | W34: SK41H 8x | X34: Rivet gun
B35: ASY-03128-24;A0 | C35: 3 | D35: 6 | E35: C16-B1-PB16 | G35: 35 | H35: MTL-02738-01;A0 | I35: 1 | J35: TURR - BRK | L35: 16.3 | M35: 1.2 | N35: 0.6 | O35: =IFERROR(L35*M35*N35,"") -> 11.736 | P35: Bin | Q35: 1 | R35: =ROUNDUP(IFERROR(VLOOKUP(Q35,$AA$9:$AD$10,4,)/O35,""),0) -> 143 | S35: 93 | T35: =S35/(I35*25) -> 3.72 | U35: =S35/R35 -> 0.65034965 | W35: SK41H 5x | X35: Rivet gun
B36: ASY-03128-24;A0 | C36: 3 | D36: 6 | E36: C16-B1-PB16 | G36: 36 | H36: A GSKT-00349 | I36: 2 | J36: BUY | L36: 17 | M36: 0.5 | N36: 0.2 | O36: =IFERROR(L36*M36*N36,"") -> 1.7 | P36: Bin | Q36: 1 | R36: =ROUNDUP(IFERROR(VLOOKUP(Q36,$AA$9:$AD$10,4,)/O36,""),0) -> 983 | S36: 200 | T36: =S36/(I36*25) -> 4 | U36: =S36/R36 -> 0.2034588 | W36: Stick onto part | X36: Manually
B37: ASY-03128-24;A0 | C37: 3 | D37: 5 | E37: C16-B1-PB16 | G37: 37 | H37: ASY-04776-01;B0 | I37: 1 | J37: N/A | L37: 2.5 | M37: 1 | N37: 0.1 | O37: =IFERROR(L37*M37*N37,"") -> 0.25 | P37: Bin | Q37: 1 | R37: =ROUNDUP(IFERROR(VLOOKUP(Q37,$AA$9:$AD$10,4,)/O37,""),0) -> 6680 | S37: 100 | T37: =S37/(I37*25) -> 4 | U37: =S37/R37 -> 0.01497006 | W37: FAS-00532 15 in/lbs | X37: Atornillador
B38: ASY-03128-24;A0 | C38: 3 | D38: 5 | E38: C16-B1-PB16 | G38: 37 | H38: A MECH-01754-04 | I38: 18 | J38: BUY | L38: 1.2 | M38: 0.7 | N38: 0.6 | O38: =IFERROR(L38*M38*N38,"") -> 0.504 | P38: Bin | Q38: 1 | R38: =ROUNDUP(IFERROR(VLOOKUP(Q38,$AA$9:$AD$10,4,)/O38,""),0) -> 3314 | S38: 1800 | T38: =S38/(I38*25) -> 4 | U38: =S38/R38 -> 0.54315027 | W38: Assembled to ASY-04776-01;B0 | X38: Manually
B39: ASY-03128-24;A0 | C39: 3 | D39: 5 | E39: C16-B1-PB16 | G39: 39 | H39: A CBL-00408-05;B0 | I39: 1 | J39: BUY | L39: 5 | M39: 0.7 | N39: 0.3 | O39: =IFERROR(L39*M39*N39,"") -> 1.05 | P39: Bin | Q39: 1 | R39: =ROUNDUP(IFERROR(VLOOKUP(Q39,$AA$9:$AD$10,4,)/O39,""),0) -> 1591 | S39: 100 | T39: =S39/(I39*25) -> 4 | U39: =S39/R39 -> 0.062853551 | W39: FAS-00381 x4 FAS-00380 x4 | X39: Atornillador 40 in/lbs
B40: ASY-03128-24;A0 | C40: 3 | D40: 5 | G40: 39 | H40: A ASY-03229-07;C0 | I40: 1 | J40: BUY | L40: Pending | M40: - | N40: - | O40: - | P40: Cart | W40: - | X40: -
B41: ASY-03128-24;A0 | C41: 3 | D41: 5 | E41: C16-B1-PB16 | G41: 41 | H41: A MECH-02689-01;B | I41: 1 | J41: BUY | L41: 5 | M41: 0.5 | N41: 0.2 | O41: =IFERROR(L41*M41*N41,"") -> 0.5 | P41: Bin | Q41: 1 | R41: =ROUNDUP(IFERROR(VLOOKUP(Q41,$AA$9:$AD$10,4,)/O41,""),0) -> 3340 | S41: 100 | T41: =S41/(I41*25) -> 4 | U41: =S41/R41 -> 0.02994012 | W41: Stick onto part | X41: Manually
B42: ASY-03128-24;A0 | C42: 4 | D42: 8 | E42: C23-B1-PB23 | G42: 44 | H42: A MECH-01200-02 | I42: 1 | J42: BUY | L42: 5 | M42: 0.5 | N42: 0.2 | O42: =IFERROR(L42*M42*N42,"") -> 0.5 | P42: Bin | Q42: 1 | R42: =ROUNDUP(IFERROR(VLOOKUP(Q42,$AA$9:$AD$10,4,)/O42,""),0) -> 3340 | S42: 100 | T42: =S42/(I42*25) -> 4 | U42: =S42/R42 -> 0.02994012 | W42: Stick onto part | X42: Manually
B43: ASY-03128-24;A0 | C43: 4 | D43: 8 | E43: C24-B2-PB24 | G43: 45 | H43: ASY-03152-06;A0 | I43: 1 | J43: TURR - BRK - PEM | L43: 27 | M43: 22 | N43: 0.4 | O43: =IFERROR(L43*M43*N43,"") -> 237.6 | P43: Bin | Q43: 2 | R43: =ROUNDUP(IFERROR(VLOOKUP(Q43,$AA$9:$AD$10,4,)/O43,""),0) -> 46 | S43: 92 | T43: =S43/(I43*25) -> 3.68 | U43: =S43/R43 -> 2 | W43: SK41H 80x MECH-01196-03 | X43: Rivet gun Aatornillador 15 in/lbs
B44: ASY-03128-24;A0 | C44: 2 | D44: 4 | E44: C-14-B1-PB14 | G44: 46 | H44: MTL-02254-02;A1 | I44: 2 | J44: TURR - BRK | L44: 17.1 | M44: 1.8 | N44: 0.7 | O44: =IFERROR(L44*M44*N44,"") -> 21.546 | P44: Bin | Q44: 1 | R44: =ROUNDUP(IFERROR(VLOOKUP(Q44,$AA$9:$AD$10,4,)/O44,""),0) -> 78 | S44: 200 | T44: =S44/(I44*25) -> 4 | U44: =S44/R44 -> 2.5641026 | W44: Place in fixture | X44: Manually
B45: ASY-03128-24;A0 | C45: 2 | D45: 4 | E45: C-14-B1-PB14 | G45: 47 | H45: ASY-03143-06;A0 | I45: 1 | J45: TURR - BRK - PEM | L45: 17.1 | M45: 14.3 | N45: 0.4 | O45: =IFERROR(L45*M45*N45,"") -> 97.812 | P45: Bin | Q45: 2 | R45: =ROUNDUP(IFERROR(VLOOKUP(Q45,$AA$9:$AD$10,4,)/O45,""),0) -> 111 | S45: 100 | T45: =S45/(I45*25) -> 4 | U45: =S45/R45 -> 0.9009009 | W45: SK41H x20 | X45: Rivet gun
B46: ASY-03128-24;A0 | C46: 3 | D46: 7 | E46: C21-B1-PB21 | G46: 51 | H46: MTL-02226-02;A0 | I46: 1 | J46: LSR - BRK | L46: 17 | M46: 0.7 | N46: 0.8 | O46: =IFERROR(L46*M46*N46,"") -> 9.52 | P46: Bin | Q46: 1 | R46: =ROUNDUP(IFERROR(VLOOKUP(Q46,$AA$9:$AD$10,4,)/O46,""),0) -> 176 | S46: 100 | T46: =S46/(I46*25) -> 4 | U46: =S46/R46 -> 0.56818182 | W46: Place onto part | X46: Manually
B47: ASY-03128-24;A0 | C47: 3 | D47: 7 | E47: C22-B2-PB22 | G47: 51 | H47: ASY-05272-01;A0 | I47: 1 | J47: TURR - PEM - BRK | L47: 18.9 | M47: 15.3 | N47: 0.5 | O47: =IFERROR(L47*M47*N47,"") -> 144.585 | P47: Bin | Q47: 2 | R47: =ROUNDUP(IFERROR(VLOOKUP(Q47,$AA$9:$AD$10,4,)/O47,""),0) -> 75 | S47: 76 | T47: =S47/(I47*25) -> 3.04 | U47: =S47/R47 -> 1.0133333 | W47: SK41H x4 | X47: Rivet gun
B48: ASY-03128-24;A0 | C48: 3 | D48: 7 | E48: C22-B2-PB22 | G48: 52 | H48: MTL-03975-01;A1 | I48: 1 | J48: TURR - BRK | L48: 18.9 | M48: 15.3 | N48: 0.4 | O48: =IFERROR(L48*M48*N48,"") -> 115.668 | P48: Bin | Q48: 2 | R48: =ROUNDUP(IFERROR(VLOOKUP(Q48,$AA$9:$AD$10,4,)/O48,""),0) -> 94 | S48: 94 | T48: =S48/(I48*25) -> 3.76 | U48: =S48/R48 -> 1 | W48: SK41H x22 | X48: Rivet gun
B49: ASY-03128-24;A0 | C49: 3 | D49: 7 | E49: C21-B1-PB21 | G49: 53 | H49: A GSKT-00349 | I49: 1 | J49: N/A | L49: 17 | M49: 0.5 | N49: 0.2 | O49: =IFERROR(L49*M49*N49,"") -> 1.7 | P49: Bin | Q49: 1 | R49: =ROUNDUP(IFERROR(VLOOKUP(Q49,$AA$9:$AD$10,4,)/O49,""),0) -> 983 | S49: 100 | T49: =S49/(I49*25) -> 4 | U49: =S49/R49 -> 0.1017294 | W49: Stick onto part | X49: Manually
...

Sheet Cart-PN Matrix
B1: Carts for operator 1
U2: Blue bin for make items
B3: Bin compartment: | D3: C1-B1-PB1-WS#1 | F3: C2-B1-PB2-WS#2 | H3: C3-B2-PB3-WS#1 | J3: C4-B2-PB4-WS#1 | L3: C5-B2-PB5-WS#1 | N3: C6-B2-PB6-WS#1 | P3: C7-B2-PB7-WS#2 | U3: Yellow bin for buy items
B4: 1 | D4: {=_xlfn._xlws.FILTER('Plan for every part'!$H$3:$H$127,('Plan for every part'!$E$3:$E$127='Cart-PN Matrix'!D3))} -> MTL-02321-01;A0 | F4: {=_xlfn._xlws.FILTER('Plan for every part'!$H$3:$H$127,('Plan for every part'!$E$3:$E$127='Cart-PN Matrix'!F3))} -> MTL-02324-02;A0 | H4: {=_xlfn._xlws.FILTER('Plan for every part'!$H$3:$H$127,('Plan for every part'!$E$3:$E$127='Cart-PN Matrix'!H3))} -> MTL-03976-01;B0 | I4: * | J4: {=_xlfn._xlws.FILTER('Plan for every part'!$H$3:$H$127,('Plan for every part'!$E$3:$E$127='Cart-PN Matrix'!J3))} -> ASY-05299-02;A0 | L4: {=_xlfn._xlws.FILTER('Plan for every part'!$H$3:$H$127,('Plan for every part'!$E$3:$E$127='Cart-PN Matrix'!L3))} -> ASY-05258-01;A0 | N4: {=_xlfn._xlws.FILTER('Plan for every part'!$H$3:$H$127,('Plan for every part'!$E$3:$E$127='Cart-PN Matrix'!N3))} -> ASY-05257-01;A0 | P4: {=_xlfn._xlws.FILTER('Plan for every part'!$H$3:$H$127,('Plan for every part'!$E$3:$E$127='Cart-PN Matrix'!P3))} -> ASY-05277-02;A0
B5: 2 | D5: GSKT-00352 | F5: MTL-02214-01;A1 | H5: MTL-03976-01;B0 | I5: * | J5: MTL-03977-01;A0 | L5: ASY-05258-01;A0 | N5: ASY-05257-01;A0 | P5: ASY-05277-02;A0
B6: 3 | D6: GSKT-00353 | F6: H FAS-00525
B7: 4 | D7: MTL-02217-01;A0
B8: 5 | D8: MTL-02216-03;A0
B9: 6 | D9: B MTL-03978-01;C0
B11: Carts for operator 2
B13: Bin compartment: | D13: C8-B1-PB8 | F13: C9-B2-PB9 | H13: C10-B2-PB10 | J13: C11-B2-PB11 | L13: C12-B2-PB12 | N13: C-13-B1-PB13 | P13: C-14-B1-PB14
B14: 1 | D14: {=_xlfn._xlws.FILTER('Plan for every part'!$H$3:$H$127,('Plan for every part'!$E$3:$E$127='Cart-PN Matrix'!D13))} -> MTL-02215-02;A1 | E14: * | F14: {=_xlfn._xlws.FILTER('Plan for every part'!$H$3:$H$127,('Plan for every part'!$E$3:$E$127='Cart-PN Matrix'!F13))} -> MTL-02352-04;A0 | H14: {=_xlfn._xlws.FILTER('Plan for every part'!$H$3:$H$127,('Plan for every part'!$E$3:$E$127='Cart-PN Matrix'!H13))} -> ASY-03157-02;A0 | J14: {=_xlfn._xlws.FILTER('Plan for every part'!$H$3:$H$127,('Plan for every part'!$E$3:$E$127='Cart-PN Matrix'!J13))} -> MTL-02356-04;B0 | L14: {=_xlfn._xlws.FILTER('Plan for every part'!$H$3:$H$127,('Plan for every part'!$E$3:$E$127='Cart-PN Matrix'!L13))} -> MTL-02362-04;B0 | N14: {=_xlfn._xlws.FILTER('Plan for every part'!$H$3:$H$127,('Plan for every part'!$E$3:$E$127='Cart-PN Matrix'!N13))} -> MTL-02357-02;A0 | O14: * | P14: {=_xlfn._xlws.FILTER('Plan for every part'!$H$3:$H$127,('Plan for every part'!$E$3:$E$127='Cart-PN Matrix'!P13))} -> MTL-02254-02;A1
B15: 2 | D15: MECH-02707-01;B0 | E15: * | F15: ASY-04181-02;A0 | H15: ASY-03157-02;A0 | J15: MTL-02356-04;B0 | L15: H MECH-02436-01 | N15: MTL-02358-03;A3 | O15: * | P15: ASY-03143-06;A0
B16: 3 | D16: A MECH-02688-02 | N16: H FAS-00797 (SPRING)
B17: 4 | D17: A MECH-02687-02 | N17: MTL-02360-06;A0
B18: 5 | D18: ASY-03668-01;A0 | N18: MTL-02363-03;A0
B19: 6 | D19: A LBL-00829-03;B0
B21: Carts for operator 3
B23: Bin compartment: | D23: C15-B1-PB15 | F23: C16-B1-PB16 | H23: C17-B2-PB17 | J23: C18-B2-PB18 | L23: C19-B2-PB19 | N23: C20-B2-PB20 | P23: C21-B1-PB21 | R23: C22-B2-PB22
B24: 1 | D24: {=_xlfn._xlws.FILTER('Plan for every part'!$H$3:$H$127,('Plan for every part'!$E$3:$E$127='Cart-PN Matrix'!D23))} -> MTL-02239-01;A0 | F24: {=_xlfn._xlws.FILTER('Plan for every part'!$H$3:$H$127,('Plan for every part'!$E$3:$E$127='Cart-PN Matrix'!F23))} -> MTL-02738-01;A0 | G24: * | H24: {=_xlfn._xlws.FILTER('Plan for every part'!$H$3:$H$127,('Plan for every part'!$E$3:$E$127='Cart-PN Matrix'!H23))} -> MTL-02237-04;A0 | J24: {=_xlfn._xlws.FILTER('Plan for every part'!$H$3:$H$127,('Plan for every part'!$E$3:$E$127='Cart-PN Matrix'!J23))} -> B ASY-05269-03;B0 (FRAME) | L24: {=_xlfn._xlws.FILTER('Plan for every part'!$H$3:$H$127,('Plan for every part'!$E$3:$E$127='Cart-PN Matrix'!L23))} -> MTL-02220-03;A0 | N24: {=_xlfn._xlws.FILTER('Plan for every part'!$H$3:$H$127,('Plan for every part'!$E$3:$E$127='Cart-PN Matrix'!N23))} -> ASY-03139-03;A0 | P24: {=_xlfn._xlws.FILTER('Plan for every part'!$H$3:$H$127,('Plan for every part'!$E$3:$E$127='Cart-PN Matrix'!P23))} -> MTL-02226-02;A0 | Q24: * | R24: {=_xlfn._xlws.FILTER('Plan for every part'!$H$3:$H$127,('Plan for every part'!$E$3:$E$127='Cart-PN Matrix'!R23))} -> ASY-05272-01;A0
B25: 2 | D25: ASY-03145-02;A0 | F25: A GSKT-00349 | G25: * | H25: MTL-02236-04;A0 | J25: B ASY-05269-03;B0 (FRAME) | L25: MTL-02220-03;A0 | N25: ASY-03139-03;A0 | P25: A GSKT-00349 | Q25: * | R25: MTL-03975-01;A1
B26: 3 | D26: MTL-02434-01;A0 | F26: ASY-04776-01;B0
B27: 4 | D27: ASY-03135-03;A0 | F27: A MECH-01754-04
B28: 5 | D28: MTL-02212-01;A0 | F28: A CBL-00408-05;B0
B29: 6 | D29: MTL-03697-01;A0 | F29: A MECH-02689-01;B
B31: Carts for operator 4 | N31: Carts for operator 5
B33: Bin compartment: | D33: C23-B1-PB23 | F33: C24-B2-PB24 | H33: C25-B2-PB25 | J33: C26-B2-PB26 | L33: C27-B2-PB27 | N33: C28-B1-PB28 | P33: C29-B2-PB29 | R33: C30-B2-PB30
B34: 1 | D34: {=_xlfn._xlws.FILTER('Plan for every part'!$H$3:$H$127,('Plan for every part'!$E$3:$E$127='Cart-PN Matrix'!D33))} -> A MECH-01200-02 | F34: {=_xlfn._xlws.FILTER('Plan for every part'!$H$3:$H$127,('Plan for every part'!$E$3:$E$127='Cart-PN Matrix'!F33))} -> ASY-03152-06;A0 | H34: {=_xlfn._xlws.FILTER('Plan for every part'!$H$3:$H$127,('Plan for every part'!$E$3:$E$127='Cart-PN Matrix'!H33))} -> ASY-04756-04;A0 | I34: * | J34: {=_xlfn._xlws.FILTER('Plan for every part'!$H$3:$H$127,('Plan for every part'!$E$3:$E$127='Cart-PN Matrix'!J33))} -> ASY-03156-03;A0 | L34: {=_xlfn._xlws.FILTER('Plan for every part'!$H$3:$H$127,('Plan for every part'!$E$3:$E$127='Cart-PN Matrix'!L33))} -> ASY-03137-03;A0 | N34: {=_xlfn._xlws.FILTER('Plan for every part'!$H$3:$H$127,('Plan for every part'!$E$3:$E$127='Cart-PN Matrix'!N33))} -> MTL-02218-01;B0 | P34: {=_xlfn._xlws.FILTER('Plan for every part'!$H$3:$H$127,('Plan for every part'!$E$3:$E$127='Cart-PN Matrix'!P33))} -> ASY-03153-05;A0 | R34: {=_xlfn._xlws.FILTER('Plan for every part'!$H$3:$H$127,('Plan for every part'!$E$3:$E$127='Cart-PN Matrix'!R33))} -> ASY-04757-04;A0
B35: 2 | F35: ASY-03152-06;A0 | H35: ASY-04756-04;A0 | I35: * | J35: ASY-03136-03;A0 | L35: ASY-03137-03;A0 | N35: A MECH-01754-04 | P35: ASY-03153-05;A0 | R35: ASY-04757-04;A0
B36: 3 | N36: A MECH-01253-01
B37: 4 | N37: MTL-02322-03;B0
B38: 5 | N38: A MECH-01754-04
B39: 6
B41: Carts for operator 7
B43: Bin compartment: | D43: C31-B2-PB31 | F43: C32-B2-PB32 | H43: C33-B2-PB33 | J43: C34-B2-PB34 | L43: C35-B1-PB35
B44: 1 | C44: * | D44: {=_xlfn._xlws.FILTER('Plan for every part'!$H$3:$H$127,('Plan for every part'!$E$3:$E$127='Cart-PN Matrix'!D43))} -> ASY-03185-02;A0 | F44: {=_xlfn._xlws.FILTER('Plan for every part'!$H$3:$H$127,('Plan for every part'!$E$3:$E$127='Cart-PN Matrix'!F43))} -> ASY-03184-05;A0 | G44: * | H44: {=_xlfn._xlws.FILTER('Plan for every part'!$H$3:$H$127,('Plan for every part'!$E$3:$E$127='Cart-PN Matrix'!H43))} -> MTL-02258-06;A0 | J44: {=_xlfn._xlws.FILTER('Plan for every part'!$H$3:$H$127,('Plan for every part'!$E$3:$E$127='Cart-PN Matrix'!J43))} -> ASY-03187-07;A0 | L44: {=_xlfn._xlws.FILTER('Plan for every part'!$H$3:$H$127,('Plan for every part'!$E$3:$E$127='Cart-PN Matrix'!L43))} -> MTL-02368-02;A0
B45: 2 | C45: * | D45: ASY-04183-01;A0 | F45: ASY-03184-05;A0 | G45: * | H45: ASY-03189-05;A0 | J45: ASY-03187-07;A0 | L45: MTL-03292-01;A0
B46: 3 | L46: B MTL-03296-02;B0
B47: 4 | L47: MTL-03292-01;A0
B48: 5 | L48: MTL-02844-02;A0
...

Sheet Cart nomenclature

Sheet Process map
B2: Assembly line staff | D2: Supermarket staff | F2: Midfield area | H2: Primary operations

Sheet BOM
A1: M/B | B1: LEVEL | C1: PARENT | D1: BACKLOG | E1: COMPONENT | F1: STATUS | G1: PROCESO INICIAL | H1: DESCRIPTION1 | I1: REQ | J1: U/M | K1: ON HAND | L1: ON ORD | M1: COMM | N1: AVAIL | O1: LEAD TIME | P1: VENDOR NAME | Q1: TYPE | R1: PROGRAMA
A2: B | B2: ___3 | C2: ASY-53727-127;A0 | D2: 1000 | E2: A ASY-03229-07;C0 | F2: B | H2: ASY,DN8,BUSBAR,MAIN 1 | I2: 1 | J2: EA | K2: 366 | L2: 618 | M2: 230 | N2: 754 | O2: 120 | P2: INTERPLEX (SUZHOU) PRECISION | R2: ARISTA NETWORKS, INC
A3: B | B3: __2 | C3: ASY-53727-127;A0 | D3: 1000 | E3: A ASY-03230-06;A0 | F3: B | H3: ASY,DN8,BUSBAR,HORIZON | I3: 1 | J3: EA | K3: 329 | L3: 647 | M3: 246 | N3: 730 | O3: 120 | P3: INTERPLEX (SUZHOU) PRECISION | R3: ARISTA NETWORKS, INC
A4: B | B4: __2 | C4: ASY-53727-127;A0 | D4: 1000 | E4: A ASY-03248-06;A0 | F4: B | H4: ASY,DN8,BUSBAR,HORIZON | I4: 1 | J4: EA | K4: 303 | L4: 673 | M4: 246 | N4: 730 | O4: 120 | P4: INTERPLEX (SUZHOU) PRECISION | R4: ARISTA NETWORKS, INC
A5: B | B5: ___3 | C5: ASY-53727-127;A0 | D5: 1000 | E5: A ASY-04714-01;A1 | F5: B | H5: ASY,DNNALI,RACK,BASKET | I5: 1 | J5: EA | K5: 758 | L5: 1000 | M5: 264 | N5: 1494 | O5: 50 | P5: HUANJOW KNITTING CO., LTD. | R5: ARISTA NETWORKS, INC
A6: B | B6: __2 | C6: ASY-53727-127;A0 | D6: 1000 | E6: A CBL-00407-05;D0 | H6: CABLE ASY, BUSBAR, VSE | I6: 1 | J6: EA | K6: 467 | L6: 529 | M6: 246 | N6: 750 | O6: 120 | P6: GREAT ASIA TAI TECH CO LTD | R6: ARISTA NETWORKS, INC
A7: B | B7: ___3 | C7: ASY-53727-127;A0 | D7: 1000 | E7: A CBL-00408-05;B0 | F7: B | H7: CABLE ASY, BUSBAR, SUP | I7: 1 | J7: EA | K7: 1312 | L7: 21 | M7: 404 | N7: 929 | O7: 110 | P7: GREAT ASIA TAI TECH CO LTD | R7: ARISTA NETWORKS, INC
A8: B | B8: __2 | C8: ASY-53727-127;A0 | D8: 1000 | E8: A CBL-00711-01;A0 | F8: B | H8: POWER CORD, SAF-D GRID | I8: 16 | J8: EA | K8: 9247 | L8: 17800 | M8: 10272 | N8: 16775 | O8: 70 | P8: IDEAL ANDERSON ASIA PACIFIC LT | R8: ARISTA NETWORKS, INC
A9: B | B9: __2 | C9: ASY-53727-127;A0 | D9: 1000 | E9: A CT4BK18-C | F9: B | H9: WIRE_ZIP_TIE 4" | I9: 1 | J9: EA | K9: 7165.95 | L9: 1000 | M9: 4901.65 | N9: 3264.3 | O9: 55 | P9: D B ROBERTS COMPANY | R9: ARISTA NETWORKS, INC
A10: B | B10: ___3 | C10: ASY-53727-127;A0 | D10: 1000 | E10: A GSKT-00349 | F10: B | H10: GASKET,EMI,FOF,D-SHAPE | I10: 2 | J10: EA | K10: 1705 | L10: 0 | M10: 1539 | N10: 166 | O10: 25 | P10: SCHLEGEL ELECTRONIC MATERIALS | R10: ARISTA NETWORKS, INC
A11: B | B11: ___3 | C11: ASY-53727-127;A0 | D11: 1000 | E11: A GSKT-00352 | F11: B | H11: GASKET,EMI,FOF,D-SHAPE | I11: 1 | J11: EA | K11: 1773 | L11: 0 | M11: 464 | N11: 1309 | O11: 25 | P11: SCHLEGEL ELECTRONIC MATERIALS | R11: ARISTA NETWORKS, INC
A12: B | B12: ___3 | C12: ASY-53727-127;A0 | D12: 1000 | E12: A GSKT-00353 | F12: B | H12: GASKET,EMI,FOF,D-SHAPE | I12: 1 | J12: EA | K12: 430 | L12: 1000 | M12: 230 | N12: 1200 | O12: 79 | P12: SCHLEGEL ELECTRONIC MATERIALS | R12: ARISTA NETWORKS, INC
A13: B | B13: __2 | C13: ASY-53727-127;A0 | D13: 1000 | E13: A LBL-00112 | F13: B | H13: 1.000 IN W X 0.25 IN H | I13: 3 | J13: EA | K13: 5464 | L13: 0 | M13: 1827 | N13: 3637 | O13: 15 | P13: BRADLEY NAMEPLATE CORPORATION | R13: ARISTA NETWORKS, INC
A14: B | B14: __2 | C14: ASY-53727-127;A0 | D14: 1000 | E14: A LBL-00212-01 | F14: B | H14: LBL,ASY NUMBER | I14: 1 | J14: EA | K14: 4704.45 | L14: 0 | M14: 563.5 | N14: 4140.95 | O14: 15 | P14: LUSTRE-CAL NAMEPLATE | R14: ARISTA NETWORKS, INC
A15: B | B15: ___3 | C15: ASY-53727-127;A0 | D15: 1000 | E15: A LBL-00829-03;B0 | F15: B | H15: INSULATOR,DN8,CHASSIS, | I15: 1 | J15: EA | K15: 980 | L15: 0 | M15: 230 | N15: 750 | O15: 30 | P15: CYMMETRIK PRINTING CO, LTD | R15: ARISTA NETWORKS, INC
A16: B | B16: ____4 | C16: ASY-53727-127;A0 | D16: 1000 | E16: A LBL-00890-02 | F16: B | H16: INSULATOR,DN8,OOB,MP,R | I16: 2 | J16: EA | K16: 1956 | L16: 0 | M16: 308 | N16: 1648 | O16: 97 | P16: BOYD CORPORATION | R16: ARISTA NETWORKS, INC
A17: B | B17: __2 | C17: ASY-53727-127;A0 | D17: 1000 | E17: A LBL-00918-07;A1 | F17: B | H17: LBL, DENALI PSU CAGE | I17: 1 | J17: EA | K17: 996 | L17: 0 | M17: 246 | N17: 750 | O17: 30 | P17: CYMMETRIK PRINTING CO, LTD | R17: ARISTA NETWORKS, INC
A18: B | B18: __2 | C18: ASY-53727-127;A0 | D18: 1000 | E18: A LBL-00960-02;A0 | F18: B | H18: LBL,DN8,PSU CAGE,LWR R | I18: 1 | J18: EA | K18: 496 | L18: 100 | M18: 246 | N18: 350 | O18: 30 | P18: CYMMETRIK PRINTING CO, LTD | R18: ARISTA NETWORKS, INC
... A53: B | B53: __2 | C53: ASY-53727-127;A0 | D53: 1000 | E53: A PDOC-00036-12A0 | F53: B | H53: DOCUMENT, GETTING STA | I53: 1 | J53: EA | K53: 218 | L53: 700 | M53: 523 | N53: 395 | O53: 10 | P53: (D)GAMA ETIQUETAS SA DE CV | R53: ARISTA NETWORKS, INC
A54: B | B54: ___3 | C54: ASY-53727-127;A0 | D54: 1000 | E54: B ASY-05269-03;B0 | H54: ASY, DN8, CHASSIS, FRA | I54: 1 | J54: EA | K54: 480 | L54: 500 | M54: 230 | N54: 750 | O54: 100 | P54: W&B TECHNOLOGY LTD | R54: ARISTA NETWORKS, INC
A55: B | B55: ___3 | C55: ASY-53727-127;A0 | D55: 1000 | E55: B MTL-03296-02;B0 | F55: B | H55: MTL;,PSU CAGE CATCH,1. | I55: 12 | J55: EA | K55: 13448 | L55: 2500 | M55: 2748 | N55: 13200 | O55: 154 | P55: LEMTECH INTERNATIONAL LTD | R55: ARISTA NETWORKS, INC
A56: B | B56: ____4 | C56: ASY-53727-127;A0 | D56: 1000 | E56: B MTL-03978-01;C0 | F56: B | H56: MTL, DN, CHASSIS, DIVI | I56: 12 | J56: EA | K56: 8604 | L56: 18500 | M56: 7442 | N56: 19662 | O56: 75 | P56: LEMTECH INTERNATIONAL LTD | R56: ARISTA NETWORKS, INC
A57: B | B57: ____4 | C57: ASY-53727-127;A0 | D57: 1000 | E57: H FAS-00525 | F57: B | H57: SPRING CENTURY #80506 | I57: 6.6 | J57: EA | K57: 937.1 | L57: 10528 | M57: 5995.3 | N57: 5469.8 | O57: 55 | P57: CENTURY SPRING CORP | R57: ARISTA NETWORKS, INC
A58: B | B58: ____4 | C58: ASY-53727-127;A0 | D58: 1000 | E58: H FAS-00797 | F58: B | H58: SPRING,EXT.,0.188" OD, | I58: 4.4 | J58: EA | K58: 4164.5 | L58: 1200 | M58: 1876.6 | N58: 3487.9 | O58: 55 | P58: CENTURY SPRING CORP | R58: ARISTA NETWORKS, INC
A59: B | B59: ___3 | C59: ASY-53727-127;A0 | D59: 1000 | E59: H MECH-01196-03 | F59: B | H59: MECH, DN8, MAIN BUSBAR | I59: 12 | J59: EA | K59: 7914.05 | L59: 18000 | M59: 8215.75 | N59: 17698.3 | O59: 70 | P59: PENCOM-SO CA | R59: ARISTA NETWORKS, INC
A60: B | B60: ____4 | C60: ASY-53727-127;A0 | D60: 1000 | E60: H MECH-01254-01 | F60: B | H60: SELF CLINCH KEYHOLE3.5 | I60: 8 | J60: EA | K60: 2552 | L60: 10000 | M60: 504 | N60: 12048 | O60: 104 | P60: PENCOM-SO CA | R60: ARISTA NETWORKS, INC
A61: B | B61: ____4 | C61: ASY-53727-127;A0 | D61: 1000 | E61: H MECH-01254-01 | F61: B | H61: SELF CLINCH KEYHOLE3.5 | I61: 8 | J61: EA | K61: 2552 | L61: 10000 | M61: 504 | N61: 12048 | O61: 104 | P61: PENCOM-SO CA | R61: ARISTA NETWORKS, INC
A62: B | B62: ____4 | C62: ASY-53727-127;A0 | D62: 1000 | E62: H MECH-02384-02 | F62: B | H62: MECH, DENALI, FACEPLAT | I62: 1 | J62: EA | K62: 14557 | L62: 0 | M62: 150 | N62: 14407 | O62: 120 | P62: D B ROBERTS COMPANY | R62: ARISTA NETWORKS, INC
A63: B | B63: ____4 | C63: ASY-53727-127;A0 | D63: 1000 | E63: H MECH-02384-02 | F63: B | H63: MECH, DENALI, FACEPLAT | I63: 1 | J63: EA | K63: 14557 | L63: 0 | M63: 150 | N63: 14407 | O63: 120 | P63: D B ROBERTS COMPANY | R63: ARISTA NETWORKS, INC
A64: B | B64: ____4 | C64: ASY-53727-127;A0 | D64: 1000 | E64: H MECH-02436-01 | F64: B | H64: MECH,DN,CHASSIS,HANDLE | I64: 4.4 | J64: EA | K64: 2611.5 | L64: 2500 | M64: 1876.6 | N64: 3234.9 | O64: 45 | P64: LEMTECH INTERNATIONAL LTD | R64: ARISTA NETWORKS, INC
A65: B | B65: ____4 | C65: ASY-53727-127;A0 | D65: 1000 | E65: H MECH-03876-01 | F65: B | H65: MECH, DENALI, FACEPLAT | I65: 6 | J65: EA | K65: 24566.6 | L65: 10500 | M65: 2868 | N65: 32198.6 | O65: 30 | P65: AFAR TECHNOLOGY (HK) LIMITED | R65: ARISTA NETWORKS, INC
A66: B | B66: ____4 | C66: ASY-53727-127;A0 | D66: 1000 | E66: H MECH-03876-01 | F66: B | H66: MECH, DENALI, FACEPLAT | I66: 6 | J66: EA | K66: 24566.6 | L66: 10500 | M66: 2868 | N66: 32198.6 | O66: 30 | P66: AFAR TECHNOLOGY (HK) LIMITED | R66: ARISTA NETWORKS, INC
... A77: B | B77: __2 | C77: ASY-53727-127;A0 | D77: 1000 | E77: P S-948 | F77: B | H77: ULINE S-948 5 X 7" BOL | I77: 2 | J77: EA | K77: 886 | L77: 1000 | M77: 1767 | N77: 119 | O77: 20 | P77: (D)ULINE SHIPPING SUPPLIES | R77: ARISTA NETWORKS, INC
A78: M | B78: __2 | C78: ASY-53727-127;A0 | D78: 1000 | E78: ASY-03128-24;A0 | F78: S | G78: 6AARI | H78: ASY, DN, BASE LEVEL, C | I78: 1 | J78: EA | K78: 16 | L78: 230 | M78: 246 | N78: 0 | O78: 3 | R78: ARISTA NETWORKS, INC
A79: M | B79: __2 | C79: ASY-53727-127;A0 | D79: 1000 | E79: ASY-03131-08;C0 | F79: S | G79: 6AARI | H79: ASY,CZ,PSU CAGE ENSAMB | I79: 1 | J79: EA | K79: 17 | L79: 229 | M79: 246 | N79: 0 | O79: 3 | R79: ARISTA NETWORKS, INC
A80: M | B80: ___3 | C80: ASY-53727-127;A0 | D80: 1000 | E80: ASY-03135-03;A0 | F80: S | G80: 6N02 | H80: ASY DN8 CHASSIS BULKHE | I80: 1 | J80: EA | K80: 241 | L80: 0 | M80: 230 | N80: 11 | O80: 1 | R80: ARISTA NETWORKS, INC
A81: M | B81: ___3 | C81: ASY-53727-127;A0 | D81: 1000 | E81: ASY-03136-03;A0 | F81: S | G81: 6N045 | H81: ASY DN8 CHASSIS TOP FR | I81: 1 | J81: EA | K81: 182 | L81: 62 | M81: 330 | N81: -86 | O81: 1 | R81: ARISTA NETWORKS, INC
A82: M | B82: ___3 | C82: ASY-53727-127;A0 | D82: 1000 | E82: ASY-03137-03;A0 | F82: S | G82: 6N04 | H82: ASY DN8 CHASSIS TOP RE | I82: 1 | J82: EA | K82: 111 | L82: 152 | M82: 230 | N82: 33 | O82: 1 | R82: ARISTA NETWORKS, INC
A83: M | B83: __2 | C83: ASY-53727-127;A0 | D83: 1000 | E83: ASY-03138-03;A0 | F83: S | G83: 6N04 | H83: ASY,DN8,CHASSIS,TOP,CO | I83: 1 | J83: EA | K83: 308 | L83: 0 | M83: 346 | N83: -38 | O83: 1 | R83: ARISTA NETWORKS, INC
A84: M | B84: ___3 | C84: ASY-53727-127;A0 | D84: 1000 | E84: ASY-03139-03;A0 | F84: S | G84: 6N04 | H84: ASY, DN8, CHASSIS, TOP | I84: 1 | J84: EA | K84: 234 | L84: 0 | M84: 230 | N84: 4 | O84: 1 | R84: ARISTA NETWORKS, INC
...

Sheet Leadtimes
A2: Weekly demand: | B2: 400
E3: Primary operations: | H3: Brake - Pem | K3: Press:
A4: Area: | B4: Hours available: | C4: Leadtime: | E4: Workcenter: | F4: ∑ Hours: | H4: Workcenter: | I4: ∑ Hours: | K4: Workcenter: | L4: ∑ Hours:
A5: Primary ops: | B5: =21*6*B10 -> 378 | C5: =SUM(F5:F12) -> 719.30942 | E5: 6N02 | F5: =SUMIF($D$15:$D$302,E5,$K$15:$K$302) -> 7.0175439 | H5: BR130 | I5: =SUMIF($D$15:$D$302,H5,$K$15:$K$302) -> 25 | K5: 6P200 | L5: =SUMIF($D$15:$D$302,K5,$K$15:$K$302) -> 9.3333333
A6: Midfield: | B6: =21*6*B11 -> 1134 | C6: =SUM(I5:I12)+SUM(L12) -> 2099.2743 | E6: 6N03 | F6: =SUMIF($D$15:$D$302,E6,$K$15:$K$302) -> 90.648883 | H6: BRK80 | I6: =SUMIF($D$15:$D$302,H6,$K$15:$K$302) -> 62.5 | K6: 6P20C | L6: =SUMIF($D$15:$D$302,K6,$K$15:$K$302) -> 35.692308
A7: Press | B7: =21*6*B12 -> 126 | C7: =SUM(L5:L9) -> 117.02326 | E7: 6N04 | F7: =SUMIF($D$15:$D$302,E7,$K$15:$K$302) -> 248.6808 | H7: RG100 | I7: =SUMIF($D$15:$D$302,H7,$K$15:$K$302) -> 35.666667 | K7: 6P250 | L7: =SUMIF($D$15:$D$302,K7,$K$15:$K$302) -> 32.114833
E8: 6N041 | F8: =SUMIF($D$15:$D$302,E8,$K$15:$K$302) -> 43.528191 | H8: 6BATC | I8: =SUMIF($D$15:$D$302,H8,$K$15:$K$302) -> 27.764706 | K8: 6P25C | L8: =SUMIF($D$15:$D$302,K8,$K$15:$K$302) -> 26.549451
A9: Area: | B9: Machines: | E9: 6N042 | F9: =SUMIF($D$15:$D$302,E9,$K$15:$K$302) -> 229.74297 | H9: 6BRG | I9: =SUMIF($D$15:$D$302,H9,$K$15:$K$302) -> 12.8 | K9: 6MACH | L9: =SUMIF($D$15:$D$302,K9,$K$15:$K$302) -> 13.333333
A10: Primary ops: | B10: 3 | E10: 6N043 | F10: =SUMIF($D$15:$D$302,E10,$K$15:$K$302) -> 26.666667 | H10: 6BRK | I10: =SUMIF($D$15:$D$302,H10,$K$15:$K$302) -> 569.6515
A11: Midfield: | B11: 9 | E11: 6N044 | F11: =SUMIF($D$15:$D$302,E11,$K$15:$K$302) -> 22.222222 | H11: 6APEM | I11: =SUMIF($D$15:$D$302,H11,$K$15:$K$302) -> 1028.8915 | K11: Midfield:
A12: Press | B12: 1 | E12: 6N045 | F12: =SUMIF($D$15:$D$302,E12,$K$15:$K$302) -> 50.802139 | H12: 6DBR | I12: =SUMIF($D$15:$D$302,H12,$K$15:$K$302) -> 318.66667 | K12: 6SLK | L12: =SUMIF($D$15:$D$302,K12,$K$15:$K$302) -> 18.333333
A14: Process Sheet Number | B14: End Item Part Number | C14: Quantity: | D14: Work Center/Vendor | E14: Step Number | F14: Run/Setup | G14: Description 11 | H14: Standard Rate | I14: Lead Time | J14: Crew Size | K14: 1W batch hours:
A15: ASY-03128-24;A0 | B15: ASY-03128-24;A0 | C15: 1 | D15: 6AARI | E15: 00110 | F15: R | G15: ENSAMBLE SEGUN DIBUJO | H15: 0.667 | I15: 0 | J15: 4 | K15: =(C15*$B$2)/(H15/J15) -> 2398.8006
A16: ASY-03131-08;C0 | B16: ASY-03131-08;C0 | C16: 1 | D16: 6AARI | E16: 00100 | F16: R | G16: ENSAMBLE SEGUN DIBUJO | H16: 1.25 | I16: 0 | J16: 1 | K16: =(C16*$B$2)/(H16/J16) -> 320
A17: ASY-03135-03;A0 | B17: ASY-03135-03;A0 | C17: 1 | D17: 6N02 | E17: 00110 | F17: R | G17: PUNZONADO EN TORRETA | H17: 57 | I17: 0 | J17: 1 | K17: =(C17*$B$2)/(H17/J17) -> 7.0175439
A18: ASY-03135-03;A0 | B18: ASY-03135-03;A0 | C18: 1 | D18: 6DBR | E18: 00120 | F18: R | G18: REBABEO PARA MANEJO | H18: 100 | I18: 0 | J18: 1 | K18: =(C18*$B$2)/(H18/J18) -> 4
A19: ASY-03135-03;A0 | B19: ASY-03135-03;A0 | C19: 1 | D19: 6BRK | E19: 00140 | F19: R | G19: DOBLADORA AMADA | H19: 250 | I19: 0 | J19: 1 | K19: =(C19*$B$2)/(H19/J19) -> 1.6
A20: ASY-03135-03;A0 | B20: ASY-03135-03;A0 | C20: 1 | D20: 6APEM | E20: 00160 | F20: R | G20: INSERCION DE PEM | H20: 11 | I20: 0 | J20: 1 | K20: =(C20*$B$2)/(H20/J20) -> 36.363636
A21: ASY-03136-03;A0 | B21: ASY-03136-03;A0 | C21: 1 | D21: 6N045 | E21: 00110 | F21: R | G21: PUNZONADO EN TORRETA | H21: 55 | I21: 0 | J21: 1 | K21: =(C21*$B$2)/(H21/J21) -> 7.2727273
A22: ASY-03136-03;A0 | B22: ASY-03136-03;A0 | C22: 1 | D22: 6DBR | E22: 00120 | F22: R | G22: REBABEO PARA MANEJO | H22: 100 | I22: 0 | J22: 1 | K22: =(C22*$B$2)/(H22/J22) -> 4
A23: ASY-03136-03;A0 | B23: ASY-03136-03;A0 | C23: 1 | D23: 6BRK | E23: 00140 | F23: R | G23: DOBLADORA AMADA | H23: 25 | I23: 0 | J23: 1 | K23: =(C23*$B$2)/(H23/J23) -> 16
A24: ASY-03136-03;A0 | B24: ASY-03136-03;A0 | C24: 1 | D24: 6APEM | E24: 00160 | F24: R | G24: INSERCION DE PEM | H24: 20 | I24: 0 | J24: 1 | K24: =(C24*$B$2)/(H24/J24) -> 20
A25: ASY-03137-03;A0 | B25: ASY-03137-03;A0 | C25: 1 | D25: 6N04 | E25: 00110 | F25: R | G25: PUNZONADO EN TORRETA | H25: 44 | I25: 0 | J25: 1 | K25: =(C25*$B$2)/(H25/J25) -> 9.0909091
A26: ASY-03137-03;A0 | B26: ASY-03137-03;A0 | C26: 1 | D26: 6DBR | E26: 00120 | F26: R | G26: REBABEO PARA MANEJO | H26: 100 | I26: 0 | J26: 1 | K26: =(C26*$B$2)/(H26/J26) -> 4
... A179: MECH-01827-01;B0 | B179: MECH-01827-01;B0 | C179: 2 | D179: RG100 | E179: 00140 | F179: R | G179: DOBLADORA AMADA | H179: 32 | I179: 0 | J179: 1 | K179: =(C179*$B$2)/(H179/J179) -> 25
A180: MECH-01827-01;B0 | B180: MECH-01827-01;B0 | C180: 2 | D180: 232625 | E180: 00150 | G180: MECH-01827-01 REV B0 | H180: 0 | I180: 5 | J180: 1 | K180: =(C180*$B$2)/(H180/J180) -> #DIV/0!
A181: MTL-02212-01;A0 | B181: MTL-02212-01;A0 | C181: 2 | D181: 6N03 | E181: 00110 | F181: R | G181: CORTE LASER AMADA | H181: 456 | I181: 0 | J181: 1 | K181: =(C181*$B$2)/(H181/J181) -> 1.754386
A182: MTL-02213-05;A0 | B182: MTL-02213-05;A0 | C182: 1 | D182: 6N045 | E182: 00110 | F182: R | G182: PUNZONADO EN TORRETA | H182: 17 | I182: 0 | J182: 1 | K182: =(C182*$B$2)/(H182/J182) -> 23.529412
A183: MTL-02213-05;A0 | B183: MTL-02213-05;A0 | C183: 1 | D183: 6DBR | E183: 00120 | F183: R | G183: REBABEO PARA MANEJO | H183: 100 | I183: 0 | J183: 1 | K183: =(C183*$B$2)/(H183/J183) -> 4
A184: MTL-02213-05;A0 | B184: MTL-02213-05;A0 | C184: 1 | D184: 6BATC | E184: 00140 | F184: R | G184: DOBLADORA AMADA | H184: 25 | I184: 0 | J184: 1 | K184: =(C184*$B$2)/(H184/J184) -> 16
A185: MTL-02214-01;A1 | B185: MTL-02214-01;A1 | C185: 1 | D185: 6N03 | E185: 00110 | F185: R | G185: CORTE LASER AMADA | H185: 54 | I185: 0 | J185: 1 | K185: =(C185*$B$2)/(H185/J185) -> 7.4074074
A186: MTL-02214-01;A1 | B186: MTL-02214-01;A1 | C186: 1 | D186: 6MACH | E186: 00130 | F186: R | G186: MAQUINADO | H186: 60 | I186: 0 | J186: 1 | K186: =(C186*$B$2)/(H186/J186) -> 6.6666667
A187: MTL-02214-01;A1 | B187: MTL-02214-01;A1 | C187: 1 | D187: 6BRK | E187: 00160 | F187: R | G187: DOBLADORA AMADA | H187: 35 | I187: 0 | J187: 1 | K187: =(C187*$B$2)/(H187/J187) -> 11.428571
A188: MTL-02214-01;A1 | B188: MTL-02214-01;A1 | C188: 1 | D188: 6BRK | E188: 00180 | F188: R | G188: DOBLADORA AMADA | H188: 300 | I188: 0 | J188: 1 | K188: =(C188*$B$2)/(H188/J188) -> 1.3333333
A189: MTL-02214-01;A1 | B189: MTL-02214-01;A1 | C189: 1 | D189: 232625 | E189: 00190 | G189: MTL-02214-01 REV A1 | H189: 0 | I189: 5 | J189: 1 | K189: =(C189*$B$2)/(H189/J189) -> #DIV/0!
A190: MTL-02215-02;A1 | B190: MTL-02215-02;A1 | C190: 1 | D190: 6N03 | E190: 00110 | F190: R | G190: CORTE LASER AMADA | H190: 54 | I190: 0 | J190: 1 | K190: =(C190*$B$2)/(H190/J190) -> 7.4074074
A191: MTL-02215-02;A1 | B191: MTL-02215-02;A1 | C191: 1 | D191: 6BRK | E191: 00140 | F191: R | G191: DOBLADORA AMADA | H191: 35 | I191: 0 | J191: 1 | K191: =(C191*$B$2)/(H191/J191) -> 11.428571
A192: MTL-02215-02;A1 | B192: MTL-02215-02;A1 | C192: 1 | D192: 6BRK | E192: 00160 | F192: R | G192: DOBLADORA AMADA | H192: 300 | I192: 0 | J192: 1 | K192: =(C192*$B$2)/(H192/J192) -> 1.3333333
A193: MTL-02215-02;A1 | B193: MTL-02215-02;A1 | C193: 1 | D193: 232625 | E193: 00170 | G193: MTL-02215-02 REV A1 | H193: 0 | I193: 5 | J193: 1 | K193: =(C193*$B$2)/(H193/J193) -> #DIV/0!
A194: MTL-02216-03;A0 | B194: MTL-02216-03;A0 | C194: 1 | D194: 6N03 | E194: 00110 | F194: R | G194: CORTE LASER AMADA | H194: 52 | I194: 0 | J194: 1 | K194: =(C194*$B$2)/(H194/J194) -> 7.6923077
...

Sheet Assy WC
A1: Process Sheet Number | B1: EndItemPartNumber | C1: Parent: | D1: Work Center/Vendor | E1: Description 1 | F1: Description 2 | G1: Step Number | H1: Run/Setup | I1: Operation Code | J1: Component Part Number | K1: Description 11 | L1: Description 21 | M1: Standard Rate | N1: Lead Time | O1: Crew Size | P1: Overlap Step Number | Q1: Overlap Quantity
A2: ASY-03128-24;A0 | B2: ASY-03128-24;A0 | C2: ASY-53727-127;A0 | D2: 6AARI | E2: JCG 20 08 24 | G2: 00110 | H2: R | I2: 801 | K2: ENSAMBLE SEGUN DIBUJO | M2: 0.667 | N2: 0 | O2: 4 | Q2: 0
A3: ASY-03131-08;C0 | B3: ASY-03131-08;C0 | C3: ASY-53727-127;A0 | D3: 6AARI | E3: JCG 05 28 20 | G3: 00100 | H3: R | I3: 801 | K3: ENSAMBLE SEGUN DIBUJO | M3: 1.25 | N3: 0 | O3: 1 | Q3: 0
A4: ASY-03135-03;A0 | B4: ASY-03135-03;A0 | C4: ASY-53727-127;A0 | D4: 6N02 | E4: KSS 05 14 19 | G4: 00110 | H4: R | I4: 102 | K4: PUNZONADO EN TORRETA | M4: 57 | N4: 0 | O4: 1 | Q4: 0
A5: ASY-03135-03;A0 | B5: ASY-03135-03;A0 | C5: ASY-53727-127;A0 | D5: 6DBR | E5: KSS 05 14 19 | G5: 00120 | H5: R | I5: 200 | K5: REBABEO PARA MANEJO | L5: SEGURO | M5: 100 | N5: 0 | O5: 1 | Q5: 0
A6: ASY-03135-03;A0 | B6: ASY-03135-03;A0 | C6: ASY-53727-127;A0 | D6: 6BRK | E6: KSS 05 14 19 | G6: 00140 | H6: R | I6: 302 | K6: DOBLADORA AMADA | M6: 250 | N6: 0 | O6: 1 | Q6: 0
A7: ASY-03135-03;A0 | B7: ASY-03135-03;A0 | C7: ASY-53727-127;A0 | D7: 6APEM | E7: KSS 05 14 19 | G7: 00160 | H7: R | I7: 400 | K7: INSERCION DE PEM | L7: FEOX-M3(11X) | M7: 11 | N7: 0 | O7: 1 | Q7: 0
A8: ASY-03136-03;A0 | B8: ASY-03136-03;A0 | C8: ASY-53727-127;A0 | D8: 6N045 | E8: KSS 01 23 19 | G8: 00110 | H8: R | I8: 102 | K8: PUNZONADO EN TORRETA | M8: 55 | N8: 0 | O8: 1 | Q8: 0
A9: ASY-03136-03;A0 | B9: ASY-03136-03;A0 | C9: ASY-53727-127;A0 | D9: 6DBR | E9: KSS 01 23 19 | G9: 00120 | H9: R | I9: 200 | K9: REBABEO PARA MANEJO | L9: SEGURO | M9: 100 | N9: 0 | O9: 1 | Q9: 0
A10: ASY-03136-03;A0 | B10: ASY-03136-03;A0 | C10: ASY-53727-127;A0 | D10: 6BRK | E10: KSS 01 23 19 | G10: 00140 | H10: R | I10: 302 | K10: DOBLADORA AMADA | M10: 25 | N10: 0 | O10: 1 | Q10: 0
A11: ASY-03136-03;A0 | B11: ASY-03136-03;A0 | C11: ASY-53727-127;A0 | D11: 6APEM | E11: KSS 01 23 19 | G11: 00160 | H11: R | I11: 400 | K11: INSERCION DE PEM | L11: CLS-M3-1 (11X) | M11: 20 | N11: 0 | O11: 1 | Q11: 0
A12: ASY-03137-03;A0 | B12: ASY-03137-03;A0 | C12: ASY-53727-127;A0 | D12: 6N04 | E12: KSS 01 23 19 | G12: 00110 | H12: R | I12: 102 | K12: PUNZONADO EN TORRETA | M12: 44 | N12: 0 | O12: 1 | Q12: 0
A13: ASY-03137-03;A0 | B13: ASY-03137-03;A0 | C13: ASY-53727-127;A0 | D13: 6DBR | E13: KSS 01 23 19 | G13: 00120 | H13: R | I13: 200 | K13: REBABEO PARA MANEJO | L13: SEGURO | M13: 100 | N13: 0 | O13: 1 | Q13: 0
A14: ASY-03137-03;A0 | B14: ASY-03137-03;A0 | C14: ASY-53727-127;A0 | D14: 6BRK | E14: KSS 01 23 19 | G14: 00140 | H14: R | I14: 302 | K14: DOBLADORA AMADA | M14: 25 | N14: 0 | O14: 1 | Q14: 0
A15: ASY-03137-03;A0 | B15: ASY-03137-03;A0 | C15: ASY-53727-127;A0 | D15: 6APEM | E15: KSS 01 23 19 | G15: 00160 | H15: R | I15: 400 | K15: INSERCION DE PEM | L15: MECH-05243 | M15: 200 | N15: 0 | O15: 1 | Q15: 0
A16: ASY-03137-03;A0 | B16: ASY-03137-03;A0 | C16: ASY-53727-127;A0 | D16: 6APEM | E16: KSS 01 23 19 | G16: 00180 | H16: R | I16: 400 | K16: INSERCION DE PEM | L16: CLS-M4-1 (4X) | M16: 62 | N16: 0 | O16: 1 | Q16: 0
A17: ASY-03137-03;A0 | B17: ASY-03137-03;A0 | C17: ASY-53727-127;A0 | D17: 6APEM | E17: KSS 01 23 19 | G17: 00200 | H17: R | I17: 400 | K17: INSERCION DE PEM | L17: CLS-M3-1(11X) | M17: 23 | N17: 0 | O17: 1 | Q17: 0
A18: ASY-03138-03;A0 | B18: ASY-03138-03;A0 | C18: ASY-53727-127;A0 | D18: 6N04 | E18: JCG 10 28 20 | G18: 00110 | H18: R | I18: 102 | K18: PUNZONADO EN TORRETA | M18: 76 | N18: 0 | O18: 1 | Q18: 0
A19: ASY-03138-03;A0 | B19: ASY-03138-03;A0 | C19: ASY-53727-127;A0 | D19: 6DBR | E19: JCG 10 28 20 | G19: 00120 | H19: R | I19: 200 | K19: REBABEO PARA MANEJO | L19: SEGURO | M19: 100 | N19: 0 | O19: 1 | Q19: 0
A20: ASY-03138-03;A0 | B20: ASY-03138-03;A0 | C20: ASY-53727-127;A0 | D20: 6BRK | E20: JCG 10 28 20 | G20: 00140 | H20: R | I20: 302 | K20: DOBLADORA AMADA | M20: 40 | N20: 0 | O20: 1 | Q20: 0
A21: ASY-03138-03;A0 | B21: ASY-03138-03;A0 | C21: ASY-53727-127;A0 | D21: 6APEM | E21: JCG 10 28 20 | G21: 00160 | H21: R | I21: 400 | K21: INSERCION DE PEM | L21: CLS-M3-1 (6X) | M21: 20 | N21: 0 | O21: 1 | Q21: 0
A22: ASY-03139-03;A0 | B22: ASY-03139-03;A0 | C22: ASY-53727-127;A0 | D22: 6N04 | E22: KSS 01 23 19 | G22: 00110 | H22: R | I22: 102 | K22: PUNZONADO EN TORRETA | M22: 48 | N22: 0 | O22: 1 | Q22: 0
A23: ASY-03139-03;A0 | B23: ASY-03139-03;A0 | C23: ASY-53727-127;A0 | D23: 6DBR | E23: KSS 01 23 19 | G23: 00120 | H23: R | I23: 200 | K23: REBABEO PARA MANEJO | L23: SEGURO | M23: 100 | N23: 0 | O23: 1 | Q23: 0
A24: ASY-03139-03;A0 | B24: ASY-03139-03;A0 | C24: ASY-53727-127;A0 | D24: 6BRK | E24: KSS 01 23 19 | G24: 00140 | H24: R | I24: 302 | K24: DOBLADORA AMADA | M24: 25 | N24: 0 | O24: 1 | Q24: 0
A25: ASY-03139-03;A0 | B25: ASY-03139-03;A0 | C25: ASY-53727-127;A0 | D25: 6APEM | E25: KSS 01 23 19 | G25: 00160 | H25: R | I25: 400 | K25: INSERCION DE PEM | L25: MECH-05243 | M25: 120 | N25: 0 | O25: 1 | Q25: 0
A26: ASY-03139-03;A0 | B26: ASY-03139-03;A0 | C26: ASY-53727-127;A0 | D26: 6APEM | E26: KSS 01 23 19 | G26: 00180 | H26: R | I26: 400 | K26: INSERCION DE PEM | L26: CLS-M4-1 (4X) | M26: 30 | N26: 0 | O26: 1 | Q26: 0
A27: ASY-03143-06;A0 | B27: ASY-03143-06;A0 | C27: ASY-53727-127;A0 | D27: 6N041 | E27: JCG 11 09 19 | G27: 00110 | H27: R | I27: 102 | K27: PUNZONADO EN TORRETA | M27: 36 | N27: 0 | O27: 1 | Q27: 0
A28: ASY-03143-06;A0 | B28: ASY-03143-06;A0 | C28: ASY-53727-127;A0 | D28: 6DBR | E28: JCG 11 09 19 | G28: 00120 | H28: R | I28: 200 | K28: REBABEO PARA MANEJO | L28: SEGURO | M28: 100 | N28: 0 | O28: 1 | Q28: 0
A29: ASY-03143-06;A0 | B29: ASY-03143-06;A0 | C29: ASY-53727-127;A0 | D29: 6BRK | E29: JCG 11 09 19 | G29: 00140 | H29: R | I29: 302 | K29: DOBLADORA AMADA | M29: 25 | N29: 0 | O29: 1 | Q29: 0
A30: ASY-03143-06;A0 | B30: ASY-03143-06;A0 | C30: ASY-53727-127;A0 | D30: 6APEM | E30: JCG 11 09 19 | G30: 00160 | H30: R | I30: 400 | K30: INSERCION DE PEM | L30: CLS-M3-0 (9X) | M30: 22 | N30: 0 | O30: 1 | Q30: 0
A31: ASY-03143-06;A0 | B31: ASY-03143-06;A0 | C31: ASY-53727-127;A0 | D31: 6APEM | E31: JCG 11 09 19 | G31: 00180 | H31: R | I31: 400 | K31: INSERCION DE PEM | L31: PEM GPSS-M3-6 (6) | M31: 40 | N31: 0 | O31: 1 | Q31: 0
A32: ASY-03145-02;A0 | B32: ASY-03145-02;A0 | C32: ASY-53727-127;A0 | D32: 6N042 | E32: JCG 11 09 19 | G32: 00110 | H32: R | I32: 102 | K32: PUNZONADO EN TORRETA | M32: 100 | N32: 0 | O32: 1 | Q32: 0
A33: ASY-03145-02;A0 | B33: ASY-03145-02;A0 | C33: ASY-53727-127;A0 | D33: 6DBR | E33: JCG 11 09 19 | G33: 00120 | H33: R | I33: 200 | K33: REBABEO PARA MANEJO | L33: SEGURO | M33: 100 | N33: 0 | O33: 1 | Q33: 0
A34: ASY-03145-02;A0 | B34: ASY-03145-02;A0 | C34: ASY-53727-127;A0 | D34: 6BRK | E34: JCG 11 09 19 | G34: 00140 | H34: R | I34: 302 | K34: DOBLADORA AMADA | M34: 44.25 | N34: 0 | O34: 1 | Q34: 0
A35: ASY-03145-02;A0 | B35: ASY-03145-02;A0 | C35: ASY-53727-127;A0 | D35: 6APEM | E35: JCG 11 09 19 | G35: 00160 | H35: R | I35: 400 | K35: INSERCION DE PEM | L35: CLS-M3-1 (2X) | M35: 60 | N35: 0 | O35: 1 | Q35: 0
A36: ASY-03152-06;A0 | B36: ASY-03152-06;A0 | C36: ASY-53727-127;A0 | D36: 6N042 | E36: JCG 11 10 19 | G36: 00110 | H36: R | I36: 102 | K36: PUNZONADO EN TORRETA | L36: CON ALIMENTADOR | M36: 24 | N36: 0 | O36: 1 | Q36: 0
A37: ASY-03152-06;A0 | B37: ASY-03152-06;A0 | C37: ASY-53727-127;A0 | D37: 6DBR | E37: JCG 11 10 19 | G37: 00120 | H37: R | I37: 200 | K37: REBABEO PARA MANEJO | L37: SEGURO | M37: 100 | N37: 0 | O37: 1 | Q37: 0
A38: ASY-03152-06;A0 | B38: ASY-03152-06;A0 | C38: ASY-53727-127;A0 | D38: 6BRK | E38: JCG 11 10 19 | G38: 00140 | H38: R | I38: 302 | K38: DOBLADORA AMADA | M38: 60 | N38: 0 | O38: 1 | Q38: 0
A39: ASY-03152-06;A0 | B39: ASY-03152-06;A0 | C39: ASY-53727-127;A0 | D39: 6APEM | E39: JCG 11 10 19 | G39: 00160 | H39: R | I39: 400 | K39: INSERCION DE PEM | L39: PEM MECH-02384-02 | M39: 120 | N39: 0 | O39: 1 | Q39: 0
A40: ASY-03152-06;A0 | B40: ASY-03152-06;A0 | C40: ASY-53727-127;A0 | D40: 6APEM | E40: JCG 11 10 19 | G40: 00180 | H40: R | I40: 400 | K40: INSERCION DE PEM | L40: GPSS-M3-6-P (2X) | M40: 60 | N40: 0 | O40: 1 | Q40: 0
...
