Workbook

Sheet SIOP File
G1: Ensamble días por año | I1: 202 | J1: 2025 | M1: 2023 | N1: 2024 | O1: 2024 | P1: 2024 | Q1: 2024 | R1: 2024 | S1: 2024 | T1: 2024 | U1: 2024 | V1: 2024 | W1: 2024 | X1: 2024 | Y1: 2024 | Z1: 2025 | AA1: 2025 | AB1: 2025 | AC1: 2025 | AD1: 2025 | AF1: 2023 | AG1: 2024 | AH1: 2024 | AI1: 2024 | AJ1: 2024 | AK1: 2024 | AL1: 2024 | AM1: 2024 | AN1: 2024 | AO1: 2024 | AP1: 2024 | AQ1: 2024 | AR1: 2024 | AS1: 2025 | AT1: 2025 | AU1: 2025 | AV1: 2025 | AW1: 2025
G2: Fabricación días por año | I2: 307
AX3: Punzonado | AZ3: Corte Laser | BA3: Estampado | BE3: Platinado (Externo) | BF3: Maquinado | BG3: Rebabeo Por Vibracion | BH3: Rebabeo Manual | BI3: Lijado (Time saber) | BJ3: Insercion PEM | BK3: Doblado Amada | BN3: Insercion PEM | BO3: Platinado (Externo) | BP3: Soldadura | BU3: Prep Pintura (Enmascarillado) | BV3: Pintura | BX3: Serigrafía | BY3: Ensamble Final | CH3: INSPECCION | CI3: Ensamble Final
G4: 2024 | AX4: Torreta | AY4: Combo | BA4: 110 | BB4: 200 | BC4: 250 | BD4: 300 | BK4: ----- | BL4: ATC | BM4: RG | BP4: Perno | BQ4: MicroAlam | BR4: Punto | BS4: TIG | BT4: Robot | BV4: PNT | BW4: VRNP | BY4: Amphenol | BZ4: Arista | CA4: Friedrich | CB4: Hyperscale | CC4: Linecards | CD4: Sanmina | CE4: AFL ASCN | CF4: AFL NO/ASCND | CG4: Otros Ensam | CI4: 335 - 224 | CJ4: 223 - 156 | CK4: 155 - 124 | CL4: 123 - 98 | CM4: 97 - 70 | CN4: 69 - 49 | CO4: 48 - 35 | CP4: 34 - 23 | CQ4: 22 - 15 | CR4: 14 - 10 | CS4: '9 - 6 | CT4: ´5 - 3 | CU4: 2 - 0.25 | DP4: # Procesos | DQ4: Total Work Content
A5: Loc | B5: Cust. Code | C5: Program | D5: Part Number | E5: Description | F5: Price | G5: Total Revenue | H5: Total Volume | I5: Monthly Avg. Volume | J5: Total Revenue | K5: Total Volume | L5: Monthly Avg. Volume | M5: 12 | N5: 1 | O5: 2 | P5: 3 | Q5: 4 | R5: 5 | S5: 6 | T5: 7 | U5: 8 | V5: 9 | W5: 10 | X5: 11 | Y5: 12 | Z5: 1 | AA5: 2 | AB5: 3 | AC5: 4 | AD5: 5 | AE5: x | AF5: 12 | AG5: 1 | AH5: 2 | AI5: 3 | AJ5: 4 | AK5: 5 | AL5: 6 | AM5: 7 | AN5: 8 | AO5: 9 | AP5: 10 | AQ5: 11 | AR5: 12 | AS5: 1 | AT5: 2 | AU5: 3 | AV5: 4 | AW5: 5 | AX5: 3 | AY5: 2 | AZ5: 1 | BA5: 2 | BB5: 1 | BC5: 6 | BD5: 3 | BE5: ? | BF5: 1 | BG5: 1 | BH5: 10 | BI5: 1 | BJ5: 1 | BK5: 7 | BL5: 1 | BM5: 3 | BN5: 1 | BO5: ? | BP5: ? | BQ5: ? | BR5: ? | BS5: ? | BT5: ? | BU5: ? | BV5: 1 | BW5: 1 | BX5: 1
A6: MX | B6: AFL | C6: 864CABINET | D6: EA000461;7 | E6: CABINET WELDMENT EDC 8 | F6: 725.43 | G6: =F6*H6 -> 0 | H6: =SUM(N6:Y6) -> 0 | I6: =ROUNDUP(H6/12,0) -> 0 | J6: =K6*F6 -> 0 | K6: =SUM(Z6:AD6) -> 0 | L6: =ROUNDUP(K6/5,0) -> 0 | M6: 0 | N6: 0 | O6: 0 | P6: 0 | Q6: 0 | R6: 0 | S6: 0 | T6: 0 | U6: 0 | V6: 0 | W6: 0 | X6: 0 | Y6: 0 | Z6: 0 | AA6: 0 | AB6: 0 | AC6: 0 | AD6: 0 | AF6: 0 | AG6: 0 | AH6: 0 | AI6: 0 | AJ6: 0 | AK6: 0 | AL6: 0 | AM6: 0 | AN6: 0 | AO6: 0 | AP6: 0 | AQ6: 0 | AR6: 0 | AS6: 0 | AT6: 0 | AU6: 0 | AV6: 0 | AW6: 0 | CI6: 120
A7: MX | B7: AFL | C7: 864CABINET | D7: EA000464;4 | E7: SIDE, TRANSITION AREA, | F7: 8.65 | G7: =F7*H7 -> 0 | H7: =SUM(N7:Y7) -> 0 | I7: =ROUNDUP(H7/12,0) -> 0 | J7: =K7*F7 -> 0 | K7: =SUM(Z7:AD7) -> 0 | L7: =ROUNDUP(K7/5,0) -> 0 | M7: 0 | N7: 0 | O7: 0 | P7: 0 | Q7: 0 | R7: 0 | S7: 0 | T7: 0 | U7: 0 | V7: 0 | W7: 0 | X7: 0 | Y7: 0 | Z7: 0 | AA7: 0 | AB7: 0 | AC7: 0 | AD7: 0 | AF7: 0 | AG7: 0 | AH7: 0 | AI7: 0 | AJ7: 0 | AK7: 0 | AL7: 0 | AM7: 0 | AN7: 0 | AO7: 0 | AP7: 0 | AQ7: 0 | AR7: 0 | AS7: 0 | AT7: 0 | AU7: 0 | AV7: 0 | AW7: 0 | CI7: 120
A8: MX | B8: AFL | C8: AFL | D8: FM004071;2 | E8: SPLICE ONLY COVER, LL- | F8: 7.34 | G8: =F8*H8 -> 0 | H8: =SUM(N8:Y8) -> 0 | I8: =ROUNDUP(H8/12,0) -> 0 | J8: =K8*F8 -> 0 | K8: =SUM(Z8:AD8) -> 0 | L8: =ROUNDUP(K8/5,0) -> 0 | M8: 74 | N8: 0 | O8: 0 | P8: 0 | Q8: 0 | R8: 0 | S8: 0 | T8: 0 | U8: 0 | V8: 0 | W8: 0 | X8: 0 | Y8: 0 | Z8: 0 | AA8: 0 | AB8: 0 | AC8: 0 | AD8: 0 | AF8: 793.28 | AG8: 0 | AH8: 0 | AI8: 0 | AJ8: 0 | AK8: 0 | AL8: 0 | AM8: 0 | AN8: 0 | AO8: 0 | AP8: 0 | AQ8: 0 | AR8: 0 | AS8: 0 | AT8: 0 | AU8: 0 | AV8: 0 | AW8: 0 | CI8: #N/A
A9: MX | B9: AFL | C9: AFL HYPER | D9: HCF-48U-ODF-003;5 | E9: 48U ODF WITH SPLICE CA | F9: 3298.43 | G9: =F9*H9 -> 946649.41 | H9: =SUM(N9:Y9) -> 287 | I9: =ROUNDUP(H9/12,0) -> 24 | J9: =K9*F9 -> 0 | K9: =SUM(Z9:AD9) -> 0 | L9: =ROUNDUP(K9/5,0) -> 0 | M9: 0 | N9: 0 | O9: 0 | P9: 28 | Q9: 28 | R9: 35 | S9: 28 | T9: 35 | U9: 28 | V9: 28 | W9: 35 | X9: 28 | Y9: 14 | Z9: 0 | AA9: 0 | AB9: 0 | AC9: 0 | AD9: 0 | AF9: 0 | AG9: 0 | AH9: 0 | AI9: 92356.04 | AJ9: 92356.04 | AK9: 115445.05 | AL9: 92356.04 | AM9: 115445.05 | AN9: 92356.04 | AO9: 92356.04 | AP9: 115445.05 | AQ9: 92356.04 | AR9: 46178.02 | AS9: 0 | AT9: 0 | AU9: 0 | AV9: 0 | AW9: 0 | AX9: X | AY9: X | AZ9: X | BF9: X | BH9: X | BK9: X | BN9: X | BP9: X | BU9: X | BV9: X | BX9: X | CB9: X | CH9: X | DP9: =COUNTIF(AX9:DO9,"x") -> 13
A10: MX | B10: AFL | C10: AFL HYPER | D10: HCF-48U-SPL-001;6 | E10: 48U ODF - SIDE PANEL K | F10: 640.07 | G10: =F10*H10 -> 312994.23 | H10: =SUM(N10:Y10) -> 489 | I10: =ROUNDUP(H10/12,0) -> 41 | J10: =K10*F10 -> 179219.6 | K10: =SUM(Z10:AD10) -> 280 | L10: =ROUNDUP(K10/5,0) -> 56 | M10: 8 | N10: 5 | O10: 0 | P10: 60 | Q10: 80 | R10: 80 | S10: 64 | T10: 60 | U10: 40 | V10: 40 | W10: 0 | X10: 0 | Y10: 60 | Z10: 80 | AA10: 60 | AB10: 60 | AC10: 40 | AD10: 40 | AF10: 5120.56 | AG10: 3200.35 | AH10: 0 | AI10: 38404.2 | AJ10: 51205.6 | AK10: 51205.6 | AL10: 40964.48 | AM10: 38404.2 | AN10: 25602.8 | AO10: 25602.8 | AP10: 0 | AQ10: 0 | AR10: 38404.2 | AS10: 51205.6 | AT10: 38404.2 | AU10: 38404.2 | AV10: 25602.8 | AW10: 25602.8 | AY10: X | AZ10: X | BH10: X | BK10: X | BN10: X | BU10: X | BV10: X | CB10: X | CH10: X | DP10: =COUNTIF(AX10:DO10,"x") -> 9
A11: MX | B11: AFL | C11: AFL-TMX | D11: OCM-12;4 | E11: OCM-12 BRACKET KIT WIT | F11: 18.5 | G11: =F11*H11 -> 0 | H11: =SUM(N11:Y11) -> 0 | I11: =ROUNDUP(H11/12,0) -> 0 | J11: =K11*F11 -> 0 | K11: =SUM(Z11:AD11) -> 0 | L11: =ROUNDUP(K11/5,0) -> 0 | M11: 0 | N11: 0 | O11: 0 | P11: 0 | Q11: 0 | R11: 0 | S11: 0 | T11: 0 | U11: 0 | V11: 0 | W11: 0 | X11: 0 | Y11: 0 | Z11: 0 | AA11: 0 | AB11: 0 | AC11: 0 | AD11: 0 | AF11: 0 | AG11: 0 | AH11: 0 | AI11: 0 | AJ11: 0 | AK11: 0 | AL11: 0 | AM11: 0 | AN11: 0 | AO11: 0 | AP11: 0 | AQ11: 0 | AR11: 0 | AS11: 0 | AT11: 0 | AU11: 0 | AV11: 0 | AW11: 0 | CI11: 19
A12: MX | B12: AFL | C12: ASCEND | D12: ASCND-1RU-12RT;23 | E12: 1RU BASE 12 RT ASCEND | F12: 255.84 | G12: =F12*H12 -> 174482.88 | H12: =SUM(N12:Y12) -> 682 | I12: =ROUNDUP(H12/12,0) -> 57 | J12: =K12*F12 -> 326451.84 | K12: =SUM(Z12:AD12) -> 1276 | L12: =ROUNDUP(K12/5,0) -> 256 | M12: 200 | N12: 100 | O12: 0 | P12: 50 | Q12: 100 | R12: 0 | S12: 0 | T12: 100 | U12: 0 | V12: 0 | W12: 0 | X12: 100 | Y12: 232 | Z12: 290 | AA12: 232 | AB12: 232 | AC12: 290 | AD12: 232 | AF12: 51168 | AG12: 25584 | AH12: 0 | AI12: 12792 | AJ12: 25584 | AK12: 0 | AL12: 0 | AM12: 25584 | AN12: 0 | AO12: 0 | AP12: 0 | AQ12: 25584 | AR12: 59354.88 | AS12: 74193.6 | AT12: 59354.88 | AU12: 59354.88 | AV12: 74193.6 | AW12: 59354.88 | AY12: X | BB12: X | BC12: X | BH12: X | BJ12: X | BK12: X | BN12: X | BU12: X | BV12: X | BX12: X | CG12: X | CH12: X | DP12: =COUNTIF(AX12:DO12,"x") -> 12
A13: MX | B13: AFL | C13: Ascend | D13: ASCND-1RU-8RT;23 | E13: 1RU-8RT ASCEND ASSY | F13: 269.11 | G13: =F13*H13 -> 309476.5 | H13: =SUM(N13:Y13) -> 1150 | I13: =ROUNDUP(H13/12,0) -> 96 | J13: =K13*F13 -> 0 | K13: =SUM(Z13:AD13) -> 0 | L13: =ROUNDUP(K13/5,0) -> 0 | M13: 0 | N13: 0 | O13: 0 | P13: 100 | Q13: 100 | R13: 200 | S13: 300 | T13: 0 | U13: 150 | V13: 100 | W13: 0 | X13: 200 | Y13: 0 | Z13: 0 | AA13: 0 | AB13: 0 | AC13: 0 | AD13: 0 | AF13: 0 | AG13: 0 | AH13: 0 | AI13: 26911 | AJ13: 26911 | AK13: 53822 | AL13: 80733 | AM13: 0 | AN13: 40366.5 | AO13: 26911 | AP13: 0 | AQ13: 53822 | AR13: 0 | AS13: 0 | AT13: 0 | AU13: 0 | AV13: 0 | AW13: 0 | BC13: X | BH13: X | CG13: X | CH13: X | DP13: =COUNTIF(AX13:DO13,"x") -> 4
A14: MX | B14: AFL | C14: ASCEND | D14: ASCND-2RU-12RT;23 | E14: 2RU BASE 12 RAMP ASCEN | F14: 285.58 | G14: =F14*H14 -> 799624 | H14: =SUM(N14:Y14) -> 2800 | I14: =ROUNDUP(H14/12,0) -> 234 | J14: =K14*F14 -> 628276 | K14: =SUM(Z14:AD14) -> 2200 | L14: =ROUNDUP(K14/5,0) -> 440 | M14: 0 | N14: 400 | O14: 0 | P14: 400 | Q14: 200 | R14: 100 | S14: 0 | T14: 200 | U14: 0 | V14: 200 | W14: 500 | X14: 400 | Y14: 400 | Z14: 500 | AA14: 400 | AB14: 400 | AC14: 500 | AD14: 400 | AF14: 0 | AG14: 114232 | AH14: 0 | AI14: 114232 | AJ14: 57116 | AK14: 28558 | AL14: 0 | AM14: 57116 | AN14: 0 | AO14: 57116 | AP14: 142790 | AQ14: 114232 | AR14: 114232 | AS14: 142790 | AT14: 114232 | AU14: 114232 | AV14: 142790 | AW14: 114232 | AY14: X | BH14: X | BJ14: X | BK14: X | BU14: X | BV14: X | BX14: X | CG14: X | CH14: X | DP14: =COUNTIF(AX14:DO14,"x") -> 9
A15: MX | B15: AFL | C15: ASCEND | D15: ASCND-2RU-24RT;23 | E15: 2RU BASE 24 RAMP ASCEN | F15: 350 | G15: =F15*H15 -> 0 | H15: =SUM(N15:Y15) -> 0 | I15: =ROUNDUP(H15/12,0) -> 0 | J15: =K15*F15 -> 0 | K15: =SUM(Z15:AD15) -> 0 | L15: =ROUNDUP(K15/5,0) -> 0 | M15: 0 | N15: 0 | O15: 0 | P15: 0 | Q15: 0 | R15: 0 | S15: 0 | T15: 0 | U15: 0 | V15: 0 | W15: 0 | X15: 0 | Y15: 0 | Z15: 0 | AA15: 0 | AB15: 0 | AC15: 0 | AD15: 0 | AF15: 0 | AG15: 0 | AH15: 0 | AI15: 0 | AJ15: 0 | AK15: 0 | AL15: 0 | AM15: 0 | AN15: 0 | AO15: 0 | AP15: 0 | AQ15: 0 | AR15: 0 | AS15: 0 | AT15: 0 | AU15: 0 | AV15: 0 | AW15: 0 | CI15: 12
A16: MX | B16: AFL | C16: ASCEND | D16: ASCND-2RU-8RT;23 | E16: 2RU BASE 8 RAMP ASCEND | F16: 348.86 | G16: =F16*H16 -> 453518 | H16: =SUM(N16:Y16) -> 1300 | I16: =ROUNDUP(H16/12,0) -> 109 | J16: =K16*F16 -> 34886 | K16: =SUM(Z16:AD16) -> 100 | L16: =ROUNDUP(K16/5,0) -> 20 | M16: 0 | N16: 0 | O16: 0 | P16: 100 | Q16: 200 | R16: 250 | S16: 200 | T16: 0 | U16: 250 | V16: 200 | W16: 100 | X16: 0 | Y16: 0 | Z16: 100 | AA16: 0 | AB16: 0 | AC16: 0 | AD16: 0 | AF16: 0 | AG16: 0 | AH16: 0 | AI16: 34886 | AJ16: 69772 | AK16: 87215 | AL16: 69772 | AM16: 0 | AN16: 87215 | AO16: 69772 | AP16: 34886 | AQ16: 0 | AR16: 0 | AS16: 34886 | AT16: 0 | AU16: 0 | AV16: 0 | AW16: 0 | CG16: X | DP16: =COUNTIF(AX16:DO16,"x") -> 1
A17: MX | B17: AFL | C17: Ascend | D17: ASCND-4RU-12RT;23 | E17: 4RU-12RT ASCEND ASSY | F17: 471.95 | G17: =F17*H17 -> 1461157.2 | H17: =SUM(N17:Y17) -> 3096 | I17: =ROUNDUP(H17/12,0) -> 258 | J17: =K17*F17 -> 1040177.8 | K17: =SUM(Z17:AD17) -> 2204 | L17: =ROUNDUP(K17/5,0) -> 441 | M17: 150 | N17: 350 | O17: 0 | P17: 0 | Q17: 200 | R17: 250 | S17: 100 | T17: 300 | U17: 200 | V17: 448 | W17: 400 | X17: 400 | Y17: 448 | Z17: 300 | AA17: 448 | AB17: 448 | AC17: 560 | AD17: 448 | AF17: 65340 | AG17: 159182.5 | AH17: 0 | AI17: 0 | AJ17: 94390 | AK17: 117987.5 | AL17: 47195 | AM17: 141585 | AN17: 94390 | AO17: 211433.6 | AP17: 188780 | AQ17: 188780 | AR17: 211433.6 | AS17: 141585 | AT17: 211433.6 | AU17: 211433.6 | AV17: 264292 | AW17: 211433.6 | AY17: X | BH17: X | BK17: X | BN17: X | BU17: X | BV17: X | BX17: X | CG17: X | CH17: X | DP17: =COUNTIF(AX17:DO17,"x") -> 9
A18: MX | B18: AFL | C18: Ascend | D18: ASCND-4RU-8RT;23 | E18: 4RU-8RT ASCEND ASSY | F18: 468.32 | G18: =F18*H18 -> 187328 | H18: =SUM(N18:Y18) -> 400 | I18: =ROUNDUP(H18/12,0) -> 34 | J18: =K18*F18 -> 93664 | K18: =SUM(Z18:AD18) -> 200 | L18: =ROUNDUP(K18/5,0) -> 40 | M18: 200 | N18: 0 | O18: 0 | P18: 200 | Q18: 0 | R18: 0 | S18: 100 | T18: 0 | U18: 0 | V18: 0 | W18: 100 | X18: 0 | Y18: 0 | Z18: 0 | AA18: 200 | AB18: 0 | AC18: 0 | AD18: 0 | AF18: 93664 | AG18: 0 | AH18: 0 | AI18: 93664 | AJ18: 0 | AK18: 0 | AL18: 46832 | AM18: 0 | AN18: 0 | AO18: 0 | AP18: 46832 | AQ18: 0 | AR18: 0 | AS18: 0 | AT18: 93664 | AU18: 0 | AV18: 0 | AW18: 0 | CG18: X | CH18: X | DP18: =COUNTIF(AX18:DO18,"x") -> 2
A19: MX | B19: AFL | C19: ASCEND | D19: CS017324;0 | E19: FRONT DOOR MAGNET PAIR | F19: 5.99 | G19: =F19*H19 -> 0 | H19: =SUM(N19:Y19) -> 0 | I19: =ROUNDUP(H19/12,0) -> 0 | J19: =K19*F19 -> 0 | K19: =SUM(Z19:AD19) -> 0 | L19: =ROUNDUP(K19/5,0) -> 0 | M19: 0 | N19: 0 | O19: 0 | P19: 0 | Q19: 0 | R19: 0 | S19: 0 | T19: 0 | U19: 0 | V19: 0 | W19: 0 | X19: 0 | Y19: 0 | Z19: 0 | AA19: 0 | AB19: 0 | AC19: 0 | AD19: 0 | AF19: 0 | AG19: 0 | AH19: 0 | AI19: 0 | AJ19: 0 | AK19: 0 | AL19: 0 | AM19: 0 | AN19: 0 | AO19: 0 | AP19: 0 | AQ19: 0 | AR19: 0 | AS19: 0 | AT19: 0 | AU19: 0 | AV19: 0 | AW19: 0 | CI19: 200
A20: MX | B20: AFL | C20: Ascend | D20: FM003957;7 | E20: 1RU DOOR (REAR) | F20: 1.82 | G20: =F20*H20 -> 0 | H20: =SUM(N20:Y20) -> 0 | I20: =ROUNDUP(H20/12,0) -> 0 | J20: =K20*F20 -> 0 | K20: =SUM(Z20:AD20) -> 0 | L20: =ROUNDUP(K20/5,0) -> 0 | M20: 0 | N20: 0 | O20: 0 | P20: 0 | Q20: 0 | R20: 0 | S20: 0 | T20: 0 | U20: 0 | V20: 0 | W20: 0 | X20: 0 | Y20: 0 | Z20: 0 | AA20: 0 | AB20: 0 | AC20: 0 | AD20: 0 | AF20: 0 | AG20: 0 | AH20: 0 | AI20: 0 | AJ20: 0 | AK20: 0 | AL20: 0 | AM20: 0 | AN20: 0 | AO20: 0 | AP20: 0 | AQ20: 0 | AR20: 0 | AS20: 0 | AT20: 0 | AU20: 0 | AV20: 0 | AW20: 0 | CI20: #N/A
A21: MX | B21: AFL | C21: ASCND 2RU | D21: FM004574;0 | E21: 2RU 23" MOUNTING BRACK | F21: 5.87 | G21: =F21*H21 -> 0 | H21: =SUM(N21:Y21) -> 0 | I21: =ROUNDUP(H21/12,0) -> 0 | J21: =K21*F21 -> 0 | K21: =SUM(Z21:AD21) -> 0 | L21: =ROUNDUP(K21/5,0) -> 0 | M21: 0 | N21: 0 | O21: 0 | P21: 0 | Q21: 0 | R21: 0 | S21: 0 | T21: 0 | U21: 0 | V21: 0 | W21: 0 | X21: 0 | Y21: 0 | Z21: 0 | AA21: 0 | AB21: 0 | AC21: 0 | AD21: 0 | AF21: 0 | AG21: 0 | AH21: 0 | AI21: 0 | AJ21: 0 | AK21: 0 | AL21: 0 | AM21: 0 | AN21: 0 | AO21: 0 | AP21: 0 | AQ21: 0 | AR21: 0 | AS21: 0 | AT21: 0 | AU21: 0 | AV21: 0 | AW21: 0 | CI21: #N/A
A22: MX | B22: AFL | C22: EDC 864 | D22: EA000458;5 | E22: PANEL, LEFT IDEAA MODU | F22: 79.11 | G22: =F22*H22 -> 0 | H22: =SUM(N22:Y22) -> 0 | I22: =ROUNDUP(H22/12,0) -> 0 | J22: =K22*F22 -> 0 | K22: =SUM(Z22:AD22) -> 0 | L22: =ROUNDUP(K22/5,0) -> 0 | M22: 0 | N22: 0 | O22: 0 | P22: 0 | Q22: 0 | R22: 0 | S22: 0 | T22: 0 | U22: 0 | V22: 0 | W22: 0 | X22: 0 | Y22: 0 | Z22: 0 | AA22: 0 | AB22: 0 | AC22: 0 | AD22: 0 | AF22: 0 | AG22: 0 | AH22: 0 | AI22: 0 | AJ22: 0 | AK22: 0 | AL22: 0 | AM22: 0 | AN22: 0 | AO22: 0 | AP22: 0 | AQ22: 0 | AR22: 0 | AS22: 0 | AT22: 0 | AU22: 0 | AV22: 0 | AW22: 0 | CI22: 100
A23: MX | B23: AFL | C23: EDC 864 | D23: EA000549;5 | E23: PANEL, RIGHT IDEAA MOD | F23: 89.36 | G23: =F23*H23 -> 0 | H23: =SUM(N23:Y23) -> 0 | I23: =ROUNDUP(H23/12,0) -> 0 | J23: =K23*F23 -> 0 | K23: =SUM(Z23:AD23) -> 0 | L23: =ROUNDUP(K23/5,0) -> 0 | M23: 0 | N23: 0 | O23: 0 | P23: 0 | Q23: 0 | R23: 0 | S23: 0 | T23: 0 | U23: 0 | V23: 0 | W23: 0 | X23: 0 | Y23: 0 | Z23: 0 | AA23: 0 | AB23: 0 | AC23: 0 | AD23: 0 | AF23: 0 | AG23: 0 | AH23: 0 | AI23: 0 | AJ23: 0 | AK23: 0 | AL23: 0 | AM23: 0 | AN23: 0 | AO23: 0 | AP23: 0 | AQ23: 0 | AR23: 0 | AS23: 0 | AT23: 0 | AU23: 0 | AV23: 0 | AW23: 0 | CI23: 100
A24: MX | B24: AFL | C24: HYPERSCALE | D24: HCF-48U-ODF002;11 | E24: 48U FRAME ASSEMBLY | F24: 2814.12 | G24: =F24*H24 -> 396790.92 | H24: =SUM(N24:Y24) -> 141 | I24: =ROUNDUP(H24/12,0) -> 12 | J24: =K24*F24 -> 0 | K24: =SUM(Z24:AD24) -> 0 | L24: =ROUNDUP(K24/5,0) -> 0 | M24: 46 | N24: 69 | O24: 20 | P24: 52 | Q24: 0 | R24: 0 | S24: 0 | T24: 0 | U24: 0 | V24: 0 | W24: 0 | X24: 0 | Y24: 0 | Z24: 0 | AA24: 0 | AB24: 0 | AC24: 0 | AD24: 0 | AF24: 129449.52 | AG24: 194174.28 | AH24: 56282.4 | AI24: 146334.24 | AJ24: 0 | AK24: 0 | AL24: 0 | AM24: 0 | AN24: 0 | AO24: 0 | AP24: 0 | AQ24: 0 | AR24: 0 | AS24: 0 | AT24: 0 | AU24: 0 | AV24: 0 | AW24: 0 | CB24: X | CH24: X | DP24: =COUNTIF(AX24:DO24,"x") -> 2
A25: MX | B25: AFL | C25: HYPERSCALE | D25: HCF-48U-ODF-004;4 | E25: 48U FRAME ASSEMBLY | F25: 0 | G25: =F25*H25 -> 0 | H25: =SUM(N25:Y25) -> 1 | I25: =ROUNDUP(H25/12,0) -> 1 | J25: =K25*F25 -> 0 | K25: =SUM(Z25:AD25) -> 0 | L25: =ROUNDUP(K25/5,0) -> 0 | M25: 0 | N25: 1 | O25: 0 | P25: 0 | Q25: 0 | R25: 0 | S25: 0 | T25: 0 | U25: 0 | V25: 0 | W25: 0 | X25: 0 | Y25: 0 | Z25: 0 | AA25: 0 | AB25: 0 | AC25: 0 | AD25: 0 | AF25: 0 | AG25: 3210.04 | AH25: 0 | AI25: 0 | AJ25: 0 | AK25: 0 | AL25: 0 | AM25: 0 | AN25: 0 | AO25: 0 | AP25: 0 | AQ25: 0 | AR25: 0 | AS25: 0 | AT25: 0 | AU25: 0 | AV25: 0 | AW25: 0 | AX25: X | AY25: X | AZ25: X | BH25: X | BJ25: X | BK25: X | BP25: X | BU25: X | BV25: X | BX25: X | CB25: X | CH25: X | DP25: =COUNTIF(AX25:DO25,"x") -> 12
A26: MX | B26: AFL | C26: LL-550 | D26: FM004072;3 | E26: SKIRT KIT, LL-550, TEL | F26: 55.1 | G26: =F26*H26 -> 0 | H26: =SUM(N26:Y26) -> 0 | I26: =ROUNDUP(H26/12,0) -> 0 | J26: =K26*F26 -> 0 | K26: =SUM(Z26:AD26) -> 0 | L26: =ROUNDUP(K26/5,0) -> 0 | M26: 0 | N26: 0 | O26: 0 | P26: 0 | Q26: 0 | R26: 0 | S26: 0 | T26: 0 | U26: 0 | V26: 0 | W26: 0 | X26: 0 | Y26: 0 | Z26: 0 | AA26: 0 | AB26: 0 | AC26: 0 | AD26: 0 | AF26: 0 | AG26: 0 | AH26: 0 | AI26: 0 | AJ26: 0 | AK26: 0 | AL26: 0 | AM26: 0 | AN26: 0 | AO26: 0 | AP26: 0 | AQ26: 0 | AR26: 0 | AS26: 0 | AT26: 0 | AU26: 0 | AV26: 0 | AW26: 0 | CI26: 60
A27: MX | B27: AFL | C27: LL-550 | D27: FM004264;0 | E27: LL-550-AT, PLATE, BLAN | F27: 6.02 | G27: =F27*H27 -> 0 | H27: =SUM(N27:Y27) -> 0 | I27: =ROUNDUP(H27/12,0) -> 0 | J27: =K27*F27 -> 0 | K27: =SUM(Z27:AD27) -> 0 | L27: =ROUNDUP(K27/5,0) -> 0 | M27: 0 | N27: 0 | O27: 0 | P27: 0 | Q27: 0 | R27: 0 | S27: 0 | T27: 0 | U27: 0 | V27: 0 | W27: 0 | X27: 0 | Y27: 0 | Z27: 0 | AA27: 0 | AB27: 0 | AC27: 0 | AD27: 0 | AF27: 0 | AG27: 0 | AH27: 0 | AI27: 0 | AJ27: 0 | AK27: 0 | AL27: 0 | AM27: 0 | AN27: 0 | AO27: 0 | AP27: 0 | AQ27: 0 | AR27: 0 | AS27: 0 | AT27: 0 | AU27: 0 | AV27: 0 | AW27: 0 | CI27: 100
A28: MX | B28: AFL | C28: LL-580 | D28: FM004211;0 | E28: LL-580 SKIRT STANDOFF | F28: 7.37 | G28: =F28*H28 -> 0 | H28: =SUM(N28:Y28) -> 0 | I28: =ROUNDUP(H28/12,0) -> 0 | J28: =K28*F28 -> 0 | K28: =SUM(Z28:AD28) -> 0 | L28: =ROUNDUP(K28/5,0) -> 0 | M28: 0 | N28: 0 | O28: 0 | P28: 0 | Q28: 0 | R28: 0 | S28: 0 | T28: 0 | U28: 0 | V28: 0 | W28: 0 | X28: 0 | Y28: 0 | Z28: 0 | AA28: 0 | AB28: 0 | AC28: 0 | AD28: 0 | AF28: 0 | AG28: 0 | AH28: 0 | AI28: 0 | AJ28: 0 | AK28: 0 | AL28: 0 | AM28: 0 | AN28: 0 | AO28: 0 | AP28: 0 | AQ28: 0 | AR28: 0 | AS28: 0 | AT28: 0 | AU28: 0 | AV28: 0 | AW28: 0 | CI28: 100
A29: MX | B29: AFL | C29: LL-580 | D29: FM004240;0 | E29: LL-580 SKIRT STANDOFF | F29: 7.09 | G29: =F29*H29 -> 0 | H29: =SUM(N29:Y29) -> 0 | I29: =ROUNDUP(H29/12,0) -> 0 | J29: =K29*F29 -> 0 | K29: =SUM(Z29:AD29) -> 0 | L29: =ROUNDUP(K29/5,0) -> 0 | M29: 0 | N29: 0 | O29: 0 | P29: 0 | Q29: 0 | R29: 0 | S29: 0 | T29: 0 | U29: 0 | V29: 0 | W29: 0 | X29: 0 | Y29: 0 | Z29: 0 | AA29: 0 | AB29: 0 | AC29: 0 | AD29: 0 | AF29: 0 | AG29: 0 | AH29: 0 | AI29: 0 | AJ29: 0 | AK29: 0 | AL29: 0 | AM29: 0 | AN29: 0 | AO29: 0 | AP29: 0 | AQ29: 0 | AR29: 0 | AS29: 0 | AT29: 0 | AU29: 0 | AV29: 0 | AW29: 0 | CI29: 100
A30: MX | B30: AFL | C30: LL-580-AT | D30: FM002895;9 | E30: LL-580-AT SKIRT | F30: 90.56 | G30: =F30*H30 -> 0 | H30: =SUM(N30:Y30) -> 0 | I30: =ROUNDUP(H30/12,0) -> 0 | J30: =K30*F30 -> 0 | K30: =SUM(Z30:AD30) -> 0 | L30: =ROUNDUP(K30/5,0) -> 0 | M30: 0 | N30: 0 | O30: 0 | P30: 0 | Q30: 0 | R30: 0 | S30: 0 | T30: 0 | U30: 0 | V30: 0 | W30: 0 | X30: 0 | Y30: 0 | Z30: 0 | AA30: 0 | AB30: 0 | AC30: 0 | AD30: 0 | AF30: 0 | AG30: 0 | AH30: 0 | AI30: 0 | AJ30: 0 | AK30: 0 | AL30: 0 | AM30: 0 | AN30: 0 | AO30: 0 | AP30: 0 | AQ30: 0 | AR30: 0 | AS30: 0 | AT30: 0 | AU30: 0 | AV30: 0 | AW30: 0 | CI30: 60
A31: MX | B31: AFL | C31: LL-580-AT | D31: FM002895-3;5 | E31: KO PLATE FOR 2", 1.5" | F31: 7.19 | G31: =F31*H31 -> 0 | H31: =SUM(N31:Y31) -> 0 | I31: =ROUNDUP(H31/12,0) -> 0 | J31: =K31*F31 -> 0 | K31: =SUM(Z31:AD31) -> 0 | L31: =ROUNDUP(K31/5,0) -> 0 | M31: 0 | N31: 0 | O31: 0 | P31: 0 | Q31: 0 | R31: 0 | S31: 0 | T31: 0 | U31: 0 | V31: 0 | W31: 0 | X31: 0 | Y31: 0 | Z31: 0 | AA31: 0 | AB31: 0 | AC31: 0 | AD31: 0 | AF31: 0 | AG31: 0 | AH31: 0 | AI31: 0 | AJ31: 0 | AK31: 0 | AL31: 0 | AM31: 0 | AN31: 0 | AO31: 0 | AP31: 0 | AQ31: 0 | AR31: 0 | AS31: 0 | AT31: 0 | AU31: 0 | AV31: 0 | AW31: 0 | CI31: #N/A
A32: MX | B32: AMAT | C32: AMAT | D32: 0022-13130;04 | E32: BRACKET H2 SENSOR C3 | F32: 5.38 | G32: =F32*H32 -> 1059.86 | H32: =SUM(N32:Y32) -> 197 | I32: =ROUNDUP(H32/12,0) -> 17 | J32: =K32*F32 -> 0 | K32: =SUM(Z32:AD32) -> 0 | L32: =ROUNDUP(K32/5,0) -> 0 | M32: 3 | N32: 197 | O32: 0 | P32: 0 | Q32: 0 | R32: 0 | S32: 0 | T32: 0 | U32: 0 | V32: 0 | W32: 0 | X32: 0 | Y32: 0 | Z32: 0 | AA32: 0 | AB32: 0 | AC32: 0 | AD32: 0 | AF32: 16.14 | AG32: 1059.86 | AH32: 0 | AI32: 0 | AJ32: 0 | AK32: 0 | AL32: 0 | AM32: 0 | AN32: 0 | AO32: 0 | AP32: 0 | AQ32: 0 | AR32: 0 | AS32: 0 | AT32: 0 | AU32: 0 | AV32: 0 | AW32: 0 | AZ32: X | BH32: X | BK32: X | BU32: X | BV32: X | CG32: X | CH32: X | DP32: =COUNTIF(AX32:DO32,"x") -> 7
A33: MX | B33: AMAT | C33: AMAT | D33: 0010-59216;07 | E33: ASSEMBLY,LOWER DOOR,MI | F33: 721.83 | G33: =F33*H33 -> 2165.49 | H33: =SUM(N33:Y33) -> 3 | I33: =ROUNDUP(H33/12,0) -> 1 | J33: =K33*F33 -> 0 | K33: =SUM(Z33:AD33) -> 0 | L33: =ROUNDUP(K33/5,0) -> 0 | M33: 0 | N33: 3 | O33: 0 | P33: 0 | Q33: 0 | R33: 0 | S33: 0 | T33: 0 | U33: 0 | V33: 0 | W33: 0 | X33: 0 | Y33: 0 | Z33: 0 | AA33: 0 | AB33: 0 | AC33: 0 | AD33: 0 | AF33: 0 | AG33: 2165.49 | AH33: 0 | AI33: 0 | AJ33: 0 | AK33: 0 | AL33: 0 | AM33: 0 | AN33: 0 | AO33: 0 | AP33: 0 | AQ33: 0 | AR33: 0 | AS33: 0 | AT33: 0 | AU33: 0 | AV33: 0 | AW33: 0 | AZ33: X | BH33: X | BJ33: X | BK33: X | BP33: X | BU33: X | BV33: X | CG33: X | CH33: X | DP33: =COUNTIF(AX33:DO33,"x") -> 9
A34: MX | B34: AMAT | C34: AMAT | D34: 0020-63454;002 | E34: BRACKET CATCH CCT/WATL | F34: 65.26 | G34: =F34*H34 -> 0 | H34: =SUM(N34:Y34) -> 0 | I34: =ROUNDUP(H34/12,0) -> 0 | J34: =K34*F34 -> 0 | K34: =SUM(Z34:AD34) -> 0 | L34: =ROUNDUP(K34/5,0) -> 0 | M34: 3 | N34: 0 | O34: 0 | P34: 0 | Q34: 0 | R34: 0 | S34: 0 | T34: 0 | U34: 0 | V34: 0 | W34: 0 | X34: 0 | Y34: 0 | Z34: 0 | AA34: 0 | AB34: 0 | AC34: 0 | AD34: 0 | AF34: 195.78 | AG34: 0 | AH34: 0 | AI34: 0 | AJ34: 0 | AK34: 0 | AL34: 0 | AM34: 0 | AN34: 0 | AO34: 0 | AP34: 0 | AQ34: 0 | AR34: 0 | AS34: 0 | AT34: 0 | AU34: 0 | AV34: 0 | AW34: 0 | CI34: #N/A
A35: MX | B35: AMAT | C35: AMAT | D35: 0020-64627;003 | E35: BRACE, SHIPPING, SIDE, | F35: 82.73 | G35: =F35*H35 -> 0 | H35: =SUM(N35:Y35) -> 0 | I35: =ROUNDUP(H35/12,0) -> 0 | J35: =K35*F35 -> 0 | K35: =SUM(Z35:AD35) -> 0 | L35: =ROUNDUP(K35/5,0) -> 0 | M35: 3 | N35: 0 | O35: 0 | P35: 0 | Q35: 0 | R35: 0 | S35: 0 | T35: 0 | U35: 0 | V35: 0 | W35: 0 | X35: 0 | Y35: 0 | Z35: 0 | AA35: 0 | AB35: 0 | AC35: 0 | AD35: 0 | AF35: 248.19 | AG35: 0 | AH35: 0 | AI35: 0 | AJ35: 0 | AK35: 0 | AL35: 0 | AM35: 0 | AN35: 0 | AO35: 0 | AP35: 0 | AQ35: 0 | AR35: 0 | AS35: 0 | AT35: 0 | AU35: 0 | AV35: 0 | AW35: 0 | CI35: #N/A
A36: MX | B36: AMAT | C36: AMAT | D36: 0021-82164;02 | E36: BRACKET, FI SHIPPING, | F36: 183 | G36: =F36*H36 -> 0 | H36: =SUM(N36:Y36) -> 0 | I36: =ROUNDUP(H36/12,0) -> 0 | J36: =K36*F36 -> 0 | K36: =SUM(Z36:AD36) -> 0 | L36: =ROUNDUP(K36/5,0) -> 0 | M36: 3 | N36: 0 | O36: 0 | P36: 0 | Q36: 0 | R36: 0 | S36: 0 | T36: 0 | U36: 0 | V36: 0 | W36: 0 | X36: 0 | Y36: 0 | Z36: 0 | AA36: 0 | AB36: 0 | AC36: 0 | AD36: 0 | AF36: 549 | AG36: 0 | AH36: 0 | AI36: 0 | AJ36: 0 | AK36: 0 | AL36: 0 | AM36: 0 | AN36: 0 | AO36: 0 | AP36: 0 | AQ36: 0 | AR36: 0 | AS36: 0 | AT36: 0 | AU36: 0 | AV36: 0 | AW36: 0 | CI36: #N/A
A37: MX | B37: AMAT | C37: AMAT | D37: 0021-96687;05 | E37: BRACKET,FRONT SIDE BRA | F37: 120.2 | G37: =F37*H37 -> 360.6 | H37: =SUM(N37:Y37) -> 3 | I37: =ROUNDUP(H37/12,0) -> 1 | J37: =K37*F37 -> 0 | K37: =SUM(Z37:AD37) -> 0 | L37: =ROUNDUP(K37/5,0) -> 0 | M37: 0 | N37: 3 | O37: 0 | P37: 0 | Q37: 0 | R37: 0 | S37: 0 | T37: 0 | U37: 0 | V37: 0 | W37: 0 | X37: 0 | Y37: 0 | Z37: 0 | AA37: 0 | AB37: 0 | AC37: 0 | AD37: 0 | AF37: 0 | AG37: 360.6 | AH37: 0 | AI37: 0 | AJ37: 0 | AK37: 0 | AL37: 0 | AM37: 0 | AN37: 0 | AO37: 0 | AP37: 0 | AQ37: 0 | AR37: 0 | AS37: 0 | AT37: 0 | AU37: 0 | AV37: 0 | AW37: 0 | AZ37: X | BH37: X | BK37: X | BP37: X | BU37: X | BV37: X | CG37: X | CH37: X | DP37: =COUNTIF(AX37:DO37,"x") -> 8
A38: MX | B38: AMAT | C38: AMAT | D38: 0022-08095;06 | E38: BRACKET, BOTTOM SHELF | F38: 85.98 | G38: =F38*H38 -> 0 | H38: =SUM(N38:Y38) -> 0 | I38: =ROUNDUP(H38/12,0) -> 0 | J38: =K38*F38 -> 0 | K38: =SUM(Z38:AD38) -> 0 | L38: =ROUNDUP(K38/5,0) -> 0 | M38: 3 | N38: 0 | O38: 0 | P38: 0 | Q38: 0 | R38: 0 | S38: 0 | T38: 0 | U38: 0 | V38: 0 | W38: 0 | X38: 0 | Y38: 0 | Z38: 0 | AA38: 0 | AB38: 0 | AC38: 0 | AD38: 0 | AF38: 257.94 | AG38: 0 | AH38: 0 | AI38: 0 | AJ38: 0 | AK38: 0 | AL38: 0 | AM38: 0 | AN38: 0 | AO38: 0 | AP38: 0 | AQ38: 0 | AR38: 0 | AS38: 0 | AT38: 0 | AU38: 0 | AV38: 0 | AW38: 0 | CI38: #N/A
A39: MX | B39: AMAT | C39: AMAT | D39: 0040-01983;AD | E39: PANEL, WATER DISTRIBUT | F39: 511.04 | G39: =F39*H39 -> 1533.12 | H39: =SUM(N39:Y39) -> 3 | I39: =ROUNDUP(H39/12,0) -> 1 | J39: =K39*F39 -> 0 | K39: =SUM(Z39:AD39) -> 0 | L39: =ROUNDUP(K39/5,0) -> 0 | M39: 0 | N39: 3 | O39: 0 | P39: 0 | Q39: 0 | R39: 0 | S39: 0 | T39: 0 | U39: 0 | V39: 0 | W39: 0 | X39: 0 | Y39: 0 | Z39: 0 | AA39: 0 | AB39: 0 | AC39: 0 | AD39: 0 | AF39: 0 | AG39: 1533.12 | AH39: 0 | AI39: 0 | AJ39: 0 | AK39: 0 | AL39: 0 | AM39: 0 | AN39: 0 | AO39: 0 | AP39: 0 | AQ39: 0 | AR39: 0 | AS39: 0 | AT39: 0 | AU39: 0 | AV39: 0 | AW39: 0 | AZ39: X | BH39: X | BJ39: X | BK39: X | BP39: X | BU39: X | BV39: X | CG39: X | CH39: X | DP39: =COUNTIF(AX39:DO39,"x") -> 9
A40: MX | B40: AMAT | C40: AMAT | D40: 0040-96763;002 | E40: BRACKET,MOUNT FORELINE | F40: 71.2 | G40: =F40*H40 -> 0 | H40: =SUM(N40:Y40) -> 0 | I40: =ROUNDUP(H40/12,0) -> 0 | J40: =K40*F40 -> 0 | K40: =SUM(Z40:AD40) -> 0 | L40: =ROUNDUP(K40/5,0) -> 0 | M40: 3 | N40: 0 | O40: 0 | P40: 0 | Q40: 0 | R40: 0 | S40: 0 | T40: 0 | U40: 0 | V40: 0 | W40: 0 | X40: 0 | Y40: 0 | Z40: 0 | AA40: 0 | AB40: 0 | AC40: 0 | AD40: 0 | AF40: 213.6 | AG40: 0 | AH40: 0 | AI40: 0 | AJ40: 0 | AK40: 0 | AL40: 0 | AM40: 0 | AN40: 0 | AO40: 0 | AP40: 0 | AQ40: 0 | AR40: 0 | AS40: 0 | AT40: 0 | AU40: 0 | AV40: 0 | AW40: 0 | CI40: #N/A
...

Sheet Pivot
B2: 2024
A3: Row Labels | B3: Sum of Total Revenue | C3: Sum of Total Volume | D3: Sum of Monthly Avg. Volume
A4: AFL | B4: 5042021.1 | C4: 10346 | D4: 866
A5: AMAT | B5: 62537.82 | C5: 945 | D5: 88
A6: AMPH | B6: 0 | C6: 0 | D6: 0
A7: ARIS | B7: 18800676 | C7: 166603 | D7: 13913
A8: FUJI | B8: 9995.94 | C8: 2 | D8: 1
A9: JMA | B9: 0 | C9: 0 | D9: 0
A10: S&C ELECT | B10: 0 | C10: 0 | D10: 0
A11: Grand Total | B11: 23915231 | C11: 177896 | D11: 14868

Sheet PFM NON-SELL
F1: Ensamble días por año | H1: 202 | I1: 2025 | L1: 2023 | M1: 2024 | N1: 2024 | O1: 2024 | P1: 2024 | Q1: 2024 | R1: 2024 | S1: 2024 | T1: 2024 | U1: 2024 | V1: 2024 | W1: 2024 | X1: 2024 | Y1: 2025 | Z1: 2025 | AA1: 2025 | AB1: 2025 | AC1: 2025 | AE1: 2023 | AF1: 2024 | AG1: 2024 | AH1: 2024 | AI1: 2024 | AJ1: 2024 | AK1: 2024 | AL1: 2024 | AM1: 2024 | AN1: 2024 | AO1: 2024 | AP1: 2024 | AQ1: 2024 | AR1: 2025 | AS1: 2025 | AT1: 2025 | AU1: 2025 | AV1: 2025
F2: Fabricación días por año | H2: 307 | AW2: 1 | AX2: 1 | AY2: 1 | AZ2: 1 | BA2: 1 | BB2: 1 | BC2: 1 | BD2: 1 | BE2: 1 | BF2: 1 | BI2: 1 | BJ2: 1 | BK2: 1 | BL2: 1 | BN2: 1 | BO2: 1 | BP2: 1 | BQ2: 1 | BV2: 1 | BX2: 1 | BY2: 1 | BZ2: 1 | CA2: 1 | CB2: 1 | CC2: 1 | CD2: 1 | CE2: 1 | CF2: 1 | CG2: 1 | CH2: 1 | CM2: 1 | CN2: 1 | CP2: 1 | CQ2: 1 | CR2: 1 | CS2: 1 | CT2: 1 | CU2: 1 | CV2: 1 | CW2: 1 | CX2: 1 | CY2: 1 | DO2: =SUM(AW2:DN2) -> 42
AW3: Punzonado | AY3: Corte Laser | AZ3: Estampado | BD3: Rebabeo Manual | BE3: Machueleado | BF3: Externo | BJ3: Maquinado | BK3: Rebabeo Por Vibracion | BL3: Inspeccion | BM3: Estampado Térmico | BN3: Insercion PEM | BO3: Doblado Amada | BR3: Externo | BV3: Lijado (Time saver) | BW3: Rebabeo Por Vibracion | BX3: Insercion PEM | BY3: Soldadura | CD3: Rebabeo Manual | CE3: Inspeccion | CF3: Prep Pintura (Enmascarillado) | CG3: Pintura | CI3: Estampado | CM3: Insercion PEM | CN3: Serigrafía | CO3: Subensamble | CP3: Ensamble Final | CY3: INSPECCION | CZ3: Ensamble Final | DO3: TOTAL PROCESOS (38)
F4: 2024 | AW4: Torreta | AX4: Combo | AZ4: 110 | BA4: 200 | BB4: 250 | BC4: 300 | BO4: BRK | BP4: ATC | BQ4: RG | BY4: Perno | BZ4: MicroAlam | CA4: Punto | CB4: TIG | CC4: Robot | CG4: PNT | CH4: SEMI | CI4: 110 | CJ4: 200 | CK4: 250 | CL4: 300 | CO4: Empty | CP4: Amphenol | CQ4: Arista | CR4: Friedrich | CS4: Hyperscale | CT4: Linecards | CU4: Sanmina | CV4: AFL ASCN | CW4: AFL NO/ASCND | CX4: Otros Ensam | CZ4: 335 - 224 | DA4: 223 - 156 | DB4: 155 - 124 | DC4: 123 - 98 | DD4: 97 - 70 | DE4: 69 - 49 | DF4: 48 - 35 | DG4: 34 - 23 | DH4: 22 - 15 | DI4: 14 - 10 | DJ4: '9 - 6 | DK4: ´5 - 3 | DL4: 2 - 0.25 | DO4: # Procesos | DP4: Total Work Content
A5: Cust. Code | B5: Program | C5: Part Number | D5: Description | E5: Price | F5: Total Revenue | G5: Total Volume | H5: Monthly Avg. Volume | I5: Total Revenue | J5: Total Volume | K5: Monthly Avg. Volume | L5: 12 | M5: 1 | N5: 2 | O5: 3 | P5: 4 | Q5: 5 | R5: 6 | S5: 7 | T5: 8 | U5: 9 | V5: 10 | W5: 11 | X5: 12 | Y5: 1 | Z5: 2 | AA5: 3 | AB5: 4 | AC5: 5 | AD5: x | AE5: 12 | AF5: 1 | AG5: 2 | AH5: 3 | AI5: 4 | AJ5: 5 | AK5: 6 | AL5: 7 | AM5: 8 | AN5: 9 | AO5: 10 | AP5: 11 | AQ5: 12 | AR5: 1 | AS5: 2 | AT5: 3 | AU5: 4 | AV5: 5 | AW5: 3 | AX5: 2 | AY5: 1 | AZ5: 2 | BA5: 1 | BB5: 6 | BC5: 3 | BD5: 1 | BE5: 1 | BF5: Pintura | BG5: Platinado | BH5: Maquinado | BI5: Pasivado | BJ5: 1 | BK5: 1 | BN5: 1 | BO5: 7 | BP5: 1 | BQ5: 3 | BR5: Pintura | BS5: Platinado | BT5: Maquinado | BU5: Pasivado | BV5: 1 | BX5: 1 | BY5: ? | BZ5: ? | CA5: ? | CB5: ? | CC5: ? | CF5: ? | CG5: 1 | CH5: 1 | CN5: 1
A6: AFL | B6: AFL HYPER | C6: HCF-48U-ODF-003;5 | D6: 48U ODF WITH SPLICE CA | E6: 3298.43 | F6: =E6*G6 -> 946649.41 | G6: =SUM(M6:X6) -> 287 | H6: =ROUNDUP(G6/12,0) -> 24 | I6: =J6*E6 -> 0 | J6: =SUM(Y6:AC6) -> 0 | K6: =ROUNDUP(J6/5,0) -> 0 | L6: 0 | M6: 0 | N6: 0 | O6: 28 | P6: 28 | Q6: 35 | R6: 28 | S6: 35 | T6: 28 | U6: 28 | V6: 35 | W6: 28 | X6: 14 | Y6: 0 | Z6: 0 | AA6: 0 | AB6: 0 | AC6: 0 | AE6: 0 | AF6: 0 | AG6: 0 | AH6: 92356.04 | AI6: 92356.04 | AJ6: 115445.05 | AK6: 92356.04 | AL6: 115445.05 | AM6: 92356.04 | AN6: 92356.04 | AO6: 115445.05 | AP6: 92356.04 | AQ6: 46178.02 | AR6: 0 | AS6: 0 | AT6: 0 | AU6: 0 | AV6: 0 | AW6: =IF('PFM NON-SELL (Draft Layers)'!AW6="X","X"," ") -> X | AX6: =IF('PFM NON-SELL (Draft Layers)'!AX6="X","X"," ") -> X | AY6: =IF('PFM NON-SELL (Draft Layers)'!AY6="X","X"," ") -> X | AZ6: =IF('PFM NON-SELL (Draft Layers)'!AZ6="X","X"," ") | BA6: =IF('PFM NON-SELL (Draft Layers)'!BA6="X","X"," ") | BB6: =IF('PFM NON-SELL (Draft Layers)'!BB6="X","X"," ") | BC6: =IF('PFM NON-SELL (Draft Layers)'!BC6="X","X"," ") | BD6: =IF('PFM NON-SELL (Draft Layers)'!BD6="X","X"," ") | ... BK6: =IF('PFM NON-SELL (Draft Layers)'!BK6="X","X"," ") | BL6: =IF('PFM NON-SELL (Draft Layers)'!BM6="X","X"," ") -> X | BM6: =IF('PFM NON-SELL (Draft Layers)'!BN6="X","X"," ") | BN6: =IF('PFM NON-SELL (Draft Layers)'!BO6="X","X"," ") | BO6: =IF('PFM NON-SELL (Draft Layers)'!BP6="X","X"," ") -> X | BP6: =IF('PFM NON-SELL (Draft Layers)'!BQ6="X","X"," ") | BQ6: =IF('PFM NON-SELL (Draft Layers)'!BR6="X","X"," ") -> X | BR6: =IF('PFM NON-SELL (Draft Layers)'!BS6="X","X"," ") -> X | BS6: =IF('PFM NON-SELL (Draft Layers)'!BT6="X","X"," ") -> X | ... BV6: =IF('PFM NON-SELL (Draft Layers)'!BW6="X","X"," ") | BW6: =IF('PFM NON-SELL (Draft Layers)'!BY6="X","X"," ") | BX6: =IF('PFM NON-SELL (Draft Layers)'!BZ6="X","X"," ") -> X | BY6: =IF('PFM NON-SELL (Draft Layers)'!CA6="X","X"," ") | BZ6: =IF('PFM NON-SELL (Draft Layers)'!CB6="X","X"," ") -> X | CA6: =IF('PFM NON-SELL (Draft Layers)'!CC6="X","X"," ") -> X | CB6: =IF('PFM NON-SELL (Draft Layers)'!CD6="X","X"," ") -> X | CC6: =IF('PFM NON-SELL (Draft Layers)'!CE6="X","X"," ") | CD6: =IF('PFM NON-SELL (Draft Layers)'!CF6="X","X"," ") -> X | ... CH6: =IF('PFM NON-SELL (Draft Layers)'!CJ6="X","X"," ") | CI6: =IF('PFM NON-SELL (Draft Layers)'!CN6="X","X"," ") | CJ6: =IF('PFM NON-SELL (Draft Layers)'!CO6="X","X"," ") | CK6: =IF('PFM NON-SELL (Draft Layers)'!CP6="X","X"," ") | CL6: =IF('PFM NON-SELL (Draft Layers)'!CQ6="X","X"," ") | CM6: =IF('PFM NON-SELL (Draft Layers)'!CV6="X","X"," ") | CN6: =IF('PFM NON-SELL (Draft Layers)'!CW6="X","X"," ") -> X | CO6: =IF('PFM NON-SELL (Draft Layers)'!CX6="X","X"," ") | CP6: =IF('PFM NON-SELL (Draft Layers)'!CY6="X","X"," ") | CQ6: =IF('PFM NON-SELL (Draft Layers)'!CZ6="X","X"," ") | CR6: =IF('PFM NON-SELL (Draft Layers)'!DA6="X","X"," ") | CS6: =IF('PFM NON-SELL (Draft Layers)'!DB6="X","X"," ") -> X | CT6: =IF('PFM NON-SELL (Draft Layers)'!DC6="X","X"," ") | ... CY6: =IF('PFM NON-SELL (Draft Layers)'!DH6="X","X"," ") -> X | DO6: =COUNTIF(AW6:DN6,"x") -> 22
A7: AFL | B7: AFL HYPER | C7: HCF-48U-SPL-001;6 | D7: 48U ODF - SIDE PANEL K | E7: 640.07 | F7: =E7*G7 -> 312994.23 | G7: =SUM(M7:X7) -> 489 | H7: =ROUNDUP(G7/12,0) -> 41 | I7: =J7*E7 -> 179219.6 | J7: =SUM(Y7:AC7) -> 280 | K7: =ROUNDUP(J7/5,0) -> 56 | L7: 8 | M7: 5 | N7: 0 | O7: 60 | P7: 80 | Q7: 80 | R7: 64 | S7: 60 | T7: 40 | U7: 40 | V7: 0 | W7: 0 | X7: 60 | Y7: 80 | Z7: 60 | AA7: 60 | AB7: 40 | AC7: 40 | AE7: 5120.56 | AF7: 3200.35 | AG7: 0 | AH7: 38404.2 | AI7: 51205.6 | AJ7: 51205.6 | AK7: 40964.48 | AL7: 38404.2 | AM7: 25602.8 | AN7: 25602.8 | AO7: 0 | AP7: 0 | AQ7: 38404.2 | AR7: 51205.6 | AS7: 38404.2 | AT7: 38404.2 | AU7: 25602.8 | AV7: 25602.8 | AW7: =IF('PFM NON-SELL (Draft Layers)'!AW7="X","X"," ") | AX7: =IF('PFM NON-SELL (Draft Layers)'!AX7="X","X"," ") -> X | AY7: =IF('PFM NON-SELL (Draft Layers)'!AY7="X","X"," ") | AZ7: =IF('PFM NON-SELL (Draft Layers)'!AZ7="X","X"," ") | BA7: =IF('PFM NON-SELL (Draft Layers)'!BA7="X","X"," ") | BB7: =IF('PFM NON-SELL (Draft Layers)'!BB7="X","X"," ") | BC7: =IF('PFM NON-SELL (Draft Layers)'!BC7="X","X"," ") | BD7: =IF('PFM NON-SELL (Draft Layers)'!BD7="X","X"," ") | ... BK7: =IF('PFM NON-SELL (Draft Layers)'!BK7="X","X"," ") | BL7: =IF('PFM NON-SELL (Draft Layers)'!BM7="X","X"," ") | BM7: =IF('PFM NON-SELL (Draft Layers)'!BN7="X","X"," ") | BN7: =IF('PFM NON-SELL (Draft Layers)'!BO7="X","X"," ") | BO7: =IF('PFM NON-SELL (Draft Layers)'!BP7="X","X"," ") -> X | BP7: =IF('PFM NON-SELL (Draft Layers)'!BQ7="X","X"," ") | BQ7: =IF('PFM NON-SELL (Draft Layers)'!BR7="X","X"," ") | BR7: =IF('PFM NON-SELL (Draft Layers)'!BS7="X","X"," ") | BS7: =IF('PFM NON-SELL (Draft Layers)'!BT7="X","X"," ") | ... BV7: =IF('PFM NON-SELL (Draft Layers)'!BW7="X","X"," ") | BW7: =IF('PFM NON-SELL (Draft Layers)'!BY7="X","X"," ") | BX7: =IF('PFM NON-SELL (Draft Layers)'!BZ7="X","X"," ") -> X | BY7: =IF('PFM NON-SELL (Draft Layers)'!CA7="X","X"," ") | BZ7: =IF('PFM NON-SELL (Draft Layers)'!CB7="X","X"," ") | CA7: =IF('PFM NON-SELL (Draft Layers)'!CC7="X","X"," ") | CB7: =IF('PFM NON-SELL (Draft Layers)'!CD7="X","X"," ") | CC7: =IF('PFM NON-SELL (Draft Layers)'!CE7="X","X"," ") | CD7: =IF('PFM NON-SELL (Draft Layers)'!CF7="X","X"," ") | ... CH7: =IF('PFM NON-SELL (Draft Layers)'!CJ7="X","X"," ") | CI7: =IF('PFM NON-SELL (Draft Layers)'!CN7="X","X"," ") | CJ7: =IF('PFM NON-SELL (Draft Layers)'!CO7="X","X"," ") | CK7: =IF('PFM NON-SELL (Draft Layers)'!CP7="X","X"," ") | CL7: =IF('PFM NON-SELL (Draft Layers)'!CQ7="X","X"," ") | CM7: =IF('PFM NON-SELL (Draft Layers)'!CV7="X","X"," ") | CN7: =IF('PFM NON-SELL (Draft Layers)'!CW7="X","X"," ") | CO7: =IF('PFM NON-SELL (Draft Layers)'!CX7="X","X"," ") | CP7: =IF('PFM NON-SELL (Draft Layers)'!CY7="X","X"," ") | CQ7: =IF('PFM NON-SELL (Draft Layers)'!CZ7="X","X"," ") | CR7: =IF('PFM NON-SELL (Draft Layers)'!DA7="X","X"," ") | CS7: =IF('PFM NON-SELL (Draft Layers)'!DB7="X","X"," ") -> X | CT7: =IF('PFM NON-SELL (Draft Layers)'!DC7="X","X"," ") | ... CY7: =IF('PFM NON-SELL (Draft Layers)'!DH7="X","X"," ") -> X | DO7: =COUNTIF(AW7:DN7,"x") -> 8
A8: AFL | B8: ASCEND | C8: ASCND-1RU-12RT;23 | D8: 1RU BASE 12 RT ASCEND | E8: 255.84 | F8: =E8*G8 -> 174482.88 | G8: =SUM(M8:X8) -> 682 | H8: =ROUNDUP(G8/12,0) -> 57 | I8: =J8*E8 -> 326451.84 | J8: =SUM(Y8:AC8) -> 1276 | K8: =ROUNDUP(J8/5,0) -> 256 | L8: 200 | M8: 100 | N8: 0 | O8: 50 | P8: 100 | Q8: 0 | R8: 0 | S8: 100 | T8: 0 | U8: 0 | V8: 0 | W8: 100 | X8: 232 | Y8: 290 | Z8: 232 | AA8: 232 | AB8: 290 | AC8: 232 | AE8: 51168 | AF8: 25584 | AG8: 0 | AH8: 12792 | AI8: 25584 | AJ8: 0 | AK8: 0 | AL8: 25584 | AM8: 0 | AN8: 0 | AO8: 0 | AP8: 25584 | AQ8: 59354.88 | AR8: 74193.6 | AS8: 59354.88 | AT8: 59354.88 | AU8: 74193.6 | AV8: 59354.88 | AW8: =IF('PFM NON-SELL (Draft Layers)'!AW15="X","X"," ") -> X | AX8: =IF('PFM NON-SELL (Draft Layers)'!AX15="X","X"," ") -> X | AY8: =IF('PFM NON-SELL (Draft Layers)'!AY15="X","X"," ") | AZ8: =IF('PFM NON-SELL (Draft Layers)'!AZ15="X","X"," ") | BA8: =IF('PFM NON-SELL (Draft Layers)'!BA15="X","X"," ") -> X | BB8: =IF('PFM NON-SELL (Draft Layers)'!BB15="X","X"," ") -> X | BC8: =IF('PFM NON-SELL (Draft Layers)'!BC15="X","X"," ") | BD8: =IF('PFM NON-SELL (Draft Layers)'!BD15="X","X"," ") | ... BK8: =IF('PFM NON-SELL (Draft Layers)'!BK15="X","X"," ") | BL8: =IF('PFM NON-SELL (Draft Layers)'!BM15="X","X"," ") | BM8: =IF('PFM NON-SELL (Draft Layers)'!BN15="X","X"," ") | BN8: =IF('PFM NON-SELL (Draft Layers)'!BO15="X","X"," ") -> X | BO8: =IF('PFM NON-SELL (Draft Layers)'!BP15="X","X"," ") -> X | BP8: =IF('PFM NON-SELL (Draft Layers)'!BQ15="X","X"," ") | BQ8: =IF('PFM NON-SELL (Draft Layers)'!BR15="X","X"," ") | BR8: =IF('PFM NON-SELL (Draft Layers)'!BS15="X","X"," ") | BS8: =IF('PFM NON-SELL (Draft Layers)'!BT15="X","X"," ") | ... BV8: =IF('PFM NON-SELL (Draft Layers)'!BW15="X","X"," ") | BW8: =IF('PFM NON-SELL (Draft Layers)'!BY15="X","X"," ") | BX8: =IF('PFM NON-SELL (Draft Layers)'!BZ15="X","X"," ") -> X | BY8: =IF('PFM NON-SELL (Draft Layers)'!CA15="X","X"," ") | BZ8: =IF('PFM NON-SELL (Draft Layers)'!CB15="X","X"," ") | CA8: =IF('PFM NON-SELL (Draft Layers)'!CC15="X","X"," ") | CB8: =IF('PFM NON-SELL (Draft Layers)'!CD15="X","X"," ") | CC8: =IF('PFM NON-SELL (Draft Layers)'!CE15="X","X"," ") | CD8: =IF('PFM NON-SELL (Draft Layers)'!CF15="X","X"," ") | ... CH8: =IF('PFM NON-SELL (Draft Layers)'!CJ15="X","X"," ") | CI8: =IF('PFM NON-SELL (Draft Layers)'!CN15="X","X"," ") | CJ8: =IF('PFM NON-SELL (Draft Layers)'!CO15="X","X"," ") | CK8: =IF('PFM NON-SELL (Draft Layers)'!CP15="X","X"," ") | CL8: =IF('PFM NON-SELL (Draft Layers)'!CQ15="X","X"," ") | CM8: =IF('PFM NON-SELL (Draft Layers)'!CV15="X","X"," ") | CN8: =IF('PFM NON-SELL (Draft Layers)'!CW15="X","X"," ") -> X | CO8: =IF('PFM NON-SELL (Draft Layers)'!CX15="X","X"," ") -> X | CP8: =IF('PFM NON-SELL (Draft Layers)'!CY15="X","X"," ") | CQ8: =IF('PFM NON-SELL (Draft Layers)'!CZ15="X","X"," ") | CR8: =IF('PFM NON-SELL (Draft Layers)'!DA15="X","X"," ") | CS8: =IF('PFM NON-SELL (Draft Layers)'!DB15="X","X"," ") | CT8: =IF('PFM NON-SELL (Draft Layers)'!DC15="X","X"," ") | ... CY8: =IF('PFM NON-SELL (Draft Layers)'!DH15="X","X"," ") -> X | DO8: =COUNTIF(AW8:DN8,"x") -> 13
A9: AFL | B9: Ascend | C9: ASCND-1RU-8RT;23 | D9: 1RU-8RT ASCEND ASSY | E9: 269.11 | F9: =E9*G9 -> 309476.5 | G9: =SUM(M9:X9) -> 1150 | H9: =ROUNDUP(G9/12,0) -> 96 | I9: =J9*E9 -> 0 | J9: =SUM(Y9:AC9) -> 0 | K9: =ROUNDUP(J9/5,0) -> 0 | L9: 0 | M9: 0 | N9: 0 | O9: 100 | P9: 100 | Q9: 200 | R9: 300 | S9: 0 | T9: 150 | U9: 100 | V9: 0 | W9: 200 | X9: 0 | Y9: 0 | Z9: 0 | AA9: 0 | AB9: 0 | AC9: 0 | AE9: 0 | AF9: 0 | AG9: 0 | AH9: 26911 | AI9: 26911 | AJ9: 53822 | AK9: 80733 | AL9: 0 | AM9: 40366.5 | AN9: 26911 | AO9: 0 | AP9: 53822 | AQ9: 0 | AR9: 0 | AS9: 0 | AT9: 0 | AU9: 0 | AV9: 0 | AW9: =IF('PFM NON-SELL (Draft Layers)'!AW29="X","X"," ") | AX9: =IF('PFM NON-SELL (Draft Layers)'!AX29="X","X"," ") | AY9: =IF('PFM NON-SELL (Draft Layers)'!AY29="X","X"," ") | AZ9: =IF('PFM NON-SELL (Draft Layers)'!AZ29="X","X"," ") | BA9: =IF('PFM NON-SELL (Draft Layers)'!BA29="X","X"," ") | BB9: =IF('PFM NON-SELL (Draft Layers)'!BB29="X","X"," ") -> X | BC9: =IF('PFM NON-SELL (Draft Layers)'!BC29="X","X"," ") | BD9: =IF('PFM NON-SELL (Draft Layers)'!BD29="X","X"," ") -> X | ... BK9: =IF('PFM NON-SELL (Draft Layers)'!BK29="X","X"," ") | BL9: =IF('PFM NON-SELL (Draft Layers)'!BM29="X","X"," ") -> X | BM9: =IF('PFM NON-SELL (Draft Layers)'!BN29="X","X"," ") -> X | BN9: =IF('PFM NON-SELL (Draft Layers)'!BO29="X","X"," ") | BO9: =IF('PFM NON-SELL (Draft Layers)'!BP29="X","X"," ") | BP9: =IF('PFM NON-SELL (Draft Layers)'!BQ29="X","X"," ") | BQ9: =IF('PFM NON-SELL (Draft Layers)'!BR29="X","X"," ") | BR9: =IF('PFM NON-SELL (Draft Layers)'!BS29="X","X"," ") | BS9: =IF('PFM NON-SELL (Draft Layers)'!BT29="X","X"," ") | ... BV9: =IF('PFM NON-SELL (Draft Layers)'!BW29="X","X"," ") | BW9: =IF('PFM NON-SELL (Draft Layers)'!BY29="X","X"," ") | BX9: =IF('PFM NON-SELL (Draft Layers)'!BZ29="X","X"," ") | BY9: =IF('PFM NON-SELL (Draft Layers)'!CA29="X","X"," ") | BZ9: =IF('PFM NON-SELL (Draft Layers)'!CB29="X","X"," ") | CA9: =IF('PFM NON-SELL (Draft Layers)'!CC29="X","X"," ") | CB9: =IF('PFM NON-SELL (Draft Layers)'!CD29="X","X"," ") | CC9: =IF('PFM NON-SELL (Draft Layers)'!CE29="X","X"," ") | CD9: =IF('PFM NON-SELL (Draft Layers)'!CF29="X","X"," ") | ... CH9: =IF('PFM NON-SELL (Draft Layers)'!CJ29="X","X"," ") | CI9: =IF('PFM NON-SELL (Draft Layers)'!CN29="X","X"," ") | CJ9: =IF('PFM NON-SELL (Draft Layers)'!CO29="X","X"," ") | CK9: =IF('PFM NON-SELL (Draft Layers)'!CP29="X","X"," ") | CL9: =IF('PFM NON-SELL (Draft Layers)'!CQ29="X","X"," ") | CM9: =IF('PFM NON-SELL (Draft Layers)'!CV29="X","X"," ") | CN9: =IF('PFM NON-SELL (Draft Layers)'!CW29="X","X"," ") | CO9: =IF('PFM NON-SELL (Draft Layers)'!CX29="X","X"," ") | CP9: =IF('PFM NON-SELL (Draft Layers)'!CY29="X","X"," ") | CQ9: =IF('PFM NON-SELL (Draft Layers)'!CZ29="X","X"," ") | CR9: =IF('PFM NON-SELL (Draft Layers)'!DA29="X","X"," ") | CS9: =IF('PFM NON-SELL (Draft Layers)'!DB29="X","X"," ") | CT9: =IF('PFM NON-SELL (Draft Layers)'!DC29="X","X"," ") | ... CY9: =IF('PFM NON-SELL (Draft Layers)'!DH29="X","X"," ") -> X | DO9: =COUNTIF(AW9:DN9,"x") -> 7
A10: AFL | B10: ASCEND | C10: ASCND-2RU-12RT;23 | D10: 2RU BASE 12 RAMP ASCEN | E10: 285.58 | F10: =E10*G10 -> 799624 | G10: =SUM(M10:X10) -> 2800 | H10: =ROUNDUP(G10/12,0) -> 234 | I10: =J10*E10 -> 628276 | J10: =SUM(Y10:AC10) -> 2200 | K10: =ROUNDUP(J10/5,0) -> 440 | L10: 0 | M10: 400 | N10: 0 | O10: 400 | P10: 200 | Q10: 100 | R10: 0 | S10: 200 | T10: 0 | U10: 200 | V10: 500 | W10: 400 | X10: 400 | Y10: 500 | Z10: 400 | AA10: 400 | AB10: 500 | AC10: 400 | AE10: 0 | AF10: 114232 | AG10: 0 | AH10: 114232 | AI10: 57116 | AJ10: 28558 | AK10: 0 | AL10: 57116 | AM10: 0 | AN10: 57116 | AO10: 142790 | AP10: 114232 | AQ10: 114232 | AR10: 142790 | AS10: 114232 | AT10: 114232 | AU10: 142790 | AV10: 114232 | AW10: =IF('PFM NON-SELL (Draft Layers)'!AW40="X","X"," ") -> X | AX10: =IF('PFM NON-SELL (Draft Layers)'!AX40="X","X"," ") -> X | AY10: =IF('PFM NON-SELL (Draft Layers)'!AY40="X","X"," ") | AZ10: =IF('PFM NON-SELL (Draft Layers)'!AZ40="X","X"," ") | BA10: =IF('PFM NON-SELL (Draft Layers)'!BA40="X","X"," ") | BB10: =IF('PFM NON-SELL (Draft Layers)'!BB40="X","X"," ") | BC10: =IF('PFM NON-SELL (Draft Layers)'!BC40="X","X"," ") | BD10: =IF('PFM NON-SELL (Draft Layers)'!BD40="X","X"," ") | ... BK10: =IF('PFM NON-SELL (Draft Layers)'!BK40="X","X"," ") | BL10: =IF('PFM NON-SELL (Draft Layers)'!BM40="X","X"," ") | BM10: =IF('PFM NON-SELL (Draft Layers)'!BN40="X","X"," ") | BN10: =IF('PFM NON-SELL (Draft Layers)'!BO40="X","X"," ") -> X | BO10: =IF('PFM NON-SELL (Draft Layers)'!BP40="X","X"," ") -> X | BP10: =IF('PFM NON-SELL (Draft Layers)'!BQ40="X","X"," ") | BQ10: =IF('PFM NON-SELL (Draft Layers)'!BR40="X","X"," ") | BR10: =IF('PFM NON-SELL (Draft Layers)'!BS40="X","X"," ") | BS10: =IF('PFM NON-SELL (Draft Layers)'!BT40="X","X"," ") | ... BV10: =IF('PFM NON-SELL (Draft Layers)'!BW40="X","X"," ") -> X | BW10: =IF('PFM NON-SELL (Draft Layers)'!BY40="X","X"," ") | BX10: =IF('PFM NON-SELL (Draft Layers)'!BZ40="X","X"," ") -> X | BY10: =IF('PFM NON-SELL (Draft Layers)'!CA40="X","X"," ") | BZ10: =IF('PFM NON-SELL (Draft Layers)'!CB40="X","X"," ") | CA10: =IF('PFM NON-SELL (Draft Layers)'!CC40="X","X"," ") | CB10: =IF('PFM NON-SELL (Draft Layers)'!CD40="X","X"," ") | CC10: =IF('PFM NON-SELL (Draft Layers)'!CE40="X","X"," ") | CD10: =IF('PFM NON-SELL (Draft Layers)'!CF40="X","X"," ") -> X | ... CH10: =IF('PFM NON-SELL (Draft Layers)'!CJ40="X","X"," ") | CI10: =IF('PFM NON-SELL (Draft Layers)'!CN40="X","X"," ") | CJ10: =IF('PFM NON-SELL (Draft Layers)'!CO40="X","X"," ") | CK10: =IF('PFM NON-SELL (Draft Layers)'!CP40="X","X"," ") | CL10: =IF('PFM NON-SELL (Draft Layers)'!CQ40="X","X"," ") | CM10: =IF('PFM NON-SELL (Draft Layers)'!CV40="X","X"," ") | CN10: =IF('PFM NON-SELL (Draft Layers)'!CW40="X","X"," ") -> X | CO10: =IF('PFM NON-SELL (Draft Layers)'!CX40="X","X"," ") | CP10: =IF('PFM NON-SELL (Draft Layers)'!CY40="X","X"," ") | CQ10: =IF('PFM NON-SELL (Draft Layers)'!CZ40="X","X"," ") | CR10: =IF('PFM NON-SELL (Draft Layers)'!DA40="X","X"," ") | CS10: =IF('PFM NON-SELL (Draft Layers)'!DB40="X","X"," ") | CT10: =IF('PFM NON-SELL (Draft Layers)'!DC40="X","X"," ") | ... CY10: =IF('PFM NON-SELL (Draft Layers)'!DH40="X","X"," ") -> X | DO10: =COUNTIF(AW10:DN10,"x") -> 12
A11: AFL | B11: ASCEND | C11: ASCND-2RU-8RT;23 | D11: 2RU BASE 8 RAMP ASCEND | E11: 348.86 | F11: =E11*G11 -> 453518 | G11: =SUM(M11:X11) -> 1300 | H11: =ROUNDUP(G11/12,0) -> 109 | I11: =J11*E11 -> 34886 | J11: =SUM(Y11:AC11) -> 100 | K11: =ROUNDUP(J11/5,0) -> 20 | L11: 0 | M11: 0 | N11: 0 | O11: 100 | P11: 200 | Q11: 250 | R11: 200 | S11: 0 | T11: 250 | U11: 200 | V11: 100 | W11: 0 | X11: 0 | Y11: 100 | Z11: 0 | AA11: 0 | AB11: 0 | AC11: 0 | AE11: 0 | AF11: 0 | AG11: 0 | AH11: 34886 | AI11: 69772 | AJ11: 87215 | AK11: 69772 | AL11: 0 | AM11: 87215 | AN11: 69772 | AO11: 34886 | AP11: 0 | AQ11: 0 | AR11: 34886 | AS11: 0 | AT11: 0 | AU11: 0 | AV11: 0 | AW11: =IF('PFM NON-SELL (Draft Layers)'!AW52="X","X"," ") | AX11: =IF('PFM NON-SELL (Draft Layers)'!AX52="X","X"," ") | AY11: =IF('PFM NON-SELL (Draft Layers)'!AY52="X","X"," ") | AZ11: =IF('PFM NON-SELL (Draft Layers)'!AZ52="X","X"," ") | BA11: =IF('PFM NON-SELL (Draft Layers)'!BA52="X","X"," ") | BB11: =IF('PFM NON-SELL (Draft Layers)'!BB52="X","X"," ") -> X | BC11: =IF('PFM NON-SELL (Draft Layers)'!BC52="X","X"," ") | BD11: =IF('PFM NON-SELL (Draft Layers)'!BD52="X","X"," ") -> X | ... BK11: =IF('PFM NON-SELL (Draft Layers)'!BK52="X","X"," ") | BL11: =IF('PFM NON-SELL (Draft Layers)'!BM52="X","X"," ") -> X | BM11: =IF('PFM NON-SELL (Draft Layers)'!BN52="X","X"," ") -> X | BN11: =IF('PFM NON-SELL (Draft Layers)'!BO52="X","X"," ") | BO11: =IF('PFM NON-SELL (Draft Layers)'!BP52="X","X"," ") | BP11: =IF('PFM NON-SELL (Draft Layers)'!BQ52="X","X"," ") | BQ11: =IF('PFM NON-SELL (Draft Layers)'!BR52="X","X"," ") | BR11: =IF('PFM NON-SELL (Draft Layers)'!BS52="X","X"," ") | BS11: =IF('PFM NON-SELL (Draft Layers)'!BT52="X","X"," ") | ... BV11: =IF('PFM NON-SELL (Draft Layers)'!BW52="X","X"," ") | BW11: =IF('PFM NON-SELL (Draft Layers)'!BY52="X","X"," ") | BX11: =IF('PFM NON-SELL (Draft Layers)'!BZ52="X","X"," ") | BY11: =IF('PFM NON-SELL (Draft Layers)'!CA52="X","X"," ") | BZ11: =IF('PFM NON-SELL (Draft Layers)'!CB52="X","X"," ") | CA11: =IF('PFM NON-SELL (Draft Layers)'!CC52="X","X"," ") | CB11: =IF('PFM NON-SELL (Draft Layers)'!CD52="X","X"," ") | CC11: =IF('PFM NON-SELL (Draft Layers)'!CE52="X","X"," ") | CD11: =IF('PFM NON-SELL (Draft Layers)'!CF52="X","X"," ") | ... CH11: =IF('PFM NON-SELL (Draft Layers)'!CJ52="X","X"," ") | CI11: =IF('PFM NON-SELL (Draft Layers)'!CN52="X","X"," ") | CJ11: =IF('PFM NON-SELL (Draft Layers)'!CO52="X","X"," ") | CK11: =IF('PFM NON-SELL (Draft Layers)'!CP52="X","X"," ") | CL11: =IF('PFM NON-SELL (Draft Layers)'!CQ52="X","X"," ") | CM11: =IF('PFM NON-SELL (Draft Layers)'!CV52="X","X"," ") | CN11: =IF('PFM NON-SELL (Draft Layers)'!CW52="X","X"," ") -> X | CO11: =IF('PFM NON-SELL (Draft Layers)'!CX52="X","X"," ") | CP11: =IF('PFM NON-SELL (Draft Layers)'!CY52="X","X"," ") | CQ11: =IF('PFM NON-SELL (Draft Layers)'!CZ52="X","X"," ") | CR11: =IF('PFM NON-SELL (Draft Layers)'!DA52="X","X"," ") | CS11: =IF('PFM NON-SELL (Draft Layers)'!DB52="X","X"," ") | CT11: =IF('PFM NON-SELL (Draft Layers)'!DC52="X","X"," ") | ... CY11: =IF('PFM NON-SELL (Draft Layers)'!DH52="X","X"," ") | DO11: =COUNTIF(AW11:DN11,"x") -> 7
A12: AFL | B12: Ascend | C12: ASCND-4RU-12RT;23 | D12: 4RU-12RT ASCEND ASSY | E12: 471.95 | F12: =E12*G12 -> 1461157.2 | G12: =SUM(M12:X12) -> 3096 | H12: =ROUNDUP(G12/12,0) -> 258 | I12: =J12*E12 -> 1040177.8 | J12: =SUM(Y12:AC12) -> 2204 | K12: =ROUNDUP(J12/5,0) -> 441 | L12: 150 | M12: 350 | N12: 0 | O12: 0 | P12: 200 | Q12: 250 | R12: 100 | S12: 300 | T12: 200 | U12: 448 | V12: 400 | W12: 400 | X12: 448 | Y12: 300 | Z12: 448 | AA12: 448 | AB12: 560 | AC12: 448 | AE12: 65340 | AF12: 159182.5 | AG12: 0 | AH12: 0 | AI12: 94390 | AJ12: 117987.5 | AK12: 47195 | AL12: 141585 | AM12: 94390 | AN12: 211433.6 | AO12: 188780 | AP12: 188780 | AQ12: 211433.6 | AR12: 141585 | AS12: 211433.6 | AT12: 211433.6 | AU12: 264292 | AV12: 211433.6 | AW12: =IF('PFM NON-SELL (Draft Layers)'!AW60="X","X"," ") -> X | AX12: =IF('PFM NON-SELL (Draft Layers)'!AX60="X","X"," ") -> X | AY12: =IF('PFM NON-SELL (Draft Layers)'!AY60="X","X"," ") | AZ12: =IF('PFM NON-SELL (Draft Layers)'!AZ60="X","X"," ") | BA12: =IF('PFM NON-SELL (Draft Layers)'!BA60="X","X"," ") | BB12: =IF('PFM NON-SELL (Draft Layers)'!BB60="X","X"," ") -> X | BC12: =IF('PFM NON-SELL (Draft Layers)'!BC60="X","X"," ") | BD12: =IF('PFM NON-SELL (Draft Layers)'!BD60="X","X"," ") -> X | ... BK12: =IF('PFM NON-SELL (Draft Layers)'!BK60="X","X"," ") | BL12: =IF('PFM NON-SELL (Draft Layers)'!BM60="X","X"," ") -> X | BM12: =IF('PFM NON-SELL (Draft Layers)'!BN60="X","X"," ") -> X | BN12: =IF('PFM NON-SELL (Draft Layers)'!BO60="X","X"," ") | BO12: =IF('PFM NON-SELL (Draft Layers)'!BP60="X","X"," ") -> X | BP12: =IF('PFM NON-SELL (Draft Layers)'!BQ60="X","X"," ") | BQ12: =IF('PFM NON-SELL (Draft Layers)'!BR60="X","X"," ") | BR12: =IF('PFM NON-SELL (Draft Layers)'!BS60="X","X"," ") | BS12: =IF('PFM NON-SELL (Draft Layers)'!BT60="X","X"," ") | ... BV12: =IF('PFM NON-SELL (Draft Layers)'!BW60="X","X"," ") -> X | BW12: =IF('PFM NON-SELL (Draft Layers)'!BY60="X","X"," ") | BX12: =IF('PFM NON-SELL (Draft Layers)'!BZ60="X","X"," ") -> X | BY12: =IF('PFM NON-SELL (Draft Layers)'!CA60="X","X"," ") | BZ12: =IF('PFM NON-SELL (Draft Layers)'!CB60="X","X"," ") | CA12: =IF('PFM NON-SELL (Draft Layers)'!CC60="X","X"," ") | CB12: =IF('PFM NON-SELL (Draft Layers)'!CD60="X","X"," ") | CC12: =IF('PFM NON-SELL (Draft Layers)'!CE60="X","X"," ") | CD12: =IF('PFM NON-SELL (Draft Layers)'!CF60="X","X"," ") | ... CH12: =IF('PFM NON-SELL (Draft Layers)'!CJ60="X","X"," ") | CI12: =IF('PFM NON-SELL (Draft Layers)'!CN60="X","X"," ") | CJ12: =IF('PFM NON-SELL (Draft Layers)'!CO60="X","X"," ") | CK12: =IF('PFM NON-SELL (Draft Layers)'!CP60="X","X"," ") | CL12: =IF('PFM NON-SELL (Draft Layers)'!CQ60="X","X"," ") | CM12: =IF('PFM NON-SELL (Draft Layers)'!CV60="X","X"," ") | CN12: =IF('PFM NON-SELL (Draft Layers)'!CW60="X","X"," ") -> X | CO12: =IF('PFM NON-SELL (Draft Layers)'!CX60="X","X"," ") | CP12: =IF('PFM NON-SELL (Draft Layers)'!CY60="X","X"," ") | CQ12: =IF('PFM NON-SELL (Draft Layers)'!CZ60="X","X"," ") | CR12: =IF('PFM NON-SELL (Draft Layers)'!DA60="X","X"," ") | CS12: =IF('PFM NON-SELL (Draft Layers)'!DB60="X","X"," ") | CT12: =IF('PFM NON-SELL (Draft Layers)'!DC60="X","X"," ") | ... CY12: =IF('PFM NON-SELL (Draft Layers)'!DH60="X","X"," ") -> X | DO12: =COUNTIF(AW12:DN12,"x") -> 15
A13: AFL | B13: Ascend | C13: ASCND-4RU-8RT;23 | D13: 4RU-8RT ASCEND ASSY | E13: 468.32 | F13: =E13*G13 -> 187328 | G13: =SUM(M13:X13) -> 400 | H13: =ROUNDUP(G13/12,0) -> 34 | I13: =J13*E13 -> 93664 | J13: =SUM(Y13:AC13) -> 200 | K13: =ROUNDUP(J13/5,0) -> 40 | L13: 200 | M13: 0 | N13: 0 | O13: 200 | P13: 0 | Q13: 0 | R13: 100 | S13: 0 | T13: 0 | U13: 0 | V13: 100 | W13: 0 | X13: 0 | Y13: 0 | Z13: 200 | AA13: 0 | AB13: 0 | AC13: 0 | AE13: 93664 | AF13: 0 | AG13: 0 | AH13: 93664 | AI13: 0 | AJ13: 0 | AK13: 46832 | AL13: 0 | AM13: 0 | AN13: 0 | AO13: 46832 | AP13: 0 | AQ13: 0 | AR13: 0 | AS13: 93664 | AT13: 0 | AU13: 0 | AV13: 0 | AW13: =IF('PFM NON-SELL (Draft Layers)'!AW83="X","X"," ") -> X | AX13: =IF('PFM NON-SELL (Draft Layers)'!AX83="X","X"," ") -> X | AY13: =IF('PFM NON-SELL (Draft Layers)'!AY83="X","X"," ") | AZ13: =IF('PFM NON-SELL (Draft Layers)'!AZ83="X","X"," ") | BA13: =IF('PFM NON-SELL (Draft Layers)'!BA83="X","X"," ") | BB13: =IF('PFM NON-SELL (Draft Layers)'!BB83="X","X"," ") -> X | BC13: =IF('PFM NON-SELL (Draft Layers)'!BC83="X","X"," ") | BD13: =IF('PFM NON-SELL (Draft Layers)'!BD83="X","X"," ") -> X | ... BK13: =IF('PFM NON-SELL (Draft Layers)'!BK83="X","X"," ") | BL13: =IF('PFM NON-SELL (Draft Layers)'!BM83="X","X"," ") -> X | BM13: =IF('PFM NON-SELL (Draft Layers)'!BN83="X","X"," ") -> X | BN13: =IF('PFM NON-SELL (Draft Layers)'!BO83="X","X"," ") | BO13: =IF('PFM NON-SELL (Draft Layers)'!BP83="X","X"," ") -> X | BP13: =IF('PFM NON-SELL (Draft Layers)'!BQ83="X","X"," ") | BQ13: =IF('PFM NON-SELL (Draft Layers)'!BR83="X","X"," ") | BR13: =IF('PFM NON-SELL (Draft Layers)'!BS83="X","X"," ") | BS13: =IF('PFM NON-SELL (Draft Layers)'!BT83="X","X"," ") | ... BV13: =IF('PFM NON-SELL (Draft Layers)'!BW83="X","X"," ") -> X | BW13: =IF('PFM NON-SELL (Draft Layers)'!BY83="X","X"," ") | BX13: =IF('PFM NON-SELL (Draft Layers)'!BZ83="X","X"," ") -> X | BY13: =IF('PFM NON-SELL (Draft Layers)'!CA83="X","X"," ") | BZ13: =IF('PFM NON-SELL (Draft Layers)'!CB83="X","X"," ") | CA13: =IF('PFM NON-SELL (Draft Layers)'!CC83="X","X"," ") | CB13: =IF('PFM NON-SELL (Draft Layers)'!CD83="X","X"," ") | CC13: =IF('PFM NON-SELL (Draft Layers)'!CE83="X","X"," ") | CD13: =IF('PFM NON-SELL (Draft Layers)'!CF83="X","X"," ") | ... CH13: =IF('PFM NON-SELL (Draft Layers)'!CJ83="X","X"," ") | CI13: =IF('PFM NON-SELL (Draft Layers)'!CN83="X","X"," ") | CJ13: =IF('PFM NON-SELL (Draft Layers)'!CO83="X","X"," ") | CK13: =IF('PFM NON-SELL (Draft Layers)'!CP83="X","X"," ") | CL13: =IF('PFM NON-SELL (Draft Layers)'!CQ83="X","X"," ") | CM13: =IF('PFM NON-SELL (Draft Layers)'!CV83="X","X"," ") | CN13: =IF('PFM NON-SELL (Draft Layers)'!CW83="X","X"," ") -> X | CO13: =IF('PFM NON-SELL (Draft Layers)'!CX83="X","X"," ") | CP13: =IF('PFM NON-SELL (Draft Layers)'!CY83="X","X"," ") | CQ13: =IF('PFM NON-SELL (Draft Layers)'!CZ83="X","X"," ") | CR13: =IF('PFM NON-SELL (Draft Layers)'!DA83="X","X"," ") | CS13: =IF('PFM NON-SELL (Draft Layers)'!DB83="X","X"," ") | CT13: =IF('PFM NON-SELL (Draft Layers)'!DC83="X","X"," ") | ... CY13: =IF('PFM NON-SELL (Draft Layers)'!DH83="X","X"," ") -> X | DO13: =COUNTIF(AW13:DN13,"x") -> 15
A14: AFL | B14: HYPERSCALE | C14: HCF-48U-ODF002;11 | D14: 48U FRAME ASSEMBLY | E14: 2814.12 | F14: =E14*G14 -> 396790.92 | G14: =SUM(M14:X14) -> 141 | H14: =ROUNDUP(G14/12,0) -> 12 | I14: =J14*E14 -> 0 | J14: =SUM(Y14:AC14) -> 0 | K14: =ROUNDUP(J14/5,0) -> 0 | L14: 46 | M14: 69 | N14: 20 | O14: 52 | P14: 0 | Q14: 0 | R14: 0 | S14: 0 | T14: 0 | U14: 0 | V14: 0 | W14: 0 | X14: 0 | Y14: 0 | Z14: 0 | AA14: 0 | AB14: 0 | AC14: 0 | AE14: 129449.52 | AF14: 194174.28 | AG14: 56282.4 | AH14: 146334.24 | AI14: 0 | AJ14: 0 | AK14: 0 | AL14: 0 | AM14: 0 | AN14: 0 | AO14: 0 | AP14: 0 | AQ14: 0 | AR14: 0 | AS14: 0 | AT14: 0 | AU14: 0 | AV14: 0 | AW14: =IF('PFM NON-SELL (Draft Layers)'!AW106="X","X"," ") -> X | AX14: =IF('PFM NON-SELL (Draft Layers)'!AX106="X","X"," ") -> X | AY14: =IF('PFM NON-SELL (Draft Layers)'!AY106="X","X"," ") -> X | AZ14: =IF('PFM NON-SELL (Draft Layers)'!AZ106="X","X"," ") | BA14: =IF('PFM NON-SELL (Draft Layers)'!BA106="X","X"," ") | BB14: =IF('PFM NON-SELL (Draft Layers)'!BB106="X","X"," ") | BC14: =IF('PFM NON-SELL (Draft Layers)'!BC106="X","X"," ") | BD14: =IF('PFM NON-SELL (Draft Layers)'!BD106="X","X"," ") | ... BK14: =IF('PFM NON-SELL (Draft Layers)'!BK106="X","X"," ") | BL14: =IF('PFM NON-SELL (Draft Layers)'!BM106="X","X"," ") | BM14: =IF('PFM NON-SELL (Draft Layers)'!BN106="X","X"," ") | BN14: =IF('PFM NON-SELL (Draft Layers)'!BO106="X","X"," ") | BO14: =IF('PFM NON-SELL (Draft Layers)'!BP106="X","X"," ") -> X | BP14: =IF('PFM NON-SELL (Draft Layers)'!BQ106="X","X"," ") | BQ14: =IF('PFM NON-SELL (Draft Layers)'!BR106="X","X"," ") -> X | BR14: =IF('PFM NON-SELL (Draft Layers)'!BS106="X","X"," ") | BS14: =IF('PFM NON-SELL (Draft Layers)'!BT106="X","X"," ") | ... BV14: =IF('PFM NON-SELL (Draft Layers)'!BW106="X","X"," ") | BW14: =IF('PFM NON-SELL (Draft Layers)'!BY106="X","X"," ") | BX14: =IF('PFM NON-SELL (Draft Layers)'!BZ106="X","X"," ") | BY14: =IF('PFM NON-SELL (Draft Layers)'!CA106="X","X"," ") | BZ14: =IF('PFM NON-SELL (Draft Layers)'!CB106="X","X"," ") -> X | CA14: =IF('PFM NON-SELL (Draft Layers)'!CC106="X","X"," ") -> X | CB14: =IF('PFM NON-SELL (Draft Layers)'!CD106="X","X"," ") -> X | CC14: =IF('PFM NON-SELL (Draft Layers)'!CE106="X","X"," ") | CD14: =IF('PFM NON-SELL (Draft Layers)'!CF106="X","X"," ") -> X | ... CH14: =IF('PFM NON-SELL (Draft Layers)'!CJ106="X","X"," ") | CI14: =IF('PFM NON-SELL (Draft Layers)'!CN106="X","X"," ") | CJ14: =IF('PFM NON-SELL (Draft Layers)'!CO106="X","X"," ") | CK14: =IF('PFM NON-SELL (Draft Layers)'!CP106="X","X"," ") | CL14: =IF('PFM NON-SELL (Draft Layers)'!CQ106="X","X"," ") | CM14: =IF('PFM NON-SELL (Draft Layers)'!CV106="X","X"," ") | CN14: =IF('PFM NON-SELL (Draft Layers)'!CW106="X","X"," ") -> X | CO14: =IF('PFM NON-SELL (Draft Layers)'!CX106="X","X"," ") | CP14: =IF('PFM NON-SELL (Draft Layers)'!CY106="X","X"," ") | CQ14: =IF('PFM NON-SELL (Draft Layers)'!CZ106="X","X"," ") | CR14: =IF('PFM NON-SELL (Draft Layers)'!DA106="X","X"," ") | CS14: =IF('PFM NON-SELL (Draft Layers)'!DB106="X","X"," ") -> X | CT14: =IF('PFM NON-SELL (Draft Layers)'!DC106="X","X"," ") | ... CY14: =IF('PFM NON-SELL (Draft Layers)'!DH106="X","X"," ") -> X | DO14: =COUNTIF(AW14:DN14,"x") -> 17
